# Goxel 0.11.1
# One line per voxel
# X Y Z RRGGBB
-16 -16 0 bf40bf
-15 -16 0 ffffff
-14 -16 0 000000
-13 -16 0 ffffff
-12 -16 0 000000
-11 -16 0 ffffff
-10 -16 0 000000
-9 -16 0 ffffff
-8 -16 0 000000
-7 -16 0 ffffff
-6 -16 0 000000
-5 -16 0 bf40bf
-4 -16 0 000000
-3 -16 0 bf40bf
-2 -16 0 000000
-1 -16 0 ffffff
-16 -15 0 ffffff
-15 -15 0 000000
-14 -15 0 ffffff
-13 -15 0 000000
-12 -15 0 ffffff
-11 -15 0 bf40bf
-10 -15 0 ffffff
-9 -15 0 000000
-8 -15 0 bf40bf
-7 -15 0 000000
-6 -15 0 bf40bf
-5 -15 0 000000
-4 -15 0 ffffff
-3 -15 0 000000
-2 -15 0 ffffff
-1 -15 0 bf40bf
-16 -14 0 bf40bf
-15 -14 0 ffffff
-14 -14 0 000000
-13 -14 0 bf40bf
-12 -14 0 000000
-11 -14 0 ffffff
-10 -14 0 bf40bf
-9 -14 0 bf40bf
-8 -14 0 000000
-7 -14 0 ffffff
-6 -14 0 bf40bf
-5 -14 0 ffffff
-4 -14 0 000000
-3 -14 0 ffffff
-2 -14 0 000000
-1 -14 0 bf40bf
-16 -13 0 ffffff
-15 -13 0 bf40bf
-14 -13 0 bf40bf
-13 -13 0 bf40bf
-12 -13 0 ffffff
-11 -13 0 bf40bf
-10 -13 0 bf40bf
-9 -13 0 bf40bf
-8 -13 0 ffffff
-7 -13 0 000000
-6 -13 0 bf40bf
-5 -13 0 000000
-4 -13 0 ffffff
-3 -13 0 000000
-2 -13 0 ffffff
-1 -13 0 000000
-16 -12 0 000000
-15 -12 0 bf40bf
-14 -12 0 bf40bf
-13 -12 0 ffffff
-12 -12 0 000000
-11 -12 0 ffffff
-10 -12 0 000000
-9 -12 0 ffffff
-8 -12 0 000000
-7 -12 0 ffffff
-6 -12 0 000000
-5 -12 0 ffffff
-4 -12 0 000000
-3 -12 0 ffffff
-2 -12 0 000000
-1 -12 0 ffffff
-16 -11 0 bf40bf
-15 -11 0 000000
-14 -11 0 ffffff
-13 -11 0 000000
-12 -11 0 ffffff
-11 -11 0 000000
-10 -11 0 ffffff
-9 -11 0 000000
-8 -11 0 ffffff
-7 -11 0 000000
-6 -11 0 ffffff
-5 -11 0 000000
-4 -11 0 ffffff
-3 -11 0 000000
-2 -11 0 ffffff
-1 -11 0 bf40bf
-16 -10 0 000000
-15 -10 0 ffffff
-14 -10 0 bf40bf
-13 -10 0 ffffff
-12 -10 0 000000
-11 -10 0 bf40bf
-10 -10 0 000000
-9 -10 0 ffffff
-8 -10 0 000000
-7 -10 0 ffffff
-6 -10 0 000000
-5 -10 0 ffffff
-4 -10 0 000000
-3 -10 0 ffffff
-2 -10 0 000000
-1 -10 0 bf40bf
-16 -9 0 ffffff
-15 -9 0 000000
-14 -9 0 ffffff
-13 -9 0 000000
-12 -9 0 bf40bf
-11 -9 0 000000
-10 -9 0 bf40bf
-9 -9 0 bf40bf
-8 -9 0 ffffff
-7 -9 0 000000
-6 -9 0 ffffff
-5 -9 0 bf40bf
-4 -9 0 ffffff
-3 -9 0 000000
-2 -9 0 ffffff
-1 -9 0 bf40bf
-16 -8 0 000000
-15 -8 0 ffffff
-14 -8 0 000000
-13 -8 0 ffffff
-12 -8 0 000000
-11 -8 0 ffffff
-10 -8 0 000000
-9 -8 0 ffffff
-8 -8 0 000000
-7 -8 0 bf40bf
-6 -8 0 000000
-5 -8 0 ffffff
-4 -8 0 000000
-3 -8 0 ffffff
-2 -8 0 000000
-1 -8 0 ffffff
-16 -7 0 bf40bf
-15 -7 0 000000
-14 -7 0 ffffff
-13 -7 0 bf40bf
-12 -7 0 ffffff
-11 -7 0 000000
-10 -7 0 bf40bf
-9 -7 0 000000
-8 -7 0 bf40bf
-7 -7 0 000000
-6 -7 0 bf40bf
-5 -7 0 bf40bf
-4 -7 0 ffffff
-3 -7 0 000000
-2 -7 0 ffffff
-1 -7 0 000000
-16 -6 0 000000
-15 -6 0 bf40bf
-14 -6 0 bf40bf
-13 -6 0 ffffff
-12 -6 0 000000
-11 -6 0 ffffff
-10 -6 0 000000
-9 -6 0 ffffff
-8 -6 0 000000
-7 -6 0 ffffff
-6 -6 0 000000
-5 -6 0 ffffff
-4 -6 0 bf40bf
-3 -6 0 bf40bf
-2 -6 0 000000
-1 -6 0 ffffff
-16 -5 0 ffffff
-15 -5 0 000000
-14 -5 0 bf40bf
-13 -5 0 bf40bf
-12 -5 0 bf40bf
-11 -5 0 000000
-10 -5 0 ffffff
-9 -5 0 000000
-8 -5 0 ffffff
-7 -5 0 000000
-6 -5 0 ffffff
-5 -5 0 000000
-4 -5 0 ffffff
-3 -5 0 000000
-2 -5 0 ffffff
-1 -5 0 bf40bf
-16 -4 0 000000
-15 -4 0 bf40bf
-14 -4 0 000000
-13 -4 0 ffffff
-12 -4 0 000000
-11 -4 0 ffffff
-10 -4 0 000000
-9 -4 0 ffffff
-8 -4 0 bf40bf
-7 -4 0 ffffff
-6 -4 0 000000
-5 -4 0 ffffff
-4 -4 0 000000
-3 -4 0 bf40bf
-2 -4 0 000000
-1 -4 0 ffffff
-16 -3 0 bf40bf
-15 -3 0 000000
-14 -3 0 ffffff
-13 -3 0 000000
-12 -3 0 bf40bf
-11 -3 0 000000
-10 -3 0 ffffff
-9 -3 0 bf40bf
-8 -3 0 ffffff
-7 -3 0 000000
-6 -3 0 ffffff
-5 -3 0 bf40bf
-4 -3 0 ffffff
-3 -3 0 000000
-2 -3 0 ffffff
-1 -3 0 000000
-16 -2 0 000000
-15 -2 0 ffffff
-14 -2 0 000000
-13 -2 0 ffffff
-12 -2 0 bf40bf
-11 -2 0 ffffff
-10 -2 0 000000
-9 -2 0 bf40bf
-8 -2 0 000000
-7 -2 0 ffffff
-6 -2 0 000000
-5 -2 0 ffffff
-4 -2 0 000000
-3 -2 0 ffffff
-2 -2 0 000000
-1 -2 0 ffffff
-16 -1 0 ffffff
-15 -1 0 bf40bf
-14 -1 0 bf40bf
-13 -1 0 000000
-12 -1 0 ffffff
-11 -1 0 000000
-10 -1 0 ffffff
-9 -1 0 000000
-8 -1 0 ffffff
-7 -1 0 000000
-6 -1 0 ffffff
-5 -1 0 000000
-4 -1 0 ffffff
-3 -1 0 000000
-2 -1 0 ffffff
-1 -1 0 000000
-16 -16 1 bf40bf
-15 -16 1 ffffff
-14 -16 1 000000
-13 -16 1 ffffff
-12 -16 1 000000
-11 -16 1 ffffff
-10 -16 1 000000
-9 -16 1 ffffff
-8 -16 1 000000
-7 -16 1 ffffff
-6 -16 1 000000
-5 -16 1 bf40bf
-4 -16 1 000000
-3 -16 1 bf40bf
-2 -16 1 000000
-1 -16 1 ffffff
-16 -15 1 ffffff
-15 -15 1 000000
-14 -15 1 ffffff
-13 -15 1 000000
-12 -15 1 ffffff
-11 -15 1 bf40bf
-10 -15 1 ffffff
-9 -15 1 000000
-8 -15 1 bf40bf
-7 -15 1 000000
-6 -15 1 bf40bf
-5 -15 1 000000
-4 -15 1 ffffff
-3 -15 1 000000
-2 -15 1 ffffff
-1 -15 1 bf40bf
-16 -14 1 bf40bf
-15 -14 1 ffffff
-14 -14 1 000000
-13 -14 1 bf40bf
-12 -14 1 000000
-11 -14 1 ffffff
-10 -14 1 bf40bf
-9 -14 1 bf40bf
-8 -14 1 000000
-7 -14 1 ffffff
-6 -14 1 bf40bf
-5 -14 1 ffffff
-4 -14 1 000000
-3 -14 1 ffffff
-2 -14 1 000000
-1 -14 1 bf40bf
-16 -13 1 ffffff
-15 -13 1 bf40bf
-14 -13 1 bf40bf
-13 -13 1 bf40bf
-12 -13 1 ffffff
-11 -13 1 bf40bf
-10 -13 1 bf40bf
-9 -13 1 bf40bf
-8 -13 1 ffffff
-7 -13 1 000000
-6 -13 1 bf40bf
-5 -13 1 000000
-4 -13 1 ffffff
-3 -13 1 000000
-2 -13 1 ffffff
-1 -13 1 000000
-16 -12 1 000000
-15 -12 1 bf40bf
-14 -12 1 bf40bf
-13 -12 1 ffffff
-12 -12 1 000000
-11 -12 1 ffffff
-10 -12 1 000000
-9 -12 1 ffffff
-8 -12 1 000000
-7 -12 1 ffffff
-6 -12 1 000000
-5 -12 1 ffffff
-4 -12 1 000000
-3 -12 1 ffffff
-2 -12 1 000000
-1 -12 1 ffffff
-16 -11 1 bf40bf
-15 -11 1 000000
-14 -11 1 ffffff
-13 -11 1 000000
-12 -11 1 ffffff
-11 -11 1 000000
-10 -11 1 ffffff
-9 -11 1 000000
-8 -11 1 ffffff
-7 -11 1 000000
-6 -11 1 ffffff
-5 -11 1 000000
-4 -11 1 ffffff
-3 -11 1 000000
-2 -11 1 ffffff
-1 -11 1 bf40bf
-16 -10 1 000000
-15 -10 1 ffffff
-14 -10 1 bf40bf
-13 -10 1 ffffff
-12 -10 1 000000
-11 -10 1 bf40bf
-10 -10 1 000000
-9 -10 1 ffffff
-8 -10 1 000000
-7 -10 1 ffffff
-6 -10 1 000000
-5 -10 1 ffffff
-4 -10 1 000000
-3 -10 1 ffffff
-2 -10 1 000000
-1 -10 1 bf40bf
-16 -9 1 ffffff
-15 -9 1 000000
-14 -9 1 ffffff
-13 -9 1 000000
-12 -9 1 bf40bf
-11 -9 1 000000
-10 -9 1 bf40bf
-9 -9 1 bf40bf
-8 -9 1 ffffff
-7 -9 1 000000
-6 -9 1 ffffff
-5 -9 1 bf40bf
-4 -9 1 ffffff
-3 -9 1 000000
-2 -9 1 ffffff
-1 -9 1 bf40bf
-16 -8 1 000000
-15 -8 1 ffffff
-14 -8 1 000000
-13 -8 1 ffffff
-12 -8 1 000000
-11 -8 1 ffffff
-10 -8 1 000000
-9 -8 1 ffffff
-8 -8 1 000000
-7 -8 1 bf40bf
-6 -8 1 000000
-5 -8 1 ffffff
-4 -8 1 000000
-3 -8 1 ffffff
-2 -8 1 000000
-1 -8 1 ffffff
-16 -7 1 bf40bf
-15 -7 1 000000
-14 -7 1 ffffff
-13 -7 1 bf40bf
-12 -7 1 ffffff
-11 -7 1 000000
-10 -7 1 bf40bf
-9 -7 1 000000
-8 -7 1 bf40bf
-7 -7 1 000000
-6 -7 1 bf40bf
-5 -7 1 bf40bf
-4 -7 1 ffffff
-3 -7 1 000000
-2 -7 1 ffffff
-1 -7 1 000000
-16 -6 1 000000
-15 -6 1 bf40bf
-14 -6 1 bf40bf
-13 -6 1 ffffff
-12 -6 1 000000
-11 -6 1 ffffff
-10 -6 1 000000
-9 -6 1 ffffff
-8 -6 1 000000
-7 -6 1 ffffff
-6 -6 1 000000
-5 -6 1 ffffff
-4 -6 1 bf40bf
-3 -6 1 bf40bf
-2 -6 1 000000
-1 -6 1 ffffff
-16 -5 1 ffffff
-15 -5 1 000000
-14 -5 1 bf40bf
-13 -5 1 bf40bf
-12 -5 1 bf40bf
-11 -5 1 000000
-10 -5 1 ffffff
-9 -5 1 000000
-8 -5 1 ffffff
-7 -5 1 000000
-6 -5 1 ffffff
-5 -5 1 000000
-4 -5 1 ffffff
-3 -5 1 000000
-2 -5 1 ffffff
-1 -5 1 bf40bf
-16 -4 1 000000
-15 -4 1 bf40bf
-14 -4 1 000000
-13 -4 1 ffffff
-12 -4 1 000000
-11 -4 1 ffffff
-10 -4 1 000000
-9 -4 1 ffffff
-8 -4 1 bf40bf
-7 -4 1 ffffff
-6 -4 1 000000
-5 -4 1 ffffff
-4 -4 1 000000
-3 -4 1 bf40bf
-2 -4 1 000000
-1 -4 1 ffffff
-16 -3 1 bf40bf
-15 -3 1 000000
-14 -3 1 ffffff
-13 -3 1 000000
-12 -3 1 bf40bf
-11 -3 1 000000
-10 -3 1 ffffff
-9 -3 1 bf40bf
-8 -3 1 ffffff
-7 -3 1 000000
-6 -3 1 ffffff
-5 -3 1 bf40bf
-4 -3 1 ffffff
-3 -3 1 000000
-2 -3 1 ffffff
-1 -3 1 000000
-16 -2 1 000000
-15 -2 1 ffffff
-14 -2 1 000000
-13 -2 1 ffffff
-12 -2 1 bf40bf
-11 -2 1 ffffff
-10 -2 1 000000
-9 -2 1 bf40bf
-8 -2 1 000000
-7 -2 1 ffffff
-6 -2 1 000000
-5 -2 1 ffffff
-4 -2 1 000000
-3 -2 1 ffffff
-2 -2 1 000000
-1 -2 1 ffffff
-16 -1 1 ffffff
-15 -1 1 bf40bf
-14 -1 1 bf40bf
-13 -1 1 000000
-12 -1 1 ffffff
-11 -1 1 000000
-10 -1 1 ffffff
-9 -1 1 000000
-8 -1 1 ffffff
-7 -1 1 000000
-6 -1 1 ffffff
-5 -1 1 000000
-4 -1 1 ffffff
-3 -1 1 000000
-2 -1 1 ffffff
-1 -1 1 000000
-16 -16 2 bf40bf
-15 -16 2 ffffff
-14 -16 2 000000
-13 -16 2 ffffff
-12 -16 2 000000
-11 -16 2 ffffff
-10 -16 2 000000
-9 -16 2 ffffff
-8 -16 2 000000
-7 -16 2 ffffff
-6 -16 2 000000
-5 -16 2 bf40bf
-4 -16 2 000000
-3 -16 2 bf40bf
-2 -16 2 000000
-1 -16 2 ffffff
-16 -15 2 ffffff
-15 -15 2 000000
-14 -15 2 ffffff
-13 -15 2 000000
-12 -15 2 ffffff
-11 -15 2 bf40bf
-10 -15 2 ffffff
-9 -15 2 000000
-8 -15 2 bf40bf
-7 -15 2 000000
-6 -15 2 bf40bf
-5 -15 2 000000
-4 -15 2 ffffff
-3 -15 2 000000
-2 -15 2 ffffff
-1 -15 2 bf40bf
-16 -14 2 bf40bf
-15 -14 2 ffffff
-14 -14 2 000000
-13 -14 2 bf40bf
-12 -14 2 000000
-11 -14 2 ffffff
-10 -14 2 bf40bf
-9 -14 2 bf40bf
-8 -14 2 000000
-7 -14 2 ffffff
-6 -14 2 bf40bf
-5 -14 2 ffffff
-4 -14 2 000000
-3 -14 2 ffffff
-2 -14 2 000000
-1 -14 2 bf40bf
-16 -13 2 ffffff
-15 -13 2 bf40bf
-14 -13 2 bf40bf
-13 -13 2 bf40bf
-12 -13 2 ffffff
-11 -13 2 bf40bf
-10 -13 2 bf40bf
-9 -13 2 bf40bf
-8 -13 2 ffffff
-7 -13 2 000000
-6 -13 2 bf40bf
-5 -13 2 000000
-4 -13 2 ffffff
-3 -13 2 000000
-2 -13 2 ffffff
-1 -13 2 000000
-16 -12 2 000000
-15 -12 2 bf40bf
-14 -12 2 bf40bf
-13 -12 2 ffffff
-12 -12 2 000000
-11 -12 2 ffffff
-10 -12 2 000000
-9 -12 2 ffffff
-8 -12 2 000000
-7 -12 2 ffffff
-6 -12 2 000000
-5 -12 2 ffffff
-4 -12 2 000000
-3 -12 2 ffffff
-2 -12 2 000000
-1 -12 2 ffffff
-16 -11 2 bf40bf
-15 -11 2 000000
-14 -11 2 ffffff
-13 -11 2 000000
-12 -11 2 ffffff
-11 -11 2 000000
-10 -11 2 ffffff
-9 -11 2 000000
-8 -11 2 ffffff
-7 -11 2 000000
-6 -11 2 ffffff
-5 -11 2 000000
-4 -11 2 ffffff
-3 -11 2 000000
-2 -11 2 ffffff
-1 -11 2 bf40bf
-16 -10 2 000000
-15 -10 2 ffffff
-14 -10 2 bf40bf
-13 -10 2 ffffff
-12 -10 2 000000
-11 -10 2 bf40bf
-10 -10 2 000000
-9 -10 2 ffffff
-8 -10 2 000000
-7 -10 2 ffffff
-6 -10 2 000000
-5 -10 2 ffffff
-4 -10 2 000000
-3 -10 2 ffffff
-2 -10 2 000000
-1 -10 2 bf40bf
-16 -9 2 ffffff
-15 -9 2 000000
-14 -9 2 ffffff
-13 -9 2 000000
-12 -9 2 bf40bf
-11 -9 2 000000
-10 -9 2 bf40bf
-9 -9 2 bf40bf
-8 -9 2 ffffff
-7 -9 2 000000
-6 -9 2 ffffff
-5 -9 2 bf40bf
-4 -9 2 ffffff
-3 -9 2 000000
-2 -9 2 ffffff
-1 -9 2 bf40bf
-16 -8 2 000000
-15 -8 2 ffffff
-14 -8 2 000000
-13 -8 2 ffffff
-12 -8 2 000000
-11 -8 2 ffffff
-10 -8 2 000000
-9 -8 2 ffffff
-8 -8 2 000000
-7 -8 2 bf40bf
-6 -8 2 000000
-5 -8 2 ffffff
-4 -8 2 000000
-3 -8 2 ffffff
-2 -8 2 000000
-1 -8 2 ffffff
-16 -7 2 bf40bf
-15 -7 2 000000
-14 -7 2 ffffff
-13 -7 2 bf40bf
-12 -7 2 ffffff
-11 -7 2 000000
-10 -7 2 bf40bf
-9 -7 2 000000
-8 -7 2 bf40bf
-7 -7 2 000000
-6 -7 2 bf40bf
-5 -7 2 bf40bf
-4 -7 2 ffffff
-3 -7 2 000000
-2 -7 2 ffffff
-1 -7 2 000000
-16 -6 2 000000
-15 -6 2 bf40bf
-14 -6 2 bf40bf
-13 -6 2 ffffff
-12 -6 2 000000
-11 -6 2 ffffff
-10 -6 2 000000
-9 -6 2 ffffff
-8 -6 2 000000
-7 -6 2 ffffff
-6 -6 2 000000
-5 -6 2 ffffff
-4 -6 2 bf40bf
-3 -6 2 bf40bf
-2 -6 2 000000
-1 -6 2 ffffff
-16 -5 2 ffffff
-15 -5 2 000000
-14 -5 2 bf40bf
-13 -5 2 bf40bf
-12 -5 2 bf40bf
-11 -5 2 000000
-10 -5 2 ffffff
-9 -5 2 000000
-8 -5 2 ffffff
-7 -5 2 000000
-6 -5 2 ffffff
-5 -5 2 000000
-4 -5 2 ffffff
-3 -5 2 000000
-2 -5 2 ffffff
-1 -5 2 bf40bf
-16 -4 2 000000
-15 -4 2 bf40bf
-14 -4 2 000000
-13 -4 2 ffffff
-12 -4 2 000000
-11 -4 2 ffffff
-10 -4 2 000000
-9 -4 2 ffffff
-8 -4 2 bf40bf
-7 -4 2 ffffff
-6 -4 2 000000
-5 -4 2 ffffff
-4 -4 2 000000
-3 -4 2 bf40bf
-2 -4 2 000000
-1 -4 2 ffffff
-16 -3 2 bf40bf
-15 -3 2 000000
-14 -3 2 ffffff
-13 -3 2 000000
-12 -3 2 bf40bf
-11 -3 2 000000
-10 -3 2 ffffff
-9 -3 2 bf40bf
-8 -3 2 ffffff
-7 -3 2 000000
-6 -3 2 ffffff
-5 -3 2 bf40bf
-4 -3 2 ffffff
-3 -3 2 000000
-2 -3 2 ffffff
-1 -3 2 000000
-16 -2 2 000000
-15 -2 2 ffffff
-14 -2 2 000000
-13 -2 2 ffffff
-12 -2 2 bf40bf
-11 -2 2 ffffff
-10 -2 2 000000
-9 -2 2 bf40bf
-8 -2 2 000000
-7 -2 2 ffffff
-6 -2 2 000000
-5 -2 2 ffffff
-4 -2 2 000000
-3 -2 2 ffffff
-2 -2 2 000000
-1 -2 2 ffffff
-16 -1 2 ffffff
-15 -1 2 bf40bf
-14 -1 2 bf40bf
-13 -1 2 000000
-12 -1 2 ffffff
-11 -1 2 000000
-10 -1 2 ffffff
-9 -1 2 000000
-8 -1 2 ffffff
-7 -1 2 000000
-6 -1 2 ffffff
-5 -1 2 000000
-4 -1 2 ffffff
-3 -1 2 000000
-2 -1 2 ffffff
-1 -1 2 000000
-16 -16 3 bf40bf
-15 -16 3 ffffff
-14 -16 3 000000
-13 -16 3 ffffff
-12 -16 3 000000
-11 -16 3 ffffff
-10 -16 3 000000
-9 -16 3 ffffff
-8 -16 3 000000
-7 -16 3 ffffff
-6 -16 3 000000
-5 -16 3 bf40bf
-4 -16 3 000000
-3 -16 3 bf40bf
-2 -16 3 000000
-1 -16 3 ffffff
-16 -15 3 ffffff
-15 -15 3 000000
-14 -15 3 ffffff
-13 -15 3 000000
-12 -15 3 ffffff
-11 -15 3 bf40bf
-10 -15 3 ffffff
-9 -15 3 000000
-8 -15 3 bf40bf
-7 -15 3 000000
-6 -15 3 bf40bf
-5 -15 3 000000
-4 -15 3 ffffff
-3 -15 3 000000
-2 -15 3 ffffff
-1 -15 3 bf40bf
-16 -14 3 bf40bf
-15 -14 3 ffffff
-14 -14 3 000000
-13 -14 3 bf40bf
-12 -14 3 000000
-11 -14 3 ffffff
-10 -14 3 bf40bf
-9 -14 3 bf40bf
-8 -14 3 000000
-7 -14 3 ffffff
-6 -14 3 bf40bf
-5 -14 3 ffffff
-4 -14 3 000000
-3 -14 3 ffffff
-2 -14 3 000000
-1 -14 3 bf40bf
-16 -13 3 ffffff
-15 -13 3 bf40bf
-14 -13 3 bf40bf
-13 -13 3 bf40bf
-12 -13 3 ffffff
-11 -13 3 bf40bf
-10 -13 3 bf40bf
-9 -13 3 bf40bf
-8 -13 3 ffffff
-7 -13 3 000000
-6 -13 3 bf40bf
-5 -13 3 000000
-4 -13 3 ffffff
-3 -13 3 000000
-2 -13 3 ffffff
-1 -13 3 000000
-16 -12 3 000000
-15 -12 3 bf40bf
-14 -12 3 bf40bf
-13 -12 3 ffffff
-12 -12 3 000000
-11 -12 3 ffffff
-10 -12 3 000000
-9 -12 3 ffffff
-8 -12 3 000000
-7 -12 3 ffffff
-6 -12 3 000000
-5 -12 3 ffffff
-4 -12 3 000000
-3 -12 3 ffffff
-2 -12 3 000000
-1 -12 3 ffffff
-16 -11 3 bf40bf
-15 -11 3 000000
-14 -11 3 ffffff
-13 -11 3 000000
-12 -11 3 ffffff
-11 -11 3 000000
-10 -11 3 ffffff
-9 -11 3 000000
-8 -11 3 ffffff
-7 -11 3 000000
-6 -11 3 ffffff
-5 -11 3 000000
-4 -11 3 ffffff
-3 -11 3 000000
-2 -11 3 ffffff
-1 -11 3 bf40bf
-16 -10 3 000000
-15 -10 3 ffffff
-14 -10 3 bf40bf
-13 -10 3 ffffff
-12 -10 3 000000
-11 -10 3 bf40bf
-10 -10 3 000000
-9 -10 3 ffffff
-8 -10 3 000000
-7 -10 3 ffffff
-6 -10 3 000000
-5 -10 3 ffffff
-4 -10 3 000000
-3 -10 3 ffffff
-2 -10 3 000000
-1 -10 3 bf40bf
-16 -9 3 ffffff
-15 -9 3 000000
-14 -9 3 ffffff
-13 -9 3 000000
-12 -9 3 bf40bf
-11 -9 3 000000
-10 -9 3 bf40bf
-9 -9 3 bf40bf
-8 -9 3 ffffff
-7 -9 3 000000
-6 -9 3 ffffff
-5 -9 3 bf40bf
-4 -9 3 ffffff
-3 -9 3 000000
-2 -9 3 ffffff
-1 -9 3 bf40bf
-16 -8 3 000000
-15 -8 3 ffffff
-14 -8 3 000000
-13 -8 3 ffffff
-12 -8 3 000000
-11 -8 3 ffffff
-10 -8 3 000000
-9 -8 3 ffffff
-8 -8 3 000000
-7 -8 3 bf40bf
-6 -8 3 000000
-5 -8 3 ffffff
-4 -8 3 000000
-3 -8 3 ffffff
-2 -8 3 000000
-1 -8 3 ffffff
-16 -7 3 bf40bf
-15 -7 3 000000
-14 -7 3 ffffff
-13 -7 3 bf40bf
-12 -7 3 ffffff
-11 -7 3 000000
-10 -7 3 bf40bf
-9 -7 3 000000
-8 -7 3 bf40bf
-7 -7 3 000000
-6 -7 3 bf40bf
-5 -7 3 bf40bf
-4 -7 3 ffffff
-3 -7 3 000000
-2 -7 3 ffffff
-1 -7 3 000000
-16 -6 3 000000
-15 -6 3 bf40bf
-14 -6 3 bf40bf
-13 -6 3 ffffff
-12 -6 3 000000
-11 -6 3 ffffff
-10 -6 3 000000
-9 -6 3 ffffff
-8 -6 3 000000
-7 -6 3 ffffff
-6 -6 3 000000
-5 -6 3 ffffff
-4 -6 3 bf40bf
-3 -6 3 bf40bf
-2 -6 3 000000
-1 -6 3 ffffff
-16 -5 3 ffffff
-15 -5 3 000000
-14 -5 3 bf40bf
-13 -5 3 bf40bf
-12 -5 3 bf40bf
-11 -5 3 000000
-10 -5 3 ffffff
-9 -5 3 000000
-8 -5 3 ffffff
-7 -5 3 000000
-6 -5 3 ffffff
-5 -5 3 000000
-4 -5 3 ffffff
-3 -5 3 000000
-2 -5 3 ffffff
-1 -5 3 bf40bf
-16 -4 3 000000
-15 -4 3 bf40bf
-14 -4 3 000000
-13 -4 3 ffffff
-12 -4 3 000000
-11 -4 3 ffffff
-10 -4 3 000000
-9 -4 3 ffffff
-8 -4 3 bf40bf
-7 -4 3 ffffff
-6 -4 3 000000
-5 -4 3 ffffff
-4 -4 3 000000
-3 -4 3 bf40bf
-2 -4 3 000000
-1 -4 3 ffffff
-16 -3 3 bf40bf
-15 -3 3 000000
-14 -3 3 ffffff
-13 -3 3 000000
-12 -3 3 bf40bf
-11 -3 3 000000
-10 -3 3 ffffff
-9 -3 3 bf40bf
-8 -3 3 ffffff
-7 -3 3 000000
-6 -3 3 ffffff
-5 -3 3 bf40bf
-4 -3 3 ffffff
-3 -3 3 000000
-2 -3 3 ffffff
-1 -3 3 000000
-16 -2 3 000000
-15 -2 3 ffffff
-14 -2 3 000000
-13 -2 3 ffffff
-12 -2 3 bf40bf
-11 -2 3 ffffff
-10 -2 3 000000
-9 -2 3 bf40bf
-8 -2 3 000000
-7 -2 3 ffffff
-6 -2 3 000000
-5 -2 3 ffffff
-4 -2 3 000000
-3 -2 3 ffffff
-2 -2 3 000000
-1 -2 3 ffffff
-16 -1 3 ffffff
-15 -1 3 bf40bf
-14 -1 3 bf40bf
-13 -1 3 000000
-12 -1 3 ffffff
-11 -1 3 000000
-10 -1 3 ffffff
-9 -1 3 000000
-8 -1 3 ffffff
-7 -1 3 000000
-6 -1 3 ffffff
-5 -1 3 000000
-4 -1 3 ffffff
-3 -1 3 000000
-2 -1 3 ffffff
-1 -1 3 000000
-16 -16 4 bf40bf
-15 -16 4 ffffff
-14 -16 4 000000
-13 -16 4 ffffff
-12 -16 4 000000
-11 -16 4 ffffff
-10 -16 4 000000
-9 -16 4 ffffff
-8 -16 4 000000
-7 -16 4 ffffff
-6 -16 4 000000
-5 -16 4 bf40bf
-4 -16 4 000000
-3 -16 4 bf40bf
-2 -16 4 000000
-1 -16 4 ffffff
-16 -15 4 ffffff
-15 -15 4 000000
-14 -15 4 ffffff
-13 -15 4 000000
-12 -15 4 ffffff
-11 -15 4 bf40bf
-10 -15 4 ffffff
-9 -15 4 000000
-8 -15 4 bf40bf
-7 -15 4 000000
-6 -15 4 bf40bf
-5 -15 4 000000
-4 -15 4 ffffff
-3 -15 4 000000
-2 -15 4 ffffff
-1 -15 4 bf40bf
-16 -14 4 bf40bf
-15 -14 4 ffffff
-14 -14 4 000000
-13 -14 4 bf40bf
-12 -14 4 000000
-11 -14 4 ffffff
-10 -14 4 bf40bf
-9 -14 4 bf40bf
-8 -14 4 000000
-7 -14 4 ffffff
-6 -14 4 bf40bf
-5 -14 4 ffffff
-4 -14 4 000000
-3 -14 4 ffffff
-2 -14 4 000000
-1 -14 4 bf40bf
-16 -13 4 ffffff
-15 -13 4 bf40bf
-14 -13 4 bf40bf
-13 -13 4 bf40bf
-12 -13 4 ffffff
-11 -13 4 bf40bf
-10 -13 4 bf40bf
-9 -13 4 bf40bf
-8 -13 4 ffffff
-7 -13 4 000000
-6 -13 4 bf40bf
-5 -13 4 000000
-4 -13 4 ffffff
-3 -13 4 000000
-2 -13 4 ffffff
-1 -13 4 000000
-16 -12 4 000000
-15 -12 4 bf40bf
-14 -12 4 bf40bf
-13 -12 4 ffffff
-12 -12 4 000000
-11 -12 4 ffffff
-10 -12 4 000000
-9 -12 4 ffffff
-8 -12 4 000000
-7 -12 4 ffffff
-6 -12 4 000000
-5 -12 4 ffffff
-4 -12 4 000000
-3 -12 4 ffffff
-2 -12 4 000000
-1 -12 4 ffffff
-16 -11 4 bf40bf
-15 -11 4 000000
-14 -11 4 ffffff
-13 -11 4 000000
-12 -11 4 ffffff
-11 -11 4 000000
-10 -11 4 ffffff
-9 -11 4 000000
-8 -11 4 ffffff
-7 -11 4 000000
-6 -11 4 ffffff
-5 -11 4 000000
-4 -11 4 ffffff
-3 -11 4 000000
-2 -11 4 ffffff
-1 -11 4 bf40bf
-16 -10 4 000000
-15 -10 4 ffffff
-14 -10 4 bf40bf
-13 -10 4 ffffff
-12 -10 4 000000
-11 -10 4 bf40bf
-10 -10 4 000000
-9 -10 4 ffffff
-8 -10 4 000000
-7 -10 4 ffffff
-6 -10 4 000000
-5 -10 4 ffffff
-4 -10 4 000000
-3 -10 4 ffffff
-2 -10 4 000000
-1 -10 4 bf40bf
-16 -9 4 ffffff
-15 -9 4 000000
-14 -9 4 ffffff
-13 -9 4 000000
-12 -9 4 bf40bf
-11 -9 4 000000
-10 -9 4 bf40bf
-9 -9 4 bf40bf
-8 -9 4 ffffff
-7 -9 4 000000
-6 -9 4 ffffff
-5 -9 4 bf40bf
-4 -9 4 ffffff
-3 -9 4 000000
-2 -9 4 ffffff
-1 -9 4 bf40bf
-16 -8 4 000000
-15 -8 4 ffffff
-14 -8 4 000000
-13 -8 4 ffffff
-12 -8 4 000000
-11 -8 4 ffffff
-10 -8 4 000000
-9 -8 4 ffffff
-8 -8 4 000000
-7 -8 4 bf40bf
-6 -8 4 000000
-5 -8 4 ffffff
-4 -8 4 000000
-3 -8 4 ffffff
-2 -8 4 000000
-1 -8 4 ffffff
-16 -7 4 bf40bf
-15 -7 4 000000
-14 -7 4 ffffff
-13 -7 4 bf40bf
-12 -7 4 ffffff
-11 -7 4 000000
-10 -7 4 bf40bf
-9 -7 4 000000
-8 -7 4 bf40bf
-7 -7 4 000000
-6 -7 4 bf40bf
-5 -7 4 bf40bf
-4 -7 4 ffffff
-3 -7 4 000000
-2 -7 4 ffffff
-1 -7 4 000000
-16 -6 4 000000
-15 -6 4 bf40bf
-14 -6 4 bf40bf
-13 -6 4 ffffff
-12 -6 4 000000
-11 -6 4 ffffff
-10 -6 4 000000
-9 -6 4 ffffff
-8 -6 4 000000
-7 -6 4 ffffff
-6 -6 4 000000
-5 -6 4 ffffff
-4 -6 4 bf40bf
-3 -6 4 bf40bf
-2 -6 4 000000
-1 -6 4 ffffff
-16 -5 4 ffffff
-15 -5 4 000000
-14 -5 4 bf40bf
-13 -5 4 bf40bf
-12 -5 4 bf40bf
-11 -5 4 000000
-10 -5 4 ffffff
-9 -5 4 000000
-8 -5 4 ffffff
-7 -5 4 000000
-6 -5 4 ffffff
-5 -5 4 000000
-4 -5 4 ffffff
-3 -5 4 000000
-2 -5 4 ffffff
-1 -5 4 bf40bf
-16 -4 4 000000
-15 -4 4 bf40bf
-14 -4 4 000000
-13 -4 4 ffffff
-12 -4 4 000000
-11 -4 4 ffffff
-10 -4 4 000000
-9 -4 4 ffffff
-8 -4 4 bf40bf
-7 -4 4 ffffff
-6 -4 4 000000
-5 -4 4 ffffff
-4 -4 4 000000
-3 -4 4 bf40bf
-2 -4 4 000000
-1 -4 4 ffffff
-16 -3 4 bf40bf
-15 -3 4 000000
-14 -3 4 ffffff
-13 -3 4 000000
-12 -3 4 bf40bf
-11 -3 4 000000
-10 -3 4 ffffff
-9 -3 4 bf40bf
-8 -3 4 ffffff
-7 -3 4 000000
-6 -3 4 ffffff
-5 -3 4 bf40bf
-4 -3 4 ffffff
-3 -3 4 000000
-2 -3 4 ffffff
-1 -3 4 000000
-16 -2 4 000000
-15 -2 4 ffffff
-14 -2 4 000000
-13 -2 4 ffffff
-12 -2 4 bf40bf
-11 -2 4 ffffff
-10 -2 4 000000
-9 -2 4 bf40bf
-8 -2 4 000000
-7 -2 4 ffffff
-6 -2 4 000000
-5 -2 4 ffffff
-4 -2 4 000000
-3 -2 4 ffffff
-2 -2 4 000000
-1 -2 4 ffffff
-16 -1 4 ffffff
-15 -1 4 bf40bf
-14 -1 4 bf40bf
-13 -1 4 000000
-12 -1 4 ffffff
-11 -1 4 000000
-10 -1 4 ffffff
-9 -1 4 000000
-8 -1 4 ffffff
-7 -1 4 000000
-6 -1 4 ffffff
-5 -1 4 000000
-4 -1 4 ffffff
-3 -1 4 000000
-2 -1 4 ffffff
-1 -1 4 000000
-16 -16 5 bf40bf
-15 -16 5 ffffff
-14 -16 5 000000
-13 -16 5 ffffff
-12 -16 5 000000
-11 -16 5 ffffff
-10 -16 5 000000
-9 -16 5 ffffff
-8 -16 5 000000
-7 -16 5 ffffff
-6 -16 5 000000
-5 -16 5 bf40bf
-4 -16 5 000000
-3 -16 5 bf40bf
-2 -16 5 000000
-1 -16 5 ffffff
-16 -15 5 ffffff
-15 -15 5 000000
-14 -15 5 ffffff
-13 -15 5 000000
-12 -15 5 ffffff
-11 -15 5 bf40bf
-10 -15 5 ffffff
-9 -15 5 000000
-8 -15 5 bf40bf
-7 -15 5 000000
-6 -15 5 bf40bf
-5 -15 5 000000
-4 -15 5 ffffff
-3 -15 5 000000
-2 -15 5 ffffff
-1 -15 5 bf40bf
-16 -14 5 bf40bf
-15 -14 5 ffffff
-14 -14 5 000000
-13 -14 5 bf40bf
-12 -14 5 000000
-11 -14 5 ffffff
-10 -14 5 bf40bf
-9 -14 5 bf40bf
-8 -14 5 000000
-7 -14 5 ffffff
-6 -14 5 bf40bf
-5 -14 5 ffffff
-4 -14 5 000000
-3 -14 5 ffffff
-2 -14 5 000000
-1 -14 5 bf40bf
-16 -13 5 ffffff
-15 -13 5 bf40bf
-14 -13 5 bf40bf
-13 -13 5 bf40bf
-12 -13 5 ffffff
-11 -13 5 bf40bf
-10 -13 5 bf40bf
-9 -13 5 bf40bf
-8 -13 5 ffffff
-7 -13 5 000000
-6 -13 5 bf40bf
-5 -13 5 000000
-4 -13 5 ffffff
-3 -13 5 000000
-2 -13 5 ffffff
-1 -13 5 000000
-16 -12 5 000000
-15 -12 5 bf40bf
-14 -12 5 bf40bf
-13 -12 5 ffffff
-12 -12 5 000000
-11 -12 5 ffffff
-10 -12 5 000000
-9 -12 5 ffffff
-8 -12 5 000000
-7 -12 5 ffffff
-6 -12 5 000000
-5 -12 5 ffffff
-4 -12 5 000000
-3 -12 5 ffffff
-2 -12 5 000000
-1 -12 5 ffffff
-16 -11 5 bf40bf
-15 -11 5 000000
-14 -11 5 ffffff
-13 -11 5 000000
-12 -11 5 ffffff
-11 -11 5 000000
-10 -11 5 ffffff
-9 -11 5 000000
-8 -11 5 ffffff
-7 -11 5 000000
-6 -11 5 ffffff
-5 -11 5 000000
-4 -11 5 ffffff
-3 -11 5 000000
-2 -11 5 ffffff
-1 -11 5 bf40bf
-16 -10 5 000000
-15 -10 5 ffffff
-14 -10 5 bf40bf
-13 -10 5 ffffff
-12 -10 5 000000
-11 -10 5 bf40bf
-10 -10 5 000000
-9 -10 5 ffffff
-8 -10 5 000000
-7 -10 5 ffffff
-6 -10 5 000000
-5 -10 5 ffffff
-4 -10 5 000000
-3 -10 5 ffffff
-2 -10 5 000000
-1 -10 5 bf40bf
-16 -9 5 ffffff
-15 -9 5 000000
-14 -9 5 ffffff
-13 -9 5 000000
-12 -9 5 bf40bf
-11 -9 5 000000
-10 -9 5 bf40bf
-9 -9 5 bf40bf
-8 -9 5 ffffff
-7 -9 5 000000
-6 -9 5 ffffff
-5 -9 5 bf40bf
-4 -9 5 ffffff
-3 -9 5 000000
-2 -9 5 ffffff
-1 -9 5 bf40bf
-16 -8 5 000000
-15 -8 5 ffffff
-14 -8 5 000000
-13 -8 5 ffffff
-12 -8 5 000000
-11 -8 5 ffffff
-10 -8 5 000000
-9 -8 5 ffffff
-8 -8 5 000000
-7 -8 5 bf40bf
-6 -8 5 000000
-5 -8 5 ffffff
-4 -8 5 000000
-3 -8 5 ffffff
-2 -8 5 000000
-1 -8 5 ffffff
-16 -7 5 bf40bf
-15 -7 5 000000
-14 -7 5 ffffff
-13 -7 5 bf40bf
-12 -7 5 ffffff
-11 -7 5 000000
-10 -7 5 bf40bf
-9 -7 5 000000
-8 -7 5 bf40bf
-7 -7 5 000000
-6 -7 5 bf40bf
-5 -7 5 bf40bf
-4 -7 5 ffffff
-3 -7 5 000000
-2 -7 5 ffffff
-1 -7 5 000000
-16 -6 5 000000
-15 -6 5 bf40bf
-14 -6 5 bf40bf
-13 -6 5 ffffff
-12 -6 5 000000
-11 -6 5 ffffff
-10 -6 5 000000
-9 -6 5 ffffff
-8 -6 5 000000
-7 -6 5 ffffff
-6 -6 5 000000
-5 -6 5 ffffff
-4 -6 5 bf40bf
-3 -6 5 bf40bf
-2 -6 5 000000
-1 -6 5 ffffff
-16 -5 5 ffffff
-15 -5 5 000000
-14 -5 5 bf40bf
-13 -5 5 bf40bf
-12 -5 5 bf40bf
-11 -5 5 000000
-10 -5 5 ffffff
-9 -5 5 000000
-8 -5 5 ffffff
-7 -5 5 000000
-6 -5 5 ffffff
-5 -5 5 000000
-4 -5 5 ffffff
-3 -5 5 000000
-2 -5 5 ffffff
-1 -5 5 bf40bf
-16 -4 5 000000
-15 -4 5 bf40bf
-14 -4 5 000000
-13 -4 5 ffffff
-12 -4 5 000000
-11 -4 5 ffffff
-10 -4 5 000000
-9 -4 5 ffffff
-8 -4 5 bf40bf
-7 -4 5 ffffff
-6 -4 5 000000
-5 -4 5 ffffff
-4 -4 5 000000
-3 -4 5 bf40bf
-2 -4 5 000000
-1 -4 5 ffffff
-16 -3 5 bf40bf
-15 -3 5 000000
-14 -3 5 ffffff
-13 -3 5 000000
-12 -3 5 bf40bf
-11 -3 5 000000
-10 -3 5 ffffff
-9 -3 5 bf40bf
-8 -3 5 ffffff
-7 -3 5 000000
-6 -3 5 ffffff
-5 -3 5 bf40bf
-4 -3 5 ffffff
-3 -3 5 000000
-2 -3 5 ffffff
-1 -3 5 000000
-16 -2 5 000000
-15 -2 5 ffffff
-14 -2 5 000000
-13 -2 5 ffffff
-12 -2 5 bf40bf
-11 -2 5 ffffff
-10 -2 5 000000
-9 -2 5 bf40bf
-8 -2 5 000000
-7 -2 5 ffffff
-6 -2 5 000000
-5 -2 5 ffffff
-4 -2 5 000000
-3 -2 5 ffffff
-2 -2 5 000000
-1 -2 5 ffffff
-16 -1 5 ffffff
-15 -1 5 bf40bf
-14 -1 5 bf40bf
-13 -1 5 000000
-12 -1 5 ffffff
-11 -1 5 000000
-10 -1 5 ffffff
-9 -1 5 000000
-8 -1 5 ffffff
-7 -1 5 000000
-6 -1 5 ffffff
-5 -1 5 000000
-4 -1 5 ffffff
-3 -1 5 000000
-2 -1 5 ffffff
-1 -1 5 000000
-16 -16 6 bf40bf
-15 -16 6 ffffff
-14 -16 6 000000
-13 -16 6 ffffff
-12 -16 6 000000
-11 -16 6 ffffff
-10 -16 6 000000
-9 -16 6 ffffff
-8 -16 6 000000
-7 -16 6 ffffff
-6 -16 6 000000
-5 -16 6 bf40bf
-4 -16 6 000000
-3 -16 6 bf40bf
-2 -16 6 000000
-1 -16 6 ffffff
-16 -15 6 ffffff
-15 -15 6 000000
-14 -15 6 ffffff
-13 -15 6 000000
-12 -15 6 ffffff
-11 -15 6 bf40bf
-10 -15 6 ffffff
-9 -15 6 000000
-8 -15 6 bf40bf
-7 -15 6 000000
-6 -15 6 bf40bf
-5 -15 6 000000
-4 -15 6 ffffff
-3 -15 6 000000
-2 -15 6 ffffff
-1 -15 6 bf40bf
-16 -14 6 bf40bf
-15 -14 6 ffffff
-14 -14 6 000000
-13 -14 6 bf40bf
-12 -14 6 000000
-11 -14 6 ffffff
-10 -14 6 bf40bf
-9 -14 6 bf40bf
-8 -14 6 000000
-7 -14 6 ffffff
-6 -14 6 bf40bf
-5 -14 6 ffffff
-4 -14 6 000000
-3 -14 6 ffffff
-2 -14 6 000000
-1 -14 6 bf40bf
-16 -13 6 ffffff
-15 -13 6 bf40bf
-14 -13 6 bf40bf
-13 -13 6 bf40bf
-12 -13 6 ffffff
-11 -13 6 bf40bf
-10 -13 6 bf40bf
-9 -13 6 bf40bf
-8 -13 6 ffffff
-7 -13 6 000000
-6 -13 6 bf40bf
-5 -13 6 000000
-4 -13 6 ffffff
-3 -13 6 000000
-2 -13 6 ffffff
-1 -13 6 000000
-16 -12 6 000000
-15 -12 6 bf40bf
-14 -12 6 bf40bf
-13 -12 6 ffffff
-12 -12 6 000000
-11 -12 6 ffffff
-10 -12 6 000000
-9 -12 6 ffffff
-8 -12 6 000000
-7 -12 6 ffffff
-6 -12 6 000000
-5 -12 6 ffffff
-4 -12 6 000000
-3 -12 6 ffffff
-2 -12 6 000000
-1 -12 6 ffffff
-16 -11 6 bf40bf
-15 -11 6 000000
-14 -11 6 ffffff
-13 -11 6 000000
-12 -11 6 ffffff
-11 -11 6 000000
-10 -11 6 ffffff
-9 -11 6 000000
-8 -11 6 ffffff
-7 -11 6 000000
-6 -11 6 ffffff
-5 -11 6 000000
-4 -11 6 ffffff
-3 -11 6 000000
-2 -11 6 ffffff
-1 -11 6 bf40bf
-16 -10 6 000000
-15 -10 6 ffffff
-14 -10 6 bf40bf
-13 -10 6 ffffff
-12 -10 6 000000
-11 -10 6 bf40bf
-10 -10 6 000000
-9 -10 6 ffffff
-8 -10 6 000000
-7 -10 6 ffffff
-6 -10 6 000000
-5 -10 6 ffffff
-4 -10 6 000000
-3 -10 6 ffffff
-2 -10 6 000000
-1 -10 6 bf40bf
-16 -9 6 ffffff
-15 -9 6 000000
-14 -9 6 ffffff
-13 -9 6 000000
-12 -9 6 bf40bf
-11 -9 6 000000
-10 -9 6 bf40bf
-9 -9 6 bf40bf
-8 -9 6 ffffff
-7 -9 6 000000
-6 -9 6 ffffff
-5 -9 6 bf40bf
-4 -9 6 ffffff
-3 -9 6 000000
-2 -9 6 ffffff
-1 -9 6 bf40bf
-16 -8 6 000000
-15 -8 6 ffffff
-14 -8 6 000000
-13 -8 6 ffffff
-12 -8 6 000000
-11 -8 6 ffffff
-10 -8 6 000000
-9 -8 6 ffffff
-8 -8 6 000000
-7 -8 6 bf40bf
-6 -8 6 000000
-5 -8 6 ffffff
-4 -8 6 000000
-3 -8 6 ffffff
-2 -8 6 000000
-1 -8 6 ffffff
-16 -7 6 bf40bf
-15 -7 6 000000
-14 -7 6 ffffff
-13 -7 6 bf40bf
-12 -7 6 ffffff
-11 -7 6 000000
-10 -7 6 bf40bf
-9 -7 6 000000
-8 -7 6 bf40bf
-7 -7 6 000000
-6 -7 6 bf40bf
-5 -7 6 bf40bf
-4 -7 6 ffffff
-3 -7 6 000000
-2 -7 6 ffffff
-1 -7 6 000000
-16 -6 6 000000
-15 -6 6 bf40bf
-14 -6 6 bf40bf
-13 -6 6 ffffff
-12 -6 6 000000
-11 -6 6 ffffff
-10 -6 6 000000
-9 -6 6 ffffff
-8 -6 6 000000
-7 -6 6 ffffff
-6 -6 6 000000
-5 -6 6 ffffff
-4 -6 6 bf40bf
-3 -6 6 bf40bf
-2 -6 6 000000
-1 -6 6 ffffff
-16 -5 6 ffffff
-15 -5 6 000000
-14 -5 6 bf40bf
-13 -5 6 bf40bf
-12 -5 6 bf40bf
-11 -5 6 000000
-10 -5 6 ffffff
-9 -5 6 000000
-8 -5 6 ffffff
-7 -5 6 000000
-6 -5 6 ffffff
-5 -5 6 000000
-4 -5 6 ffffff
-3 -5 6 000000
-2 -5 6 ffffff
-1 -5 6 bf40bf
-16 -4 6 000000
-15 -4 6 bf40bf
-14 -4 6 000000
-13 -4 6 ffffff
-12 -4 6 000000
-11 -4 6 ffffff
-10 -4 6 000000
-9 -4 6 ffffff
-8 -4 6 bf40bf
-7 -4 6 ffffff
-6 -4 6 000000
-5 -4 6 ffffff
-4 -4 6 000000
-3 -4 6 bf40bf
-2 -4 6 000000
-1 -4 6 ffffff
-16 -3 6 bf40bf
-15 -3 6 000000
-14 -3 6 ffffff
-13 -3 6 000000
-12 -3 6 bf40bf
-11 -3 6 000000
-10 -3 6 ffffff
-9 -3 6 bf40bf
-8 -3 6 ffffff
-7 -3 6 000000
-6 -3 6 ffffff
-5 -3 6 bf40bf
-4 -3 6 ffffff
-3 -3 6 000000
-2 -3 6 ffffff
-1 -3 6 000000
-16 -2 6 000000
-15 -2 6 ffffff
-14 -2 6 000000
-13 -2 6 ffffff
-12 -2 6 bf40bf
-11 -2 6 ffffff
-10 -2 6 000000
-9 -2 6 bf40bf
-8 -2 6 000000
-7 -2 6 ffffff
-6 -2 6 000000
-5 -2 6 ffffff
-4 -2 6 000000
-3 -2 6 ffffff
-2 -2 6 000000
-1 -2 6 ffffff
-16 -1 6 ffffff
-15 -1 6 bf40bf
-14 -1 6 bf40bf
-13 -1 6 000000
-12 -1 6 ffffff
-11 -1 6 000000
-10 -1 6 ffffff
-9 -1 6 000000
-8 -1 6 ffffff
-7 -1 6 000000
-6 -1 6 ffffff
-5 -1 6 000000
-4 -1 6 ffffff
-3 -1 6 000000
-2 -1 6 ffffff
-1 -1 6 000000
-16 -16 7 bf40bf
-15 -16 7 ffffff
-14 -16 7 000000
-13 -16 7 ffffff
-12 -16 7 000000
-11 -16 7 ffffff
-10 -16 7 000000
-9 -16 7 ffffff
-8 -16 7 000000
-7 -16 7 ffffff
-6 -16 7 000000
-5 -16 7 bf40bf
-4 -16 7 000000
-3 -16 7 bf40bf
-2 -16 7 000000
-1 -16 7 ffffff
-16 -15 7 ffffff
-15 -15 7 000000
-14 -15 7 ffffff
-13 -15 7 000000
-12 -15 7 ffffff
-11 -15 7 bf40bf
-10 -15 7 ffffff
-9 -15 7 000000
-8 -15 7 bf40bf
-7 -15 7 000000
-6 -15 7 bf40bf
-5 -15 7 000000
-4 -15 7 ffffff
-3 -15 7 000000
-2 -15 7 ffffff
-1 -15 7 bf40bf
-16 -14 7 bf40bf
-15 -14 7 ffffff
-14 -14 7 000000
-13 -14 7 bf40bf
-12 -14 7 000000
-11 -14 7 ffffff
-10 -14 7 bf40bf
-9 -14 7 bf40bf
-8 -14 7 000000
-7 -14 7 ffffff
-6 -14 7 bf40bf
-5 -14 7 ffffff
-4 -14 7 000000
-3 -14 7 ffffff
-2 -14 7 000000
-1 -14 7 bf40bf
-16 -13 7 ffffff
-15 -13 7 bf40bf
-14 -13 7 bf40bf
-13 -13 7 bf40bf
-12 -13 7 ffffff
-11 -13 7 bf40bf
-10 -13 7 bf40bf
-9 -13 7 bf40bf
-8 -13 7 ffffff
-7 -13 7 000000
-6 -13 7 bf40bf
-5 -13 7 000000
-4 -13 7 ffffff
-3 -13 7 000000
-2 -13 7 ffffff
-1 -13 7 000000
-16 -12 7 000000
-15 -12 7 bf40bf
-14 -12 7 bf40bf
-13 -12 7 ffffff
-12 -12 7 000000
-11 -12 7 ffffff
-10 -12 7 000000
-9 -12 7 ffffff
-8 -12 7 000000
-7 -12 7 ffffff
-6 -12 7 000000
-5 -12 7 ffffff
-4 -12 7 000000
-3 -12 7 ffffff
-2 -12 7 000000
-1 -12 7 ffffff
-16 -11 7 bf40bf
-15 -11 7 000000
-14 -11 7 ffffff
-13 -11 7 000000
-12 -11 7 ffffff
-11 -11 7 000000
-10 -11 7 ffffff
-9 -11 7 000000
-8 -11 7 ffffff
-7 -11 7 000000
-6 -11 7 ffffff
-5 -11 7 000000
-4 -11 7 ffffff
-3 -11 7 000000
-2 -11 7 ffffff
-1 -11 7 bf40bf
-16 -10 7 000000
-15 -10 7 ffffff
-14 -10 7 bf40bf
-13 -10 7 ffffff
-12 -10 7 000000
-11 -10 7 bf40bf
-10 -10 7 000000
-9 -10 7 ffffff
-8 -10 7 000000
-7 -10 7 ffffff
-6 -10 7 000000
-5 -10 7 ffffff
-4 -10 7 000000
-3 -10 7 ffffff
-2 -10 7 000000
-1 -10 7 bf40bf
-16 -9 7 ffffff
-15 -9 7 000000
-14 -9 7 ffffff
-13 -9 7 000000
-12 -9 7 bf40bf
-11 -9 7 000000
-10 -9 7 bf40bf
-9 -9 7 bf40bf
-8 -9 7 ffffff
-7 -9 7 000000
-6 -9 7 ffffff
-5 -9 7 bf40bf
-4 -9 7 ffffff
-3 -9 7 000000
-2 -9 7 ffffff
-1 -9 7 bf40bf
-16 -8 7 000000
-15 -8 7 ffffff
-14 -8 7 000000
-13 -8 7 ffffff
-12 -8 7 000000
-11 -8 7 ffffff
-10 -8 7 000000
-9 -8 7 ffffff
-8 -8 7 000000
-7 -8 7 bf40bf
-6 -8 7 000000
-5 -8 7 ffffff
-4 -8 7 000000
-3 -8 7 ffffff
-2 -8 7 000000
-1 -8 7 ffffff
-16 -7 7 bf40bf
-15 -7 7 000000
-14 -7 7 ffffff
-13 -7 7 bf40bf
-12 -7 7 ffffff
-11 -7 7 000000
-10 -7 7 bf40bf
-9 -7 7 000000
-8 -7 7 bf40bf
-7 -7 7 000000
-6 -7 7 bf40bf
-5 -7 7 bf40bf
-4 -7 7 ffffff
-3 -7 7 000000
-2 -7 7 ffffff
-1 -7 7 000000
-16 -6 7 000000
-15 -6 7 bf40bf
-14 -6 7 bf40bf
-13 -6 7 ffffff
-12 -6 7 000000
-11 -6 7 ffffff
-10 -6 7 000000
-9 -6 7 ffffff
-8 -6 7 000000
-7 -6 7 ffffff
-6 -6 7 000000
-5 -6 7 ffffff
-4 -6 7 bf40bf
-3 -6 7 bf40bf
-2 -6 7 000000
-1 -6 7 ffffff
-16 -5 7 ffffff
-15 -5 7 000000
-14 -5 7 bf40bf
-13 -5 7 bf40bf
-12 -5 7 bf40bf
-11 -5 7 000000
-10 -5 7 ffffff
-9 -5 7 000000
-8 -5 7 ffffff
-7 -5 7 000000
-6 -5 7 ffffff
-5 -5 7 000000
-4 -5 7 ffffff
-3 -5 7 000000
-2 -5 7 ffffff
-1 -5 7 bf40bf
-16 -4 7 000000
-15 -4 7 bf40bf
-14 -4 7 000000
-13 -4 7 ffffff
-12 -4 7 000000
-11 -4 7 ffffff
-10 -4 7 000000
-9 -4 7 ffffff
-8 -4 7 bf40bf
-7 -4 7 ffffff
-6 -4 7 000000
-5 -4 7 ffffff
-4 -4 7 000000
-3 -4 7 bf40bf
-2 -4 7 000000
-1 -4 7 ffffff
-16 -3 7 bf40bf
-15 -3 7 000000
-14 -3 7 ffffff
-13 -3 7 000000
-12 -3 7 bf40bf
-11 -3 7 000000
-10 -3 7 ffffff
-9 -3 7 bf40bf
-8 -3 7 ffffff
-7 -3 7 000000
-6 -3 7 ffffff
-5 -3 7 bf40bf
-4 -3 7 ffffff
-3 -3 7 000000
-2 -3 7 ffffff
-1 -3 7 000000
-16 -2 7 000000
-15 -2 7 ffffff
-14 -2 7 000000
-13 -2 7 ffffff
-12 -2 7 bf40bf
-11 -2 7 ffffff
-10 -2 7 000000
-9 -2 7 bf40bf
-8 -2 7 000000
-7 -2 7 ffffff
-6 -2 7 000000
-5 -2 7 ffffff
-4 -2 7 000000
-3 -2 7 ffffff
-2 -2 7 000000
-1 -2 7 ffffff
-16 -1 7 ffffff
-15 -1 7 bf40bf
-14 -1 7 bf40bf
-13 -1 7 000000
-12 -1 7 ffffff
-11 -1 7 000000
-10 -1 7 ffffff
-9 -1 7 000000
-8 -1 7 ffffff
-7 -1 7 000000
-6 -1 7 ffffff
-5 -1 7 000000
-4 -1 7 ffffff
-3 -1 7 000000
-2 -1 7 ffffff
-1 -1 7 000000
-16 -16 8 bf40bf
-15 -16 8 ffffff
-14 -16 8 000000
-13 -16 8 ffffff
-12 -16 8 000000
-11 -16 8 ffffff
-10 -16 8 000000
-9 -16 8 ffffff
-8 -16 8 000000
-7 -16 8 ffffff
-6 -16 8 000000
-5 -16 8 bf40bf
-4 -16 8 000000
-3 -16 8 bf40bf
-2 -16 8 000000
-1 -16 8 ffffff
-16 -15 8 ffffff
-15 -15 8 000000
-14 -15 8 ffffff
-13 -15 8 000000
-12 -15 8 ffffff
-11 -15 8 bf40bf
-10 -15 8 ffffff
-9 -15 8 000000
-8 -15 8 bf40bf
-7 -15 8 000000
-6 -15 8 bf40bf
-5 -15 8 000000
-4 -15 8 ffffff
-3 -15 8 000000
-2 -15 8 ffffff
-1 -15 8 bf40bf
-16 -14 8 bf40bf
-15 -14 8 ffffff
-14 -14 8 000000
-13 -14 8 bf40bf
-12 -14 8 000000
-11 -14 8 ffffff
-10 -14 8 bf40bf
-9 -14 8 bf40bf
-8 -14 8 000000
-7 -14 8 ffffff
-6 -14 8 bf40bf
-5 -14 8 ffffff
-4 -14 8 000000
-3 -14 8 ffffff
-2 -14 8 000000
-1 -14 8 bf40bf
-16 -13 8 ffffff
-15 -13 8 bf40bf
-14 -13 8 bf40bf
-13 -13 8 bf40bf
-12 -13 8 ffffff
-11 -13 8 bf40bf
-10 -13 8 bf40bf
-9 -13 8 bf40bf
-8 -13 8 ffffff
-7 -13 8 000000
-6 -13 8 bf40bf
-5 -13 8 000000
-4 -13 8 ffffff
-3 -13 8 000000
-2 -13 8 ffffff
-1 -13 8 000000
-16 -12 8 000000
-15 -12 8 bf40bf
-14 -12 8 bf40bf
-13 -12 8 ffffff
-12 -12 8 000000
-11 -12 8 ffffff
-10 -12 8 000000
-9 -12 8 ffffff
-8 -12 8 000000
-7 -12 8 ffffff
-6 -12 8 000000
-5 -12 8 ffffff
-4 -12 8 000000
-3 -12 8 ffffff
-2 -12 8 000000
-1 -12 8 ffffff
-16 -11 8 bf40bf
-15 -11 8 000000
-14 -11 8 ffffff
-13 -11 8 000000
-12 -11 8 ffffff
-11 -11 8 000000
-10 -11 8 ffffff
-9 -11 8 000000
-8 -11 8 ffffff
-7 -11 8 000000
-6 -11 8 ffffff
-5 -11 8 000000
-4 -11 8 ffffff
-3 -11 8 000000
-2 -11 8 ffffff
-1 -11 8 bf40bf
-16 -10 8 000000
-15 -10 8 ffffff
-14 -10 8 bf40bf
-13 -10 8 ffffff
-12 -10 8 000000
-11 -10 8 bf40bf
-10 -10 8 000000
-9 -10 8 ffffff
-8 -10 8 000000
-7 -10 8 ffffff
-6 -10 8 000000
-5 -10 8 ffffff
-4 -10 8 000000
-3 -10 8 ffffff
-2 -10 8 000000
-1 -10 8 bf40bf
-16 -9 8 ffffff
-15 -9 8 000000
-14 -9 8 ffffff
-13 -9 8 000000
-12 -9 8 bf40bf
-11 -9 8 000000
-10 -9 8 bf40bf
-9 -9 8 bf40bf
-8 -9 8 ffffff
-7 -9 8 000000
-6 -9 8 ffffff
-5 -9 8 bf40bf
-4 -9 8 ffffff
-3 -9 8 000000
-2 -9 8 ffffff
-1 -9 8 bf40bf
-16 -8 8 000000
-15 -8 8 ffffff
-14 -8 8 000000
-13 -8 8 ffffff
-12 -8 8 000000
-11 -8 8 ffffff
-10 -8 8 000000
-9 -8 8 ffffff
-8 -8 8 000000
-7 -8 8 bf40bf
-6 -8 8 000000
-5 -8 8 ffffff
-4 -8 8 000000
-3 -8 8 ffffff
-2 -8 8 000000
-1 -8 8 ffffff
-16 -7 8 bf40bf
-15 -7 8 000000
-14 -7 8 ffffff
-13 -7 8 bf40bf
-12 -7 8 ffffff
-11 -7 8 000000
-10 -7 8 bf40bf
-9 -7 8 000000
-8 -7 8 bf40bf
-7 -7 8 000000
-6 -7 8 bf40bf
-5 -7 8 bf40bf
-4 -7 8 ffffff
-3 -7 8 000000
-2 -7 8 ffffff
-1 -7 8 000000
-16 -6 8 000000
-15 -6 8 bf40bf
-14 -6 8 bf40bf
-13 -6 8 ffffff
-12 -6 8 000000
-11 -6 8 ffffff
-10 -6 8 000000
-9 -6 8 ffffff
-8 -6 8 000000
-7 -6 8 ffffff
-6 -6 8 000000
-5 -6 8 ffffff
-4 -6 8 bf40bf
-3 -6 8 bf40bf
-2 -6 8 000000
-1 -6 8 ffffff
-16 -5 8 ffffff
-15 -5 8 000000
-14 -5 8 bf40bf
-13 -5 8 bf40bf
-12 -5 8 bf40bf
-11 -5 8 000000
-10 -5 8 ffffff
-9 -5 8 000000
-8 -5 8 ffffff
-7 -5 8 000000
-6 -5 8 ffffff
-5 -5 8 000000
-4 -5 8 ffffff
-3 -5 8 000000
-2 -5 8 ffffff
-1 -5 8 bf40bf
-16 -4 8 000000
-15 -4 8 bf40bf
-14 -4 8 000000
-13 -4 8 ffffff
-12 -4 8 000000
-11 -4 8 ffffff
-10 -4 8 000000
-9 -4 8 ffffff
-8 -4 8 bf40bf
-7 -4 8 ffffff
-6 -4 8 000000
-5 -4 8 ffffff
-4 -4 8 000000
-3 -4 8 bf40bf
-2 -4 8 000000
-1 -4 8 ffffff
-16 -3 8 bf40bf
-15 -3 8 000000
-14 -3 8 ffffff
-13 -3 8 000000
-12 -3 8 bf40bf
-11 -3 8 000000
-10 -3 8 ffffff
-9 -3 8 bf40bf
-8 -3 8 ffffff
-7 -3 8 000000
-6 -3 8 ffffff
-5 -3 8 bf40bf
-4 -3 8 ffffff
-3 -3 8 000000
-2 -3 8 ffffff
-1 -3 8 000000
-16 -2 8 000000
-15 -2 8 ffffff
-14 -2 8 000000
-13 -2 8 ffffff
-12 -2 8 bf40bf
-11 -2 8 ffffff
-10 -2 8 000000
-9 -2 8 bf40bf
-8 -2 8 000000
-7 -2 8 ffffff
-6 -2 8 000000
-5 -2 8 ffffff
-4 -2 8 000000
-3 -2 8 ffffff
-2 -2 8 000000
-1 -2 8 ffffff
-16 -1 8 ffffff
-15 -1 8 bf40bf
-14 -1 8 bf40bf
-13 -1 8 000000
-12 -1 8 ffffff
-11 -1 8 000000
-10 -1 8 ffffff
-9 -1 8 000000
-8 -1 8 ffffff
-7 -1 8 000000
-6 -1 8 ffffff
-5 -1 8 000000
-4 -1 8 ffffff
-3 -1 8 000000
-2 -1 8 ffffff
-1 -1 8 000000
-16 -16 9 bf40bf
-15 -16 9 ffffff
-14 -16 9 000000
-13 -16 9 ffffff
-12 -16 9 000000
-11 -16 9 ffffff
-10 -16 9 000000
-9 -16 9 ffffff
-8 -16 9 000000
-7 -16 9 ffffff
-4 -16 9 000000
-3 -16 9 bf40bf
-2 -16 9 000000
-1 -16 9 ffffff
-16 -15 9 ffffff
-15 -15 9 000000
-14 -15 9 ffffff
-13 -15 9 000000
-12 -15 9 ffffff
-11 -15 9 bf40bf
-10 -15 9 ffffff
-9 -15 9 000000
-8 -15 9 bf40bf
-7 -15 9 000000
-4 -15 9 ffffff
-3 -15 9 000000
-2 -15 9 ffffff
-1 -15 9 bf40bf
-16 -14 9 bf40bf
-15 -14 9 ffffff
-14 -14 9 000000
-13 -14 9 bf40bf
-12 -14 9 000000
-11 -14 9 ffffff
-10 -14 9 bf40bf
-9 -14 9 bf40bf
-8 -14 9 000000
-7 -14 9 ffffff
-4 -14 9 000000
-3 -14 9 ffffff
-2 -14 9 000000
-1 -14 9 bf40bf
-16 -13 9 ffffff
-15 -13 9 bf40bf
-14 -13 9 bf40bf
-13 -13 9 bf40bf
-12 -13 9 ffffff
-11 -13 9 bf40bf
-10 -13 9 bf40bf
-9 -13 9 bf40bf
-8 -13 9 ffffff
-7 -13 9 000000
-4 -13 9 ffffff
-3 -13 9 000000
-2 -13 9 ffffff
-1 -13 9 000000
-16 -12 9 000000
-15 -12 9 bf40bf
-14 -12 9 bf40bf
-13 -12 9 ffffff
-12 -12 9 000000
-11 -12 9 ffffff
-10 -12 9 000000
-9 -12 9 ffffff
-8 -12 9 000000
-7 -12 9 ffffff
-4 -12 9 000000
-3 -12 9 ffffff
-2 -12 9 000000
-1 -12 9 ffffff
-16 -11 9 bf40bf
-15 -11 9 000000
-14 -11 9 ffffff
-13 -11 9 000000
-12 -11 9 ffffff
-11 -11 9 000000
-10 -11 9 ffffff
-9 -11 9 000000
-8 -11 9 ffffff
-7 -11 9 000000
-4 -11 9 ffffff
-3 -11 9 000000
-2 -11 9 ffffff
-1 -11 9 bf40bf
-16 -10 9 000000
-15 -10 9 ffffff
-14 -10 9 bf40bf
-13 -10 9 ffffff
-12 -10 9 000000
-11 -10 9 bf40bf
-10 -10 9 000000
-9 -10 9 ffffff
-8 -10 9 000000
-7 -10 9 ffffff
-4 -10 9 000000
-3 -10 9 ffffff
-2 -10 9 000000
-1 -10 9 bf40bf
-16 -9 9 ffffff
-15 -9 9 000000
-14 -9 9 ffffff
-13 -9 9 000000
-12 -9 9 bf40bf
-11 -9 9 000000
-10 -9 9 bf40bf
-9 -9 9 bf40bf
-8 -9 9 ffffff
-7 -9 9 000000
-4 -9 9 ffffff
-3 -9 9 000000
-2 -9 9 ffffff
-1 -9 9 bf40bf
-16 -8 9 000000
-15 -8 9 ffffff
-14 -8 9 000000
-13 -8 9 ffffff
-12 -8 9 000000
-11 -8 9 ffffff
-10 -8 9 000000
-9 -8 9 ffffff
-8 -8 9 000000
-7 -8 9 bf40bf
-4 -8 9 000000
-3 -8 9 ffffff
-2 -8 9 000000
-1 -8 9 ffffff
-16 -7 9 bf40bf
-15 -7 9 000000
-14 -7 9 ffffff
-13 -7 9 bf40bf
-12 -7 9 ffffff
-11 -7 9 000000
-10 -7 9 bf40bf
-9 -7 9 000000
-8 -7 9 bf40bf
-7 -7 9 000000
-4 -7 9 ffffff
-3 -7 9 000000
-2 -7 9 ffffff
-1 -7 9 000000
-16 -6 9 000000
-15 -6 9 bf40bf
-14 -6 9 bf40bf
-13 -6 9 ffffff
-12 -6 9 000000
-11 -6 9 ffffff
-10 -6 9 000000
-9 -6 9 ffffff
-8 -6 9 000000
-7 -6 9 ffffff
-4 -6 9 bf40bf
-3 -6 9 bf40bf
-2 -6 9 000000
-1 -6 9 ffffff
-16 -5 9 ffffff
-15 -5 9 000000
-14 -5 9 bf40bf
-13 -5 9 bf40bf
-12 -5 9 bf40bf
-11 -5 9 000000
-10 -5 9 ffffff
-9 -5 9 000000
-8 -5 9 ffffff
-7 -5 9 000000
-4 -5 9 ffffff
-3 -5 9 000000
-2 -5 9 ffffff
-1 -5 9 bf40bf
-16 -4 9 000000
-15 -4 9 bf40bf
-14 -4 9 000000
-13 -4 9 ffffff
-12 -4 9 000000
-11 -4 9 ffffff
-10 -4 9 000000
-9 -4 9 ffffff
-8 -4 9 bf40bf
-7 -4 9 ffffff
-4 -4 9 000000
-3 -4 9 bf40bf
-2 -4 9 000000
-1 -4 9 ffffff
-16 -3 9 bf40bf
-15 -3 9 000000
-14 -3 9 ffffff
-13 -3 9 000000
-12 -3 9 bf40bf
-11 -3 9 000000
-10 -3 9 ffffff
-9 -3 9 bf40bf
-8 -3 9 ffffff
-7 -3 9 000000
-4 -3 9 ffffff
-3 -3 9 000000
-2 -3 9 ffffff
-1 -3 9 000000
-16 -2 9 000000
-15 -2 9 ffffff
-14 -2 9 000000
-13 -2 9 ffffff
-12 -2 9 bf40bf
-11 -2 9 ffffff
-10 -2 9 000000
-9 -2 9 bf40bf
-8 -2 9 000000
-7 -2 9 ffffff
-4 -2 9 000000
-3 -2 9 ffffff
-2 -2 9 000000
-1 -2 9 ffffff
-16 -1 9 ffffff
-15 -1 9 bf40bf
-14 -1 9 bf40bf
-13 -1 9 000000
-12 -1 9 ffffff
-11 -1 9 000000
-10 -1 9 ffffff
-9 -1 9 000000
-8 -1 9 ffffff
-7 -1 9 000000
-4 -1 9 ffffff
-3 -1 9 000000
-2 -1 9 ffffff
-1 -1 9 000000
-16 -16 10 bf40bf
-15 -16 10 ffffff
-14 -16 10 000000
-13 -16 10 ffffff
-12 -16 10 000000
-11 -16 10 ffffff
-10 -16 10 000000
-9 -16 10 ffffff
-8 -16 10 000000
-4 -16 10 000000
-3 -16 10 bf40bf
-2 -16 10 000000
-1 -16 10 ffffff
-16 -15 10 ffffff
-15 -15 10 000000
-14 -15 10 ffffff
-13 -15 10 000000
-12 -15 10 ffffff
-11 -15 10 bf40bf
-10 -15 10 ffffff
-9 -15 10 000000
-8 -15 10 bf40bf
-4 -15 10 ffffff
-3 -15 10 000000
-2 -15 10 ffffff
-1 -15 10 bf40bf
-16 -14 10 bf40bf
-15 -14 10 ffffff
-14 -14 10 000000
-13 -14 10 bf40bf
-12 -14 10 000000
-11 -14 10 ffffff
-10 -14 10 bf40bf
-9 -14 10 bf40bf
-8 -14 10 000000
-4 -14 10 000000
-3 -14 10 ffffff
-2 -14 10 000000
-1 -14 10 bf40bf
-16 -13 10 ffffff
-15 -13 10 bf40bf
-14 -13 10 bf40bf
-13 -13 10 bf40bf
-12 -13 10 ffffff
-11 -13 10 bf40bf
-10 -13 10 bf40bf
-9 -13 10 bf40bf
-8 -13 10 ffffff
-4 -13 10 ffffff
-3 -13 10 000000
-2 -13 10 ffffff
-1 -13 10 000000
-16 -12 10 000000
-15 -12 10 bf40bf
-14 -12 10 bf40bf
-13 -12 10 ffffff
-12 -12 10 000000
-11 -12 10 ffffff
-10 -12 10 000000
-9 -12 10 ffffff
-8 -12 10 000000
-4 -12 10 000000
-3 -12 10 ffffff
-2 -12 10 000000
-1 -12 10 ffffff
-16 -11 10 bf40bf
-15 -11 10 000000
-14 -11 10 ffffff
-13 -11 10 000000
-12 -11 10 ffffff
-11 -11 10 000000
-10 -11 10 ffffff
-9 -11 10 000000
-8 -11 10 ffffff
-4 -11 10 ffffff
-3 -11 10 000000
-2 -11 10 ffffff
-1 -11 10 bf40bf
-16 -10 10 000000
-15 -10 10 ffffff
-14 -10 10 bf40bf
-13 -10 10 ffffff
-12 -10 10 000000
-11 -10 10 bf40bf
-10 -10 10 000000
-9 -10 10 ffffff
-8 -10 10 000000
-4 -10 10 000000
-3 -10 10 ffffff
-2 -10 10 000000
-1 -10 10 bf40bf
-16 -9 10 ffffff
-15 -9 10 000000
-14 -9 10 ffffff
-13 -9 10 000000
-12 -9 10 bf40bf
-11 -9 10 000000
-10 -9 10 bf40bf
-9 -9 10 bf40bf
-8 -9 10 ffffff
-4 -9 10 ffffff
-3 -9 10 000000
-2 -9 10 ffffff
-1 -9 10 bf40bf
-16 -8 10 000000
-15 -8 10 ffffff
-14 -8 10 000000
-13 -8 10 ffffff
-12 -8 10 000000
-11 -8 10 ffffff
-10 -8 10 000000
-9 -8 10 ffffff
-8 -8 10 000000
-4 -8 10 000000
-3 -8 10 ffffff
-2 -8 10 000000
-1 -8 10 ffffff
-16 -7 10 bf40bf
-15 -7 10 000000
-14 -7 10 ffffff
-13 -7 10 bf40bf
-12 -7 10 ffffff
-11 -7 10 000000
-10 -7 10 bf40bf
-9 -7 10 000000
-8 -7 10 bf40bf
-4 -7 10 ffffff
-3 -7 10 000000
-2 -7 10 ffffff
-1 -7 10 000000
-16 -6 10 000000
-15 -6 10 bf40bf
-14 -6 10 bf40bf
-13 -6 10 ffffff
-12 -6 10 000000
-11 -6 10 ffffff
-10 -6 10 000000
-9 -6 10 ffffff
-8 -6 10 000000
-4 -6 10 bf40bf
-3 -6 10 bf40bf
-2 -6 10 000000
-1 -6 10 ffffff
-16 -5 10 ffffff
-15 -5 10 000000
-14 -5 10 bf40bf
-13 -5 10 bf40bf
-12 -5 10 bf40bf
-11 -5 10 000000
-10 -5 10 ffffff
-9 -5 10 000000
-8 -5 10 ffffff
-4 -5 10 ffffff
-2 -5 10 ffffff
-1 -5 10 bf40bf
-16 -4 10 000000
-15 -4 10 bf40bf
-14 -4 10 000000
-13 -4 10 ffffff
-12 -4 10 000000
-11 -4 10 ffffff
-10 -4 10 000000
-9 -4 10 ffffff
-8 -4 10 bf40bf
-4 -4 10 000000
-2 -4 10 000000
-1 -4 10 ffffff
-16 -3 10 bf40bf
-15 -3 10 000000
-14 -3 10 ffffff
-13 -3 10 000000
-12 -3 10 bf40bf
-11 -3 10 000000
-10 -3 10 ffffff
-9 -3 10 bf40bf
-8 -3 10 ffffff
-4 -3 10 ffffff
-2 -3 10 ffffff
-1 -3 10 000000
-16 -2 10 000000
-15 -2 10 ffffff
-14 -2 10 000000
-13 -2 10 ffffff
-12 -2 10 bf40bf
-11 -2 10 ffffff
-10 -2 10 000000
-9 -2 10 bf40bf
-8 -2 10 000000
-4 -2 10 000000
-2 -2 10 000000
-1 -2 10 ffffff
-16 -1 10 ffffff
-15 -1 10 bf40bf
-14 -1 10 bf40bf
-13 -1 10 000000
-12 -1 10 ffffff
-11 -1 10 000000
-10 -1 10 ffffff
-9 -1 10 000000
-8 -1 10 ffffff
-4 -1 10 ffffff
-2 -1 10 ffffff
-1 -1 10 000000
-15 -16 11 ffffff
-14 -16 11 000000
-13 -16 11 ffffff
-12 -16 11 000000
-11 -16 11 ffffff
-10 -16 11 000000
-3 -16 11 bf40bf
-1 -16 11 ffffff
-16 -15 11 ffffff
-14 -15 11 ffffff
-13 -15 11 000000
-12 -15 11 ffffff
-11 -15 11 bf40bf
-10 -15 11 ffffff
-3 -15 11 000000
-1 -15 11 bf40bf
-16 -14 11 bf40bf
-15 -14 11 ffffff
-13 -14 11 bf40bf
-12 -14 11 000000
-11 -14 11 ffffff
-10 -14 11 bf40bf
-3 -14 11 ffffff
-1 -14 11 bf40bf
-16 -13 11 ffffff
-15 -13 11 bf40bf
-13 -13 11 bf40bf
-12 -13 11 ffffff
-11 -13 11 bf40bf
-10 -13 11 bf40bf
-3 -13 11 000000
-1 -13 11 000000
-16 -12 11 000000
-15 -12 11 bf40bf
-14 -12 11 bf40bf
-12 -12 11 000000
-11 -12 11 ffffff
-10 -12 11 000000
-3 -12 11 ffffff
-1 -12 11 ffffff
-16 -11 11 bf40bf
-15 -11 11 000000
-14 -11 11 ffffff
-13 -11 11 000000
-12 -11 11 ffffff
-11 -11 11 000000
-10 -11 11 ffffff
-1 -11 11 bf40bf
-16 -10 11 000000
-15 -10 11 ffffff
-14 -10 11 bf40bf
-13 -10 11 ffffff
-12 -10 11 000000
-11 -10 11 bf40bf
-10 -10 11 000000
-16 -9 11 ffffff
-15 -9 11 000000
-14 -9 11 ffffff
-13 -9 11 000000
-12 -9 11 bf40bf
-11 -9 11 000000
-10 -9 11 bf40bf
-16 -8 11 000000
-15 -8 11 ffffff
-14 -8 11 000000
-13 -8 11 ffffff
-12 -8 11 000000
-11 -8 11 ffffff
-10 -8 11 000000
-16 -7 11 bf40bf
-15 -7 11 000000
-14 -7 11 ffffff
-13 -7 11 bf40bf
-12 -7 11 ffffff
-11 -7 11 000000
-10 -7 11 bf40bf
-16 -6 11 000000
-15 -6 11 bf40bf
-14 -6 11 bf40bf
-13 -6 11 ffffff
-12 -6 11 000000
-11 -6 11 ffffff
-10 -6 11 000000
-16 -5 11 ffffff
-15 -5 11 000000
-14 -5 11 bf40bf
-13 -5 11 bf40bf
-12 -5 11 bf40bf
-11 -5 11 000000
-10 -5 11 ffffff
-16 -4 11 000000
-15 -4 11 bf40bf
-14 -4 11 000000
-13 -4 11 ffffff
-12 -4 11 000000
-11 -4 11 ffffff
-10 -4 11 000000
-9 -4 11 ffffff
-16 -3 11 bf40bf
-15 -3 11 000000
-14 -3 11 ffffff
-13 -3 11 000000
-12 -3 11 bf40bf
-11 -3 11 000000
-10 -3 11 ffffff
-9 -3 11 bf40bf
-16 -2 11 000000
-15 -2 11 ffffff
-14 -2 11 000000
-13 -2 11 ffffff
-12 -2 11 bf40bf
-11 -2 11 ffffff
-10 -2 11 000000
-9 -2 11 bf40bf
-16 -1 11 ffffff
-15 -1 11 bf40bf
-14 -1 11 bf40bf
-13 -1 11 000000
-12 -1 11 ffffff
-11 -1 11 000000
-10 -1 11 ffffff
-9 -1 11 000000
0 -16 0 000000
1 -16 0 ffffff
2 -16 0 000000
3 -16 0 ffffff
4 -16 0 bf40bf
5 -16 0 ffffff
6 -16 0 000000
7 -16 0 ffffff
8 -16 0 000000
9 -16 0 ffffff
10 -16 0 000000
11 -16 0 bf40bf
12 -16 0 bf40bf
13 -16 0 ffffff
14 -16 0 000000
15 -16 0 ffffff
0 -15 0 bf40bf
1 -15 0 bf40bf
2 -15 0 ffffff
3 -15 0 bf40bf
4 -15 0 ffffff
5 -15 0 bf40bf
6 -15 0 ffffff
7 -15 0 000000
8 -15 0 bf40bf
9 -15 0 000000
10 -15 0 ffffff
11 -15 0 000000
12 -15 0 ffffff
13 -15 0 000000
14 -15 0 ffffff
15 -15 0 000000
0 -14 0 000000
1 -14 0 ffffff
2 -14 0 bf40bf
3 -14 0 ffffff
4 -14 0 000000
5 -14 0 ffffff
6 -14 0 000000
7 -14 0 ffffff
8 -14 0 000000
9 -14 0 ffffff
10 -14 0 bf40bf
11 -14 0 ffffff
12 -14 0 000000
13 -14 0 ffffff
14 -14 0 000000
15 -14 0 ffffff
0 -13 0 ffffff
1 -13 0 000000
2 -13 0 ffffff
3 -13 0 bf40bf
4 -13 0 ffffff
5 -13 0 000000
6 -13 0 ffffff
7 -13 0 000000
8 -13 0 ffffff
9 -13 0 000000
10 -13 0 ffffff
11 -13 0 000000
12 -13 0 ffffff
13 -13 0 000000
14 -13 0 bf40bf
15 -13 0 000000
0 -12 0 000000
1 -12 0 ffffff
2 -12 0 000000
3 -12 0 ffffff
4 -12 0 000000
5 -12 0 ffffff
6 -12 0 bf40bf
7 -12 0 bf40bf
8 -12 0 000000
9 -12 0 ffffff
10 -12 0 000000
11 -12 0 ffffff
12 -12 0 000000
13 -12 0 ffffff
14 -12 0 000000
15 -12 0 ffffff
0 -11 0 ffffff
1 -11 0 000000
2 -11 0 ffffff
3 -11 0 000000
4 -11 0 ffffff
5 -11 0 000000
6 -11 0 bf40bf
7 -11 0 000000
8 -11 0 ffffff
9 -11 0 bf40bf
10 -11 0 ffffff
11 -11 0 bf40bf
12 -11 0 ffffff
13 -11 0 000000
14 -11 0 ffffff
15 -11 0 000000
0 -10 0 000000
1 -10 0 ffffff
2 -10 0 000000
3 -10 0 ffffff
4 -10 0 000000
5 -10 0 ffffff
6 -10 0 000000
7 -10 0 ffffff
8 -10 0 000000
9 -10 0 ffffff
10 -10 0 bf40bf
11 -10 0 ffffff
12 -10 0 000000
13 -10 0 ffffff
14 -10 0 000000
15 -10 0 ffffff
0 -9 0 ffffff
1 -9 0 000000
2 -9 0 ffffff
3 -9 0 000000
4 -9 0 ffffff
5 -9 0 bf40bf
6 -9 0 ffffff
7 -9 0 000000
8 -9 0 ffffff
9 -9 0 000000
10 -9 0 ffffff
11 -9 0 000000
12 -9 0 ffffff
13 -9 0 000000
14 -9 0 ffffff
15 -9 0 000000
0 -8 0 000000
1 -8 0 bf40bf
2 -8 0 000000
3 -8 0 bf40bf
4 -8 0 000000
5 -8 0 ffffff
6 -8 0 bf40bf
7 -8 0 bf40bf
8 -8 0 000000
9 -8 0 ffffff
10 -8 0 000000
11 -8 0 ffffff
12 -8 0 bf40bf
13 -8 0 ffffff
14 -8 0 000000
15 -8 0 ffffff
0 -7 0 ffffff
1 -7 0 000000
2 -7 0 ffffff
3 -7 0 bf40bf
4 -7 0 bf40bf
5 -7 0 000000
6 -7 0 ffffff
7 -7 0 000000
8 -7 0 ffffff
9 -7 0 000000
10 -7 0 ffffff
11 -7 0 000000
12 -7 0 ffffff
13 -7 0 000000
14 -7 0 ffffff
15 -7 0 000000
0 -6 0 000000
1 -6 0 ffffff
2 -6 0 000000
3 -6 0 ffffff
4 -6 0 000000
5 -6 0 ffffff
6 -6 0 000000
7 -6 0 ffffff
8 -6 0 000000
9 -6 0 ffffff
10 -6 0 bf40bf
11 -6 0 ffffff
12 -6 0 bf40bf
13 -6 0 bf40bf
14 -6 0 000000
15 -6 0 ffffff
0 -5 0 ffffff
1 -5 0 000000
2 -5 0 ffffff
3 -5 0 bf40bf
4 -5 0 ffffff
5 -5 0 000000
6 -5 0 ffffff
7 -5 0 000000
8 -5 0 ffffff
9 -5 0 bf40bf
10 -5 0 ffffff
11 -5 0 bf40bf
12 -5 0 bf40bf
13 -5 0 000000
14 -5 0 bf40bf
15 -5 0 000000
0 -4 0 000000
1 -4 0 ffffff
2 -4 0 bf40bf
3 -4 0 ffffff
4 -4 0 000000
5 -4 0 ffffff
6 -4 0 000000
7 -4 0 ffffff
8 -4 0 000000
9 -4 0 ffffff
10 -4 0 000000
11 -4 0 ffffff
12 -4 0 000000
13 -4 0 ffffff
14 -4 0 000000
15 -4 0 ffffff
0 -3 0 ffffff
1 -3 0 bf40bf
2 -3 0 bf40bf
3 -3 0 bf40bf
4 -3 0 bf40bf
5 -3 0 000000
6 -3 0 bf40bf
7 -3 0 000000
8 -3 0 ffffff
9 -3 0 000000
10 -3 0 ffffff
11 -3 0 000000
12 -3 0 bf40bf
13 -3 0 000000
14 -3 0 ffffff
15 -3 0 000000
0 -2 0 bf40bf
1 -2 0 ffffff
2 -2 0 000000
3 -2 0 ffffff
4 -2 0 bf40bf
5 -2 0 ffffff
6 -2 0 000000
7 -2 0 bf40bf
8 -2 0 bf40bf
9 -2 0 ffffff
10 -2 0 000000
11 -2 0 ffffff
12 -2 0 000000
13 -2 0 ffffff
14 -2 0 000000
15 -2 0 ffffff
0 -1 0 ffffff
1 -1 0 bf40bf
2 -1 0 bf40bf
3 -1 0 000000
4 -1 0 bf40bf
5 -1 0 000000
6 -1 0 ffffff
7 -1 0 000000
8 -1 0 bf40bf
9 -1 0 000000
10 -1 0 ffffff
11 -1 0 bf40bf
12 -1 0 bf40bf
13 -1 0 000000
14 -1 0 ffffff
15 -1 0 000000
0 -16 1 000000
1 -16 1 ffffff
2 -16 1 000000
3 -16 1 ffffff
4 -16 1 bf40bf
5 -16 1 ffffff
6 -16 1 000000
7 -16 1 ffffff
8 -16 1 000000
9 -16 1 ffffff
10 -16 1 000000
11 -16 1 bf40bf
12 -16 1 bf40bf
13 -16 1 ffffff
14 -16 1 000000
15 -16 1 ffffff
0 -15 1 bf40bf
1 -15 1 bf40bf
2 -15 1 ffffff
3 -15 1 bf40bf
4 -15 1 ffffff
5 -15 1 bf40bf
6 -15 1 ffffff
7 -15 1 000000
8 -15 1 bf40bf
9 -15 1 000000
10 -15 1 ffffff
11 -15 1 000000
12 -15 1 ffffff
13 -15 1 000000
14 -15 1 ffffff
15 -15 1 000000
0 -14 1 000000
1 -14 1 ffffff
2 -14 1 bf40bf
3 -14 1 ffffff
4 -14 1 000000
5 -14 1 ffffff
6 -14 1 000000
7 -14 1 ffffff
8 -14 1 000000
9 -14 1 ffffff
10 -14 1 bf40bf
11 -14 1 ffffff
12 -14 1 000000
13 -14 1 ffffff
14 -14 1 000000
15 -14 1 ffffff
0 -13 1 ffffff
1 -13 1 000000
2 -13 1 ffffff
3 -13 1 bf40bf
4 -13 1 ffffff
5 -13 1 000000
6 -13 1 ffffff
7 -13 1 000000
8 -13 1 ffffff
9 -13 1 000000
10 -13 1 ffffff
11 -13 1 000000
12 -13 1 ffffff
13 -13 1 000000
14 -13 1 bf40bf
15 -13 1 000000
0 -12 1 000000
1 -12 1 ffffff
2 -12 1 000000
3 -12 1 ffffff
4 -12 1 000000
5 -12 1 ffffff
6 -12 1 bf40bf
7 -12 1 bf40bf
8 -12 1 000000
9 -12 1 ffffff
10 -12 1 000000
11 -12 1 ffffff
12 -12 1 000000
13 -12 1 ffffff
14 -12 1 000000
15 -12 1 ffffff
0 -11 1 ffffff
1 -11 1 000000
2 -11 1 ffffff
3 -11 1 000000
4 -11 1 ffffff
5 -11 1 000000
6 -11 1 bf40bf
7 -11 1 000000
8 -11 1 ffffff
9 -11 1 bf40bf
10 -11 1 ffffff
11 -11 1 bf40bf
12 -11 1 ffffff
13 -11 1 000000
14 -11 1 ffffff
15 -11 1 000000
0 -10 1 000000
1 -10 1 ffffff
2 -10 1 000000
3 -10 1 ffffff
4 -10 1 000000
5 -10 1 ffffff
6 -10 1 000000
7 -10 1 ffffff
8 -10 1 000000
9 -10 1 ffffff
10 -10 1 bf40bf
11 -10 1 ffffff
12 -10 1 000000
13 -10 1 ffffff
14 -10 1 000000
15 -10 1 ffffff
0 -9 1 ffffff
1 -9 1 000000
2 -9 1 ffffff
3 -9 1 000000
4 -9 1 ffffff
5 -9 1 bf40bf
6 -9 1 ffffff
7 -9 1 000000
8 -9 1 ffffff
9 -9 1 000000
10 -9 1 ffffff
11 -9 1 000000
12 -9 1 ffffff
13 -9 1 000000
14 -9 1 ffffff
15 -9 1 000000
0 -8 1 000000
1 -8 1 bf40bf
2 -8 1 000000
3 -8 1 bf40bf
4 -8 1 000000
5 -8 1 ffffff
6 -8 1 bf40bf
7 -8 1 bf40bf
8 -8 1 000000
9 -8 1 ffffff
10 -8 1 000000
11 -8 1 ffffff
12 -8 1 bf40bf
13 -8 1 ffffff
14 -8 1 000000
15 -8 1 ffffff
0 -7 1 ffffff
1 -7 1 000000
2 -7 1 ffffff
3 -7 1 bf40bf
4 -7 1 bf40bf
5 -7 1 000000
6 -7 1 ffffff
7 -7 1 000000
8 -7 1 ffffff
9 -7 1 000000
10 -7 1 ffffff
11 -7 1 000000
12 -7 1 ffffff
13 -7 1 000000
14 -7 1 ffffff
15 -7 1 000000
0 -6 1 000000
1 -6 1 ffffff
2 -6 1 000000
3 -6 1 ffffff
4 -6 1 000000
5 -6 1 ffffff
6 -6 1 000000
7 -6 1 ffffff
8 -6 1 000000
9 -6 1 ffffff
10 -6 1 bf40bf
11 -6 1 ffffff
12 -6 1 bf40bf
13 -6 1 bf40bf
14 -6 1 000000
15 -6 1 ffffff
0 -5 1 ffffff
1 -5 1 000000
2 -5 1 ffffff
3 -5 1 bf40bf
4 -5 1 ffffff
5 -5 1 000000
6 -5 1 ffffff
7 -5 1 000000
8 -5 1 ffffff
9 -5 1 bf40bf
10 -5 1 ffffff
11 -5 1 bf40bf
12 -5 1 bf40bf
13 -5 1 000000
14 -5 1 bf40bf
15 -5 1 000000
0 -4 1 000000
1 -4 1 ffffff
2 -4 1 bf40bf
3 -4 1 ffffff
4 -4 1 000000
5 -4 1 ffffff
6 -4 1 000000
7 -4 1 ffffff
8 -4 1 000000
9 -4 1 ffffff
10 -4 1 000000
11 -4 1 ffffff
12 -4 1 000000
13 -4 1 ffffff
14 -4 1 000000
15 -4 1 ffffff
0 -3 1 ffffff
1 -3 1 bf40bf
2 -3 1 bf40bf
3 -3 1 bf40bf
4 -3 1 bf40bf
5 -3 1 000000
6 -3 1 bf40bf
7 -3 1 000000
8 -3 1 ffffff
9 -3 1 000000
10 -3 1 ffffff
11 -3 1 000000
12 -3 1 bf40bf
13 -3 1 000000
14 -3 1 ffffff
15 -3 1 000000
0 -2 1 bf40bf
1 -2 1 ffffff
2 -2 1 000000
3 -2 1 ffffff
4 -2 1 bf40bf
5 -2 1 ffffff
6 -2 1 000000
7 -2 1 bf40bf
8 -2 1 bf40bf
9 -2 1 ffffff
10 -2 1 000000
11 -2 1 ffffff
12 -2 1 000000
13 -2 1 ffffff
14 -2 1 000000
15 -2 1 ffffff
0 -1 1 ffffff
1 -1 1 bf40bf
2 -1 1 bf40bf
3 -1 1 000000
4 -1 1 bf40bf
5 -1 1 000000
6 -1 1 ffffff
7 -1 1 000000
8 -1 1 bf40bf
9 -1 1 000000
10 -1 1 ffffff
11 -1 1 bf40bf
12 -1 1 bf40bf
13 -1 1 000000
14 -1 1 ffffff
15 -1 1 000000
0 -16 2 000000
1 -16 2 ffffff
2 -16 2 000000
3 -16 2 ffffff
4 -16 2 bf40bf
5 -16 2 ffffff
6 -16 2 000000
7 -16 2 ffffff
8 -16 2 000000
9 -16 2 ffffff
10 -16 2 000000
11 -16 2 bf40bf
12 -16 2 bf40bf
13 -16 2 ffffff
14 -16 2 000000
15 -16 2 ffffff
0 -15 2 bf40bf
1 -15 2 bf40bf
2 -15 2 ffffff
3 -15 2 bf40bf
4 -15 2 ffffff
5 -15 2 bf40bf
6 -15 2 ffffff
7 -15 2 000000
8 -15 2 bf40bf
9 -15 2 000000
10 -15 2 ffffff
11 -15 2 000000
12 -15 2 ffffff
13 -15 2 000000
14 -15 2 ffffff
15 -15 2 000000
0 -14 2 000000
1 -14 2 ffffff
2 -14 2 bf40bf
3 -14 2 ffffff
4 -14 2 000000
5 -14 2 ffffff
6 -14 2 000000
7 -14 2 ffffff
8 -14 2 000000
9 -14 2 ffffff
10 -14 2 bf40bf
11 -14 2 ffffff
12 -14 2 000000
13 -14 2 ffffff
14 -14 2 000000
15 -14 2 ffffff
0 -13 2 ffffff
1 -13 2 000000
2 -13 2 ffffff
3 -13 2 bf40bf
4 -13 2 ffffff
5 -13 2 000000
6 -13 2 ffffff
7 -13 2 000000
8 -13 2 ffffff
9 -13 2 000000
10 -13 2 ffffff
11 -13 2 000000
12 -13 2 ffffff
13 -13 2 000000
14 -13 2 bf40bf
15 -13 2 000000
0 -12 2 000000
1 -12 2 ffffff
2 -12 2 000000
3 -12 2 ffffff
4 -12 2 000000
5 -12 2 ffffff
6 -12 2 bf40bf
7 -12 2 bf40bf
8 -12 2 000000
9 -12 2 ffffff
10 -12 2 000000
11 -12 2 ffffff
12 -12 2 000000
13 -12 2 ffffff
14 -12 2 000000
15 -12 2 ffffff
0 -11 2 ffffff
1 -11 2 000000
2 -11 2 ffffff
3 -11 2 000000
4 -11 2 ffffff
5 -11 2 000000
6 -11 2 bf40bf
7 -11 2 000000
8 -11 2 ffffff
9 -11 2 bf40bf
10 -11 2 ffffff
11 -11 2 bf40bf
12 -11 2 ffffff
13 -11 2 000000
14 -11 2 ffffff
15 -11 2 000000
0 -10 2 000000
1 -10 2 ffffff
2 -10 2 000000
3 -10 2 ffffff
4 -10 2 000000
5 -10 2 ffffff
6 -10 2 000000
7 -10 2 ffffff
8 -10 2 000000
9 -10 2 ffffff
10 -10 2 bf40bf
11 -10 2 ffffff
12 -10 2 000000
13 -10 2 ffffff
14 -10 2 000000
15 -10 2 ffffff
0 -9 2 ffffff
1 -9 2 000000
2 -9 2 ffffff
3 -9 2 000000
4 -9 2 ffffff
5 -9 2 bf40bf
6 -9 2 ffffff
7 -9 2 000000
8 -9 2 ffffff
9 -9 2 000000
10 -9 2 ffffff
11 -9 2 000000
12 -9 2 ffffff
13 -9 2 000000
14 -9 2 ffffff
15 -9 2 000000
0 -8 2 000000
1 -8 2 bf40bf
2 -8 2 000000
3 -8 2 bf40bf
4 -8 2 000000
5 -8 2 ffffff
6 -8 2 bf40bf
7 -8 2 bf40bf
8 -8 2 000000
9 -8 2 ffffff
10 -8 2 000000
11 -8 2 ffffff
12 -8 2 bf40bf
13 -8 2 ffffff
14 -8 2 000000
15 -8 2 ffffff
0 -7 2 ffffff
1 -7 2 000000
2 -7 2 ffffff
3 -7 2 bf40bf
4 -7 2 bf40bf
5 -7 2 000000
6 -7 2 ffffff
7 -7 2 000000
8 -7 2 ffffff
9 -7 2 000000
10 -7 2 ffffff
11 -7 2 000000
12 -7 2 ffffff
13 -7 2 000000
14 -7 2 ffffff
15 -7 2 000000
0 -6 2 000000
1 -6 2 ffffff
2 -6 2 000000
3 -6 2 ffffff
4 -6 2 000000
5 -6 2 ffffff
6 -6 2 000000
7 -6 2 ffffff
8 -6 2 000000
9 -6 2 ffffff
10 -6 2 bf40bf
11 -6 2 ffffff
12 -6 2 bf40bf
13 -6 2 bf40bf
14 -6 2 000000
15 -6 2 ffffff
0 -5 2 ffffff
1 -5 2 000000
2 -5 2 ffffff
3 -5 2 bf40bf
4 -5 2 ffffff
5 -5 2 000000
6 -5 2 ffffff
7 -5 2 000000
8 -5 2 ffffff
9 -5 2 bf40bf
10 -5 2 ffffff
11 -5 2 bf40bf
12 -5 2 bf40bf
13 -5 2 000000
14 -5 2 bf40bf
15 -5 2 000000
0 -4 2 000000
1 -4 2 ffffff
2 -4 2 bf40bf
3 -4 2 ffffff
4 -4 2 000000
5 -4 2 ffffff
6 -4 2 000000
7 -4 2 ffffff
8 -4 2 000000
9 -4 2 ffffff
10 -4 2 000000
11 -4 2 ffffff
12 -4 2 000000
13 -4 2 ffffff
14 -4 2 000000
15 -4 2 ffffff
0 -3 2 ffffff
1 -3 2 bf40bf
2 -3 2 bf40bf
3 -3 2 bf40bf
4 -3 2 bf40bf
5 -3 2 000000
6 -3 2 bf40bf
7 -3 2 000000
8 -3 2 ffffff
9 -3 2 000000
10 -3 2 ffffff
11 -3 2 000000
12 -3 2 bf40bf
13 -3 2 000000
14 -3 2 ffffff
15 -3 2 000000
0 -2 2 bf40bf
1 -2 2 ffffff
2 -2 2 000000
3 -2 2 ffffff
4 -2 2 bf40bf
5 -2 2 ffffff
6 -2 2 000000
7 -2 2 bf40bf
8 -2 2 bf40bf
9 -2 2 ffffff
10 -2 2 000000
11 -2 2 ffffff
12 -2 2 000000
13 -2 2 ffffff
14 -2 2 000000
15 -2 2 ffffff
0 -1 2 ffffff
1 -1 2 bf40bf
2 -1 2 bf40bf
3 -1 2 000000
4 -1 2 bf40bf
5 -1 2 000000
6 -1 2 ffffff
7 -1 2 000000
8 -1 2 bf40bf
9 -1 2 000000
10 -1 2 ffffff
11 -1 2 bf40bf
12 -1 2 bf40bf
13 -1 2 000000
14 -1 2 ffffff
15 -1 2 000000
0 -16 3 000000
1 -16 3 ffffff
2 -16 3 000000
3 -16 3 ffffff
4 -16 3 bf40bf
5 -16 3 ffffff
6 -16 3 000000
7 -16 3 ffffff
8 -16 3 000000
9 -16 3 ffffff
10 -16 3 000000
11 -16 3 bf40bf
12 -16 3 bf40bf
13 -16 3 ffffff
14 -16 3 000000
15 -16 3 ffffff
0 -15 3 bf40bf
1 -15 3 bf40bf
2 -15 3 ffffff
3 -15 3 bf40bf
4 -15 3 ffffff
5 -15 3 bf40bf
6 -15 3 ffffff
7 -15 3 000000
8 -15 3 bf40bf
9 -15 3 000000
10 -15 3 ffffff
11 -15 3 000000
12 -15 3 ffffff
13 -15 3 000000
14 -15 3 ffffff
15 -15 3 000000
0 -14 3 000000
1 -14 3 ffffff
2 -14 3 bf40bf
3 -14 3 ffffff
4 -14 3 000000
5 -14 3 ffffff
6 -14 3 000000
7 -14 3 ffffff
8 -14 3 000000
9 -14 3 ffffff
10 -14 3 bf40bf
11 -14 3 ffffff
12 -14 3 000000
13 -14 3 ffffff
14 -14 3 000000
15 -14 3 ffffff
0 -13 3 ffffff
1 -13 3 000000
2 -13 3 ffffff
3 -13 3 bf40bf
4 -13 3 ffffff
5 -13 3 000000
6 -13 3 ffffff
7 -13 3 000000
8 -13 3 ffffff
9 -13 3 000000
10 -13 3 ffffff
11 -13 3 000000
12 -13 3 ffffff
13 -13 3 000000
14 -13 3 bf40bf
15 -13 3 000000
0 -12 3 000000
1 -12 3 ffffff
2 -12 3 000000
3 -12 3 ffffff
4 -12 3 000000
5 -12 3 ffffff
6 -12 3 bf40bf
7 -12 3 bf40bf
8 -12 3 000000
9 -12 3 ffffff
10 -12 3 000000
11 -12 3 ffffff
12 -12 3 000000
13 -12 3 ffffff
14 -12 3 000000
15 -12 3 ffffff
0 -11 3 ffffff
1 -11 3 000000
2 -11 3 ffffff
3 -11 3 000000
4 -11 3 ffffff
5 -11 3 000000
6 -11 3 bf40bf
7 -11 3 000000
8 -11 3 ffffff
9 -11 3 bf40bf
10 -11 3 ffffff
11 -11 3 bf40bf
12 -11 3 ffffff
13 -11 3 000000
14 -11 3 ffffff
15 -11 3 000000
0 -10 3 000000
1 -10 3 ffffff
2 -10 3 000000
3 -10 3 ffffff
4 -10 3 000000
5 -10 3 ffffff
6 -10 3 000000
7 -10 3 ffffff
8 -10 3 000000
9 -10 3 ffffff
10 -10 3 bf40bf
11 -10 3 ffffff
12 -10 3 000000
13 -10 3 ffffff
14 -10 3 000000
15 -10 3 ffffff
0 -9 3 ffffff
1 -9 3 000000
2 -9 3 ffffff
3 -9 3 000000
4 -9 3 ffffff
5 -9 3 bf40bf
6 -9 3 ffffff
7 -9 3 000000
8 -9 3 ffffff
9 -9 3 000000
10 -9 3 ffffff
11 -9 3 000000
12 -9 3 ffffff
13 -9 3 000000
14 -9 3 ffffff
15 -9 3 000000
0 -8 3 000000
1 -8 3 bf40bf
2 -8 3 000000
3 -8 3 bf40bf
4 -8 3 000000
5 -8 3 ffffff
6 -8 3 bf40bf
7 -8 3 bf40bf
8 -8 3 000000
9 -8 3 ffffff
10 -8 3 000000
11 -8 3 ffffff
12 -8 3 bf40bf
13 -8 3 ffffff
14 -8 3 000000
15 -8 3 ffffff
0 -7 3 ffffff
1 -7 3 000000
2 -7 3 ffffff
3 -7 3 bf40bf
4 -7 3 bf40bf
5 -7 3 000000
6 -7 3 ffffff
7 -7 3 000000
8 -7 3 ffffff
9 -7 3 000000
10 -7 3 ffffff
11 -7 3 000000
12 -7 3 ffffff
13 -7 3 000000
14 -7 3 ffffff
15 -7 3 000000
0 -6 3 000000
1 -6 3 ffffff
2 -6 3 000000
3 -6 3 ffffff
4 -6 3 000000
5 -6 3 ffffff
6 -6 3 000000
7 -6 3 ffffff
8 -6 3 000000
9 -6 3 ffffff
10 -6 3 bf40bf
11 -6 3 ffffff
12 -6 3 bf40bf
13 -6 3 bf40bf
14 -6 3 000000
15 -6 3 ffffff
0 -5 3 ffffff
1 -5 3 000000
2 -5 3 ffffff
3 -5 3 bf40bf
4 -5 3 ffffff
5 -5 3 000000
6 -5 3 ffffff
7 -5 3 000000
8 -5 3 ffffff
9 -5 3 bf40bf
10 -5 3 ffffff
11 -5 3 bf40bf
12 -5 3 bf40bf
13 -5 3 000000
14 -5 3 bf40bf
15 -5 3 000000
0 -4 3 000000
1 -4 3 ffffff
2 -4 3 bf40bf
3 -4 3 ffffff
4 -4 3 000000
5 -4 3 ffffff
6 -4 3 000000
7 -4 3 ffffff
8 -4 3 000000
9 -4 3 ffffff
10 -4 3 000000
11 -4 3 ffffff
12 -4 3 000000
13 -4 3 ffffff
14 -4 3 000000
15 -4 3 ffffff
0 -3 3 ffffff
1 -3 3 bf40bf
2 -3 3 bf40bf
3 -3 3 bf40bf
4 -3 3 bf40bf
5 -3 3 000000
6 -3 3 bf40bf
7 -3 3 000000
8 -3 3 ffffff
9 -3 3 000000
10 -3 3 ffffff
11 -3 3 000000
12 -3 3 bf40bf
13 -3 3 000000
14 -3 3 ffffff
15 -3 3 000000
0 -2 3 bf40bf
1 -2 3 ffffff
2 -2 3 000000
3 -2 3 ffffff
4 -2 3 bf40bf
5 -2 3 ffffff
6 -2 3 000000
7 -2 3 bf40bf
8 -2 3 bf40bf
9 -2 3 ffffff
10 -2 3 000000
11 -2 3 ffffff
12 -2 3 000000
13 -2 3 ffffff
14 -2 3 000000
15 -2 3 ffffff
0 -1 3 ffffff
1 -1 3 bf40bf
2 -1 3 bf40bf
3 -1 3 000000
4 -1 3 bf40bf
5 -1 3 000000
6 -1 3 ffffff
7 -1 3 000000
8 -1 3 bf40bf
9 -1 3 000000
10 -1 3 ffffff
11 -1 3 bf40bf
12 -1 3 bf40bf
13 -1 3 000000
14 -1 3 ffffff
15 -1 3 000000
0 -16 4 000000
1 -16 4 ffffff
2 -16 4 000000
3 -16 4 ffffff
4 -16 4 bf40bf
5 -16 4 ffffff
6 -16 4 000000
7 -16 4 ffffff
8 -16 4 000000
9 -16 4 ffffff
10 -16 4 000000
11 -16 4 bf40bf
12 -16 4 bf40bf
13 -16 4 ffffff
14 -16 4 000000
15 -16 4 ffffff
0 -15 4 bf40bf
1 -15 4 bf40bf
2 -15 4 ffffff
3 -15 4 bf40bf
4 -15 4 ffffff
5 -15 4 bf40bf
6 -15 4 ffffff
7 -15 4 000000
8 -15 4 bf40bf
9 -15 4 000000
10 -15 4 ffffff
11 -15 4 000000
12 -15 4 ffffff
13 -15 4 000000
14 -15 4 ffffff
15 -15 4 000000
0 -14 4 000000
1 -14 4 ffffff
2 -14 4 bf40bf
3 -14 4 ffffff
4 -14 4 000000
5 -14 4 ffffff
6 -14 4 000000
7 -14 4 ffffff
8 -14 4 000000
9 -14 4 ffffff
10 -14 4 bf40bf
11 -14 4 ffffff
12 -14 4 000000
13 -14 4 ffffff
14 -14 4 000000
15 -14 4 ffffff
0 -13 4 ffffff
1 -13 4 000000
2 -13 4 ffffff
3 -13 4 bf40bf
4 -13 4 ffffff
5 -13 4 000000
6 -13 4 ffffff
7 -13 4 000000
8 -13 4 ffffff
9 -13 4 000000
10 -13 4 ffffff
11 -13 4 000000
12 -13 4 ffffff
13 -13 4 000000
14 -13 4 bf40bf
15 -13 4 000000
0 -12 4 000000
1 -12 4 ffffff
2 -12 4 000000
3 -12 4 ffffff
4 -12 4 000000
5 -12 4 ffffff
6 -12 4 bf40bf
7 -12 4 bf40bf
8 -12 4 000000
9 -12 4 ffffff
10 -12 4 000000
11 -12 4 ffffff
12 -12 4 000000
13 -12 4 ffffff
14 -12 4 000000
15 -12 4 ffffff
0 -11 4 ffffff
1 -11 4 000000
2 -11 4 ffffff
3 -11 4 000000
4 -11 4 ffffff
5 -11 4 000000
6 -11 4 bf40bf
7 -11 4 000000
8 -11 4 ffffff
9 -11 4 bf40bf
10 -11 4 ffffff
11 -11 4 bf40bf
12 -11 4 ffffff
13 -11 4 000000
14 -11 4 ffffff
15 -11 4 000000
0 -10 4 000000
1 -10 4 ffffff
2 -10 4 000000
3 -10 4 ffffff
4 -10 4 000000
5 -10 4 ffffff
6 -10 4 000000
7 -10 4 ffffff
8 -10 4 000000
9 -10 4 ffffff
10 -10 4 bf40bf
11 -10 4 ffffff
12 -10 4 000000
13 -10 4 ffffff
14 -10 4 000000
15 -10 4 ffffff
0 -9 4 ffffff
1 -9 4 000000
2 -9 4 ffffff
3 -9 4 000000
4 -9 4 ffffff
5 -9 4 bf40bf
6 -9 4 ffffff
7 -9 4 000000
8 -9 4 ffffff
9 -9 4 000000
10 -9 4 ffffff
11 -9 4 000000
12 -9 4 ffffff
13 -9 4 000000
14 -9 4 ffffff
15 -9 4 000000
0 -8 4 000000
1 -8 4 bf40bf
2 -8 4 000000
3 -8 4 bf40bf
4 -8 4 000000
5 -8 4 ffffff
6 -8 4 bf40bf
7 -8 4 bf40bf
8 -8 4 000000
9 -8 4 ffffff
10 -8 4 000000
11 -8 4 ffffff
12 -8 4 bf40bf
13 -8 4 ffffff
14 -8 4 000000
15 -8 4 ffffff
0 -7 4 ffffff
1 -7 4 000000
2 -7 4 ffffff
3 -7 4 bf40bf
4 -7 4 bf40bf
5 -7 4 000000
6 -7 4 ffffff
7 -7 4 000000
8 -7 4 ffffff
9 -7 4 000000
10 -7 4 ffffff
11 -7 4 000000
12 -7 4 ffffff
13 -7 4 000000
14 -7 4 ffffff
15 -7 4 000000
0 -6 4 000000
1 -6 4 ffffff
2 -6 4 000000
3 -6 4 ffffff
4 -6 4 000000
5 -6 4 ffffff
6 -6 4 000000
7 -6 4 ffffff
8 -6 4 000000
9 -6 4 ffffff
10 -6 4 bf40bf
11 -6 4 ffffff
12 -6 4 bf40bf
13 -6 4 bf40bf
14 -6 4 000000
15 -6 4 ffffff
0 -5 4 ffffff
1 -5 4 000000
2 -5 4 ffffff
3 -5 4 bf40bf
4 -5 4 ffffff
5 -5 4 000000
6 -5 4 ffffff
7 -5 4 000000
8 -5 4 ffffff
9 -5 4 bf40bf
10 -5 4 ffffff
11 -5 4 bf40bf
12 -5 4 bf40bf
13 -5 4 000000
14 -5 4 bf40bf
15 -5 4 000000
0 -4 4 000000
1 -4 4 ffffff
2 -4 4 bf40bf
3 -4 4 ffffff
4 -4 4 000000
5 -4 4 ffffff
6 -4 4 000000
7 -4 4 ffffff
8 -4 4 000000
9 -4 4 ffffff
10 -4 4 000000
11 -4 4 ffffff
12 -4 4 000000
13 -4 4 ffffff
14 -4 4 000000
15 -4 4 ffffff
0 -3 4 ffffff
1 -3 4 bf40bf
2 -3 4 bf40bf
3 -3 4 bf40bf
4 -3 4 bf40bf
5 -3 4 000000
6 -3 4 bf40bf
7 -3 4 000000
8 -3 4 ffffff
9 -3 4 000000
10 -3 4 ffffff
11 -3 4 000000
12 -3 4 bf40bf
13 -3 4 000000
14 -3 4 ffffff
15 -3 4 000000
0 -2 4 bf40bf
1 -2 4 ffffff
2 -2 4 000000
3 -2 4 ffffff
4 -2 4 bf40bf
5 -2 4 ffffff
6 -2 4 000000
7 -2 4 bf40bf
8 -2 4 bf40bf
9 -2 4 ffffff
10 -2 4 000000
11 -2 4 ffffff
12 -2 4 000000
13 -2 4 ffffff
14 -2 4 000000
15 -2 4 ffffff
0 -1 4 ffffff
1 -1 4 bf40bf
2 -1 4 bf40bf
3 -1 4 000000
4 -1 4 bf40bf
5 -1 4 000000
6 -1 4 ffffff
7 -1 4 000000
8 -1 4 bf40bf
9 -1 4 000000
10 -1 4 ffffff
11 -1 4 bf40bf
12 -1 4 bf40bf
13 -1 4 000000
14 -1 4 ffffff
15 -1 4 000000
0 -16 5 000000
1 -16 5 ffffff
2 -16 5 000000
3 -16 5 ffffff
4 -16 5 bf40bf
5 -16 5 ffffff
6 -16 5 000000
7 -16 5 ffffff
8 -16 5 000000
9 -16 5 ffffff
10 -16 5 000000
11 -16 5 bf40bf
12 -16 5 bf40bf
13 -16 5 ffffff
14 -16 5 000000
15 -16 5 ffffff
0 -15 5 bf40bf
1 -15 5 bf40bf
2 -15 5 ffffff
3 -15 5 bf40bf
4 -15 5 ffffff
5 -15 5 bf40bf
6 -15 5 ffffff
7 -15 5 000000
8 -15 5 bf40bf
9 -15 5 000000
10 -15 5 ffffff
11 -15 5 000000
12 -15 5 ffffff
13 -15 5 000000
14 -15 5 ffffff
15 -15 5 000000
0 -14 5 000000
1 -14 5 ffffff
2 -14 5 bf40bf
3 -14 5 ffffff
4 -14 5 000000
5 -14 5 ffffff
6 -14 5 000000
7 -14 5 ffffff
8 -14 5 000000
9 -14 5 ffffff
10 -14 5 bf40bf
11 -14 5 ffffff
12 -14 5 000000
13 -14 5 ffffff
14 -14 5 000000
15 -14 5 ffffff
0 -13 5 ffffff
1 -13 5 000000
2 -13 5 ffffff
3 -13 5 bf40bf
4 -13 5 ffffff
5 -13 5 000000
6 -13 5 ffffff
7 -13 5 000000
8 -13 5 ffffff
9 -13 5 000000
10 -13 5 ffffff
11 -13 5 000000
12 -13 5 ffffff
13 -13 5 000000
14 -13 5 bf40bf
15 -13 5 000000
0 -12 5 000000
1 -12 5 ffffff
2 -12 5 000000
3 -12 5 ffffff
4 -12 5 000000
5 -12 5 ffffff
6 -12 5 bf40bf
7 -12 5 bf40bf
8 -12 5 000000
9 -12 5 ffffff
10 -12 5 000000
11 -12 5 ffffff
12 -12 5 000000
13 -12 5 ffffff
14 -12 5 000000
15 -12 5 ffffff
0 -11 5 ffffff
1 -11 5 000000
2 -11 5 ffffff
3 -11 5 000000
4 -11 5 ffffff
5 -11 5 000000
6 -11 5 bf40bf
7 -11 5 000000
8 -11 5 ffffff
9 -11 5 bf40bf
10 -11 5 ffffff
11 -11 5 bf40bf
12 -11 5 ffffff
13 -11 5 000000
14 -11 5 ffffff
15 -11 5 000000
0 -10 5 000000
1 -10 5 ffffff
2 -10 5 000000
3 -10 5 ffffff
4 -10 5 000000
5 -10 5 ffffff
6 -10 5 000000
7 -10 5 ffffff
8 -10 5 000000
9 -10 5 ffffff
10 -10 5 bf40bf
11 -10 5 ffffff
12 -10 5 000000
13 -10 5 ffffff
14 -10 5 000000
15 -10 5 ffffff
0 -9 5 ffffff
1 -9 5 000000
2 -9 5 ffffff
3 -9 5 000000
4 -9 5 ffffff
5 -9 5 bf40bf
6 -9 5 ffffff
7 -9 5 000000
8 -9 5 ffffff
9 -9 5 000000
10 -9 5 ffffff
11 -9 5 000000
12 -9 5 ffffff
13 -9 5 000000
14 -9 5 ffffff
15 -9 5 000000
0 -8 5 000000
1 -8 5 bf40bf
2 -8 5 000000
3 -8 5 bf40bf
4 -8 5 000000
5 -8 5 ffffff
6 -8 5 bf40bf
7 -8 5 bf40bf
8 -8 5 000000
9 -8 5 ffffff
10 -8 5 000000
11 -8 5 ffffff
12 -8 5 bf40bf
13 -8 5 ffffff
14 -8 5 000000
15 -8 5 ffffff
0 -7 5 ffffff
1 -7 5 000000
2 -7 5 ffffff
3 -7 5 bf40bf
4 -7 5 bf40bf
5 -7 5 000000
6 -7 5 ffffff
7 -7 5 000000
8 -7 5 ffffff
9 -7 5 000000
10 -7 5 ffffff
11 -7 5 000000
12 -7 5 ffffff
13 -7 5 000000
14 -7 5 ffffff
15 -7 5 000000
0 -6 5 000000
1 -6 5 ffffff
2 -6 5 000000
3 -6 5 ffffff
4 -6 5 000000
5 -6 5 ffffff
6 -6 5 000000
7 -6 5 ffffff
8 -6 5 000000
9 -6 5 ffffff
10 -6 5 bf40bf
11 -6 5 ffffff
12 -6 5 bf40bf
13 -6 5 bf40bf
14 -6 5 000000
15 -6 5 ffffff
0 -5 5 ffffff
1 -5 5 000000
2 -5 5 ffffff
3 -5 5 bf40bf
4 -5 5 ffffff
5 -5 5 000000
6 -5 5 ffffff
7 -5 5 000000
8 -5 5 ffffff
9 -5 5 bf40bf
10 -5 5 ffffff
11 -5 5 bf40bf
12 -5 5 bf40bf
13 -5 5 000000
14 -5 5 bf40bf
15 -5 5 000000
0 -4 5 000000
1 -4 5 ffffff
2 -4 5 bf40bf
3 -4 5 ffffff
4 -4 5 000000
5 -4 5 ffffff
6 -4 5 000000
7 -4 5 ffffff
8 -4 5 000000
9 -4 5 ffffff
10 -4 5 000000
11 -4 5 ffffff
12 -4 5 000000
13 -4 5 ffffff
14 -4 5 000000
15 -4 5 ffffff
0 -3 5 ffffff
1 -3 5 bf40bf
2 -3 5 bf40bf
3 -3 5 bf40bf
4 -3 5 bf40bf
5 -3 5 000000
6 -3 5 bf40bf
7 -3 5 000000
8 -3 5 ffffff
9 -3 5 000000
10 -3 5 ffffff
11 -3 5 000000
12 -3 5 bf40bf
13 -3 5 000000
14 -3 5 ffffff
15 -3 5 000000
0 -2 5 bf40bf
1 -2 5 ffffff
2 -2 5 000000
3 -2 5 ffffff
4 -2 5 bf40bf
5 -2 5 ffffff
6 -2 5 000000
7 -2 5 bf40bf
8 -2 5 bf40bf
9 -2 5 ffffff
10 -2 5 000000
11 -2 5 ffffff
12 -2 5 000000
13 -2 5 ffffff
14 -2 5 000000
15 -2 5 ffffff
0 -1 5 ffffff
1 -1 5 bf40bf
2 -1 5 bf40bf
3 -1 5 000000
4 -1 5 bf40bf
5 -1 5 000000
6 -1 5 ffffff
7 -1 5 000000
8 -1 5 bf40bf
9 -1 5 000000
10 -1 5 ffffff
11 -1 5 bf40bf
12 -1 5 bf40bf
13 -1 5 000000
14 -1 5 ffffff
15 -1 5 000000
0 -16 6 000000
1 -16 6 ffffff
2 -16 6 000000
3 -16 6 ffffff
4 -16 6 bf40bf
5 -16 6 ffffff
6 -16 6 000000
7 -16 6 ffffff
8 -16 6 000000
9 -16 6 ffffff
10 -16 6 000000
11 -16 6 bf40bf
12 -16 6 bf40bf
13 -16 6 ffffff
14 -16 6 000000
15 -16 6 ffffff
0 -15 6 bf40bf
1 -15 6 bf40bf
2 -15 6 ffffff
3 -15 6 bf40bf
4 -15 6 ffffff
5 -15 6 bf40bf
6 -15 6 ffffff
7 -15 6 000000
8 -15 6 bf40bf
9 -15 6 000000
10 -15 6 ffffff
11 -15 6 000000
12 -15 6 ffffff
13 -15 6 000000
14 -15 6 ffffff
15 -15 6 000000
0 -14 6 000000
1 -14 6 ffffff
2 -14 6 bf40bf
3 -14 6 ffffff
4 -14 6 000000
5 -14 6 ffffff
6 -14 6 000000
7 -14 6 ffffff
8 -14 6 000000
9 -14 6 ffffff
10 -14 6 bf40bf
11 -14 6 ffffff
12 -14 6 000000
13 -14 6 ffffff
14 -14 6 000000
15 -14 6 ffffff
0 -13 6 ffffff
1 -13 6 000000
2 -13 6 ffffff
3 -13 6 bf40bf
4 -13 6 ffffff
5 -13 6 000000
6 -13 6 ffffff
7 -13 6 000000
8 -13 6 ffffff
9 -13 6 000000
10 -13 6 ffffff
11 -13 6 000000
12 -13 6 ffffff
13 -13 6 000000
14 -13 6 bf40bf
15 -13 6 000000
0 -12 6 000000
1 -12 6 ffffff
2 -12 6 000000
3 -12 6 ffffff
4 -12 6 000000
5 -12 6 ffffff
6 -12 6 bf40bf
7 -12 6 bf40bf
8 -12 6 000000
9 -12 6 ffffff
10 -12 6 000000
11 -12 6 ffffff
12 -12 6 000000
13 -12 6 ffffff
14 -12 6 000000
15 -12 6 ffffff
0 -11 6 ffffff
1 -11 6 000000
2 -11 6 ffffff
3 -11 6 000000
4 -11 6 ffffff
5 -11 6 000000
6 -11 6 bf40bf
7 -11 6 000000
8 -11 6 ffffff
9 -11 6 bf40bf
10 -11 6 ffffff
11 -11 6 bf40bf
12 -11 6 ffffff
13 -11 6 000000
14 -11 6 ffffff
15 -11 6 000000
0 -10 6 000000
1 -10 6 ffffff
2 -10 6 000000
3 -10 6 ffffff
4 -10 6 000000
5 -10 6 ffffff
6 -10 6 000000
7 -10 6 ffffff
8 -10 6 000000
9 -10 6 ffffff
10 -10 6 bf40bf
11 -10 6 ffffff
12 -10 6 000000
13 -10 6 ffffff
14 -10 6 000000
15 -10 6 ffffff
0 -9 6 ffffff
1 -9 6 000000
2 -9 6 ffffff
3 -9 6 000000
4 -9 6 ffffff
5 -9 6 bf40bf
6 -9 6 ffffff
7 -9 6 000000
8 -9 6 ffffff
9 -9 6 000000
10 -9 6 ffffff
11 -9 6 000000
12 -9 6 ffffff
13 -9 6 000000
14 -9 6 ffffff
15 -9 6 000000
0 -8 6 000000
1 -8 6 bf40bf
2 -8 6 000000
3 -8 6 bf40bf
4 -8 6 000000
5 -8 6 ffffff
6 -8 6 bf40bf
7 -8 6 bf40bf
8 -8 6 000000
9 -8 6 ffffff
10 -8 6 000000
11 -8 6 ffffff
12 -8 6 bf40bf
13 -8 6 ffffff
14 -8 6 000000
15 -8 6 ffffff
0 -7 6 ffffff
1 -7 6 000000
2 -7 6 ffffff
3 -7 6 bf40bf
4 -7 6 bf40bf
5 -7 6 000000
6 -7 6 ffffff
7 -7 6 000000
8 -7 6 ffffff
9 -7 6 000000
10 -7 6 ffffff
11 -7 6 000000
12 -7 6 ffffff
13 -7 6 000000
14 -7 6 ffffff
15 -7 6 000000
0 -6 6 000000
1 -6 6 ffffff
2 -6 6 000000
3 -6 6 ffffff
4 -6 6 000000
5 -6 6 ffffff
6 -6 6 000000
7 -6 6 ffffff
8 -6 6 000000
9 -6 6 ffffff
10 -6 6 bf40bf
11 -6 6 ffffff
12 -6 6 bf40bf
13 -6 6 bf40bf
14 -6 6 000000
15 -6 6 ffffff
0 -5 6 ffffff
1 -5 6 000000
2 -5 6 ffffff
3 -5 6 bf40bf
4 -5 6 ffffff
5 -5 6 000000
6 -5 6 ffffff
7 -5 6 000000
8 -5 6 ffffff
9 -5 6 bf40bf
10 -5 6 ffffff
11 -5 6 bf40bf
12 -5 6 bf40bf
13 -5 6 000000
14 -5 6 bf40bf
15 -5 6 000000
0 -4 6 000000
1 -4 6 ffffff
2 -4 6 bf40bf
3 -4 6 ffffff
4 -4 6 000000
5 -4 6 ffffff
6 -4 6 000000
7 -4 6 ffffff
8 -4 6 000000
9 -4 6 ffffff
10 -4 6 000000
11 -4 6 ffffff
12 -4 6 000000
13 -4 6 ffffff
14 -4 6 000000
15 -4 6 ffffff
0 -3 6 ffffff
1 -3 6 bf40bf
2 -3 6 bf40bf
3 -3 6 bf40bf
4 -3 6 bf40bf
5 -3 6 000000
6 -3 6 bf40bf
7 -3 6 000000
8 -3 6 ffffff
9 -3 6 000000
10 -3 6 ffffff
11 -3 6 000000
12 -3 6 bf40bf
13 -3 6 000000
14 -3 6 ffffff
15 -3 6 000000
0 -2 6 bf40bf
1 -2 6 ffffff
2 -2 6 000000
3 -2 6 ffffff
4 -2 6 bf40bf
5 -2 6 ffffff
6 -2 6 000000
7 -2 6 bf40bf
8 -2 6 bf40bf
9 -2 6 ffffff
10 -2 6 000000
11 -2 6 ffffff
12 -2 6 000000
13 -2 6 ffffff
14 -2 6 000000
15 -2 6 ffffff
0 -1 6 ffffff
1 -1 6 bf40bf
2 -1 6 bf40bf
3 -1 6 000000
4 -1 6 bf40bf
5 -1 6 000000
6 -1 6 ffffff
7 -1 6 000000
8 -1 6 bf40bf
9 -1 6 000000
10 -1 6 ffffff
11 -1 6 bf40bf
12 -1 6 bf40bf
13 -1 6 000000
14 -1 6 ffffff
15 -1 6 000000
0 -16 7 000000
1 -16 7 ffffff
2 -16 7 000000
3 -16 7 ffffff
4 -16 7 bf40bf
5 -16 7 ffffff
6 -16 7 000000
7 -16 7 ffffff
8 -16 7 000000
9 -16 7 ffffff
10 -16 7 000000
11 -16 7 bf40bf
12 -16 7 bf40bf
13 -16 7 ffffff
14 -16 7 000000
15 -16 7 ffffff
0 -15 7 bf40bf
1 -15 7 bf40bf
2 -15 7 ffffff
3 -15 7 bf40bf
4 -15 7 ffffff
5 -15 7 bf40bf
6 -15 7 ffffff
7 -15 7 000000
8 -15 7 bf40bf
9 -15 7 000000
10 -15 7 ffffff
11 -15 7 000000
12 -15 7 ffffff
13 -15 7 000000
14 -15 7 ffffff
15 -15 7 000000
0 -14 7 000000
1 -14 7 ffffff
2 -14 7 bf40bf
3 -14 7 ffffff
4 -14 7 000000
5 -14 7 ffffff
6 -14 7 000000
7 -14 7 ffffff
8 -14 7 000000
9 -14 7 ffffff
10 -14 7 bf40bf
11 -14 7 ffffff
12 -14 7 000000
13 -14 7 ffffff
14 -14 7 000000
15 -14 7 ffffff
0 -13 7 ffffff
1 -13 7 000000
2 -13 7 ffffff
3 -13 7 bf40bf
4 -13 7 ffffff
5 -13 7 000000
6 -13 7 ffffff
7 -13 7 000000
8 -13 7 ffffff
9 -13 7 000000
10 -13 7 ffffff
11 -13 7 000000
12 -13 7 ffffff
13 -13 7 000000
14 -13 7 bf40bf
15 -13 7 000000
0 -12 7 000000
1 -12 7 ffffff
2 -12 7 000000
3 -12 7 ffffff
4 -12 7 000000
5 -12 7 ffffff
6 -12 7 bf40bf
7 -12 7 bf40bf
8 -12 7 000000
9 -12 7 ffffff
10 -12 7 000000
11 -12 7 ffffff
12 -12 7 000000
13 -12 7 ffffff
14 -12 7 000000
15 -12 7 ffffff
0 -11 7 ffffff
1 -11 7 000000
2 -11 7 ffffff
3 -11 7 000000
4 -11 7 ffffff
5 -11 7 000000
6 -11 7 bf40bf
7 -11 7 000000
8 -11 7 ffffff
9 -11 7 bf40bf
10 -11 7 ffffff
11 -11 7 bf40bf
12 -11 7 ffffff
13 -11 7 000000
14 -11 7 ffffff
15 -11 7 000000
0 -10 7 000000
1 -10 7 ffffff
2 -10 7 000000
3 -10 7 ffffff
4 -10 7 000000
5 -10 7 ffffff
6 -10 7 000000
7 -10 7 ffffff
8 -10 7 000000
9 -10 7 ffffff
10 -10 7 bf40bf
11 -10 7 ffffff
12 -10 7 000000
13 -10 7 ffffff
14 -10 7 000000
15 -10 7 ffffff
0 -9 7 ffffff
1 -9 7 000000
2 -9 7 ffffff
3 -9 7 000000
4 -9 7 ffffff
5 -9 7 bf40bf
6 -9 7 ffffff
7 -9 7 000000
8 -9 7 ffffff
9 -9 7 000000
10 -9 7 ffffff
11 -9 7 000000
12 -9 7 ffffff
13 -9 7 000000
14 -9 7 ffffff
15 -9 7 000000
0 -8 7 000000
1 -8 7 bf40bf
2 -8 7 000000
3 -8 7 bf40bf
4 -8 7 000000
5 -8 7 ffffff
6 -8 7 bf40bf
7 -8 7 bf40bf
8 -8 7 000000
9 -8 7 ffffff
10 -8 7 000000
11 -8 7 ffffff
12 -8 7 bf40bf
13 -8 7 ffffff
14 -8 7 000000
15 -8 7 ffffff
0 -7 7 ffffff
1 -7 7 000000
2 -7 7 ffffff
3 -7 7 bf40bf
4 -7 7 bf40bf
5 -7 7 000000
6 -7 7 ffffff
7 -7 7 000000
8 -7 7 ffffff
9 -7 7 000000
10 -7 7 ffffff
11 -7 7 000000
12 -7 7 ffffff
13 -7 7 000000
14 -7 7 ffffff
15 -7 7 000000
0 -6 7 000000
1 -6 7 ffffff
2 -6 7 000000
3 -6 7 ffffff
4 -6 7 000000
5 -6 7 ffffff
6 -6 7 000000
7 -6 7 ffffff
8 -6 7 000000
9 -6 7 ffffff
10 -6 7 bf40bf
11 -6 7 ffffff
12 -6 7 bf40bf
13 -6 7 bf40bf
14 -6 7 000000
15 -6 7 ffffff
0 -5 7 ffffff
1 -5 7 000000
2 -5 7 ffffff
3 -5 7 bf40bf
4 -5 7 ffffff
5 -5 7 000000
6 -5 7 ffffff
7 -5 7 000000
8 -5 7 ffffff
9 -5 7 bf40bf
10 -5 7 ffffff
11 -5 7 bf40bf
12 -5 7 bf40bf
13 -5 7 000000
14 -5 7 bf40bf
15 -5 7 000000
0 -4 7 000000
1 -4 7 ffffff
2 -4 7 bf40bf
3 -4 7 ffffff
4 -4 7 000000
5 -4 7 ffffff
6 -4 7 000000
7 -4 7 ffffff
8 -4 7 000000
9 -4 7 ffffff
10 -4 7 000000
11 -4 7 ffffff
12 -4 7 000000
13 -4 7 ffffff
14 -4 7 000000
15 -4 7 ffffff
0 -3 7 ffffff
1 -3 7 bf40bf
2 -3 7 bf40bf
3 -3 7 bf40bf
4 -3 7 bf40bf
5 -3 7 000000
6 -3 7 bf40bf
7 -3 7 000000
8 -3 7 ffffff
9 -3 7 000000
10 -3 7 ffffff
11 -3 7 000000
12 -3 7 bf40bf
13 -3 7 000000
14 -3 7 ffffff
15 -3 7 000000
0 -2 7 bf40bf
1 -2 7 ffffff
2 -2 7 000000
3 -2 7 ffffff
4 -2 7 bf40bf
5 -2 7 ffffff
6 -2 7 000000
7 -2 7 bf40bf
8 -2 7 bf40bf
9 -2 7 ffffff
10 -2 7 000000
11 -2 7 ffffff
12 -2 7 000000
13 -2 7 ffffff
14 -2 7 000000
15 -2 7 ffffff
0 -1 7 ffffff
1 -1 7 bf40bf
2 -1 7 bf40bf
3 -1 7 000000
4 -1 7 bf40bf
5 -1 7 000000
6 -1 7 ffffff
7 -1 7 000000
8 -1 7 bf40bf
9 -1 7 000000
10 -1 7 ffffff
11 -1 7 bf40bf
12 -1 7 bf40bf
13 -1 7 000000
14 -1 7 ffffff
15 -1 7 000000
0 -16 8 000000
1 -16 8 ffffff
2 -16 8 000000
3 -16 8 ffffff
4 -16 8 bf40bf
5 -16 8 ffffff
6 -16 8 000000
7 -16 8 ffffff
8 -16 8 000000
9 -16 8 ffffff
10 -16 8 000000
11 -16 8 bf40bf
12 -16 8 bf40bf
13 -16 8 ffffff
14 -16 8 000000
15 -16 8 ffffff
0 -15 8 bf40bf
1 -15 8 bf40bf
2 -15 8 ffffff
3 -15 8 bf40bf
4 -15 8 ffffff
5 -15 8 bf40bf
6 -15 8 ffffff
7 -15 8 000000
8 -15 8 bf40bf
9 -15 8 000000
10 -15 8 ffffff
11 -15 8 000000
12 -15 8 ffffff
13 -15 8 000000
14 -15 8 ffffff
15 -15 8 000000
0 -14 8 000000
1 -14 8 ffffff
2 -14 8 bf40bf
3 -14 8 ffffff
4 -14 8 000000
5 -14 8 ffffff
6 -14 8 000000
7 -14 8 ffffff
8 -14 8 000000
9 -14 8 ffffff
10 -14 8 bf40bf
11 -14 8 ffffff
12 -14 8 000000
13 -14 8 ffffff
14 -14 8 000000
15 -14 8 ffffff
0 -13 8 ffffff
1 -13 8 000000
2 -13 8 ffffff
3 -13 8 bf40bf
4 -13 8 ffffff
5 -13 8 000000
6 -13 8 ffffff
7 -13 8 000000
8 -13 8 ffffff
9 -13 8 000000
10 -13 8 ffffff
11 -13 8 000000
12 -13 8 ffffff
13 -13 8 000000
14 -13 8 bf40bf
15 -13 8 000000
0 -12 8 000000
1 -12 8 ffffff
2 -12 8 000000
3 -12 8 ffffff
4 -12 8 000000
5 -12 8 ffffff
6 -12 8 bf40bf
7 -12 8 bf40bf
8 -12 8 000000
9 -12 8 ffffff
10 -12 8 000000
11 -12 8 ffffff
12 -12 8 000000
13 -12 8 ffffff
14 -12 8 000000
15 -12 8 ffffff
0 -11 8 ffffff
1 -11 8 000000
2 -11 8 ffffff
3 -11 8 000000
4 -11 8 ffffff
5 -11 8 000000
6 -11 8 bf40bf
7 -11 8 000000
8 -11 8 ffffff
9 -11 8 bf40bf
10 -11 8 ffffff
11 -11 8 bf40bf
12 -11 8 ffffff
13 -11 8 000000
14 -11 8 ffffff
15 -11 8 000000
0 -10 8 000000
1 -10 8 ffffff
2 -10 8 000000
3 -10 8 ffffff
4 -10 8 000000
5 -10 8 ffffff
6 -10 8 000000
7 -10 8 ffffff
8 -10 8 000000
9 -10 8 ffffff
10 -10 8 bf40bf
11 -10 8 ffffff
12 -10 8 000000
13 -10 8 ffffff
14 -10 8 000000
15 -10 8 ffffff
0 -9 8 ffffff
1 -9 8 000000
2 -9 8 ffffff
3 -9 8 000000
4 -9 8 ffffff
5 -9 8 bf40bf
6 -9 8 ffffff
7 -9 8 000000
8 -9 8 ffffff
9 -9 8 000000
10 -9 8 ffffff
11 -9 8 000000
12 -9 8 ffffff
13 -9 8 000000
14 -9 8 ffffff
15 -9 8 000000
0 -8 8 000000
1 -8 8 bf40bf
2 -8 8 000000
3 -8 8 bf40bf
4 -8 8 000000
5 -8 8 ffffff
6 -8 8 bf40bf
7 -8 8 bf40bf
8 -8 8 000000
9 -8 8 ffffff
10 -8 8 000000
11 -8 8 ffffff
12 -8 8 bf40bf
13 -8 8 ffffff
14 -8 8 000000
15 -8 8 ffffff
0 -7 8 ffffff
1 -7 8 000000
2 -7 8 ffffff
3 -7 8 bf40bf
4 -7 8 bf40bf
5 -7 8 000000
6 -7 8 ffffff
7 -7 8 000000
8 -7 8 ffffff
9 -7 8 000000
10 -7 8 ffffff
11 -7 8 000000
12 -7 8 ffffff
13 -7 8 000000
14 -7 8 ffffff
15 -7 8 000000
0 -6 8 000000
1 -6 8 ffffff
2 -6 8 000000
3 -6 8 ffffff
4 -6 8 000000
5 -6 8 ffffff
6 -6 8 000000
7 -6 8 ffffff
8 -6 8 000000
9 -6 8 ffffff
10 -6 8 bf40bf
11 -6 8 ffffff
12 -6 8 bf40bf
13 -6 8 bf40bf
14 -6 8 000000
15 -6 8 ffffff
0 -5 8 ffffff
1 -5 8 000000
2 -5 8 ffffff
3 -5 8 bf40bf
4 -5 8 ffffff
5 -5 8 000000
6 -5 8 ffffff
7 -5 8 000000
8 -5 8 ffffff
9 -5 8 bf40bf
10 -5 8 ffffff
11 -5 8 bf40bf
12 -5 8 bf40bf
13 -5 8 000000
14 -5 8 bf40bf
15 -5 8 000000
0 -4 8 000000
1 -4 8 ffffff
2 -4 8 bf40bf
3 -4 8 ffffff
4 -4 8 000000
5 -4 8 ffffff
6 -4 8 000000
7 -4 8 ffffff
8 -4 8 000000
9 -4 8 ffffff
10 -4 8 000000
11 -4 8 ffffff
12 -4 8 000000
13 -4 8 ffffff
14 -4 8 000000
15 -4 8 ffffff
0 -3 8 ffffff
1 -3 8 bf40bf
2 -3 8 bf40bf
3 -3 8 bf40bf
4 -3 8 bf40bf
5 -3 8 000000
6 -3 8 bf40bf
7 -3 8 000000
8 -3 8 ffffff
9 -3 8 000000
10 -3 8 ffffff
11 -3 8 000000
12 -3 8 bf40bf
13 -3 8 000000
14 -3 8 ffffff
15 -3 8 000000
0 -2 8 bf40bf
1 -2 8 ffffff
2 -2 8 000000
3 -2 8 ffffff
4 -2 8 bf40bf
5 -2 8 ffffff
6 -2 8 000000
7 -2 8 bf40bf
8 -2 8 bf40bf
9 -2 8 ffffff
10 -2 8 000000
11 -2 8 ffffff
12 -2 8 000000
13 -2 8 ffffff
14 -2 8 000000
15 -2 8 ffffff
0 -1 8 ffffff
1 -1 8 bf40bf
2 -1 8 bf40bf
3 -1 8 000000
4 -1 8 bf40bf
5 -1 8 000000
6 -1 8 ffffff
7 -1 8 000000
8 -1 8 bf40bf
9 -1 8 000000
10 -1 8 ffffff
11 -1 8 bf40bf
12 -1 8 bf40bf
13 -1 8 000000
14 -1 8 ffffff
15 -1 8 000000
0 -16 9 000000
1 -16 9 ffffff
2 -16 9 000000
3 -16 9 ffffff
4 -16 9 bf40bf
5 -16 9 ffffff
6 -16 9 000000
7 -16 9 ffffff
8 -16 9 000000
9 -16 9 ffffff
10 -16 9 000000
11 -16 9 bf40bf
12 -16 9 bf40bf
13 -16 9 ffffff
14 -16 9 000000
15 -16 9 ffffff
0 -15 9 bf40bf
1 -15 9 bf40bf
2 -15 9 ffffff
3 -15 9 bf40bf
4 -15 9 ffffff
5 -15 9 bf40bf
6 -15 9 ffffff
7 -15 9 000000
8 -15 9 bf40bf
9 -15 9 000000
10 -15 9 ffffff
11 -15 9 000000
12 -15 9 ffffff
13 -15 9 000000
14 -15 9 ffffff
15 -15 9 000000
0 -14 9 000000
1 -14 9 ffffff
2 -14 9 bf40bf
3 -14 9 ffffff
4 -14 9 000000
5 -14 9 ffffff
6 -14 9 000000
7 -14 9 ffffff
8 -14 9 000000
9 -14 9 ffffff
10 -14 9 bf40bf
11 -14 9 ffffff
12 -14 9 000000
13 -14 9 ffffff
14 -14 9 000000
15 -14 9 ffffff
0 -13 9 ffffff
1 -13 9 000000
2 -13 9 ffffff
3 -13 9 bf40bf
4 -13 9 ffffff
5 -13 9 000000
6 -13 9 ffffff
7 -13 9 000000
8 -13 9 ffffff
9 -13 9 000000
10 -13 9 ffffff
11 -13 9 000000
12 -13 9 ffffff
13 -13 9 000000
14 -13 9 bf40bf
15 -13 9 000000
0 -12 9 000000
1 -12 9 ffffff
2 -12 9 000000
3 -12 9 ffffff
4 -12 9 000000
5 -12 9 ffffff
6 -12 9 bf40bf
7 -12 9 bf40bf
8 -12 9 000000
9 -12 9 ffffff
10 -12 9 000000
11 -12 9 ffffff
12 -12 9 000000
13 -12 9 ffffff
14 -12 9 000000
15 -12 9 ffffff
0 -11 9 ffffff
1 -11 9 000000
2 -11 9 ffffff
3 -11 9 000000
4 -11 9 ffffff
5 -11 9 000000
6 -11 9 bf40bf
7 -11 9 000000
8 -11 9 ffffff
9 -11 9 bf40bf
10 -11 9 ffffff
11 -11 9 bf40bf
12 -11 9 ffffff
13 -11 9 000000
14 -11 9 ffffff
15 -11 9 000000
0 -10 9 000000
1 -10 9 ffffff
2 -10 9 000000
3 -10 9 ffffff
4 -10 9 000000
5 -10 9 ffffff
6 -10 9 000000
7 -10 9 ffffff
8 -10 9 000000
9 -10 9 ffffff
10 -10 9 bf40bf
11 -10 9 ffffff
12 -10 9 000000
13 -10 9 ffffff
14 -10 9 000000
15 -10 9 ffffff
0 -9 9 ffffff
1 -9 9 000000
2 -9 9 ffffff
3 -9 9 000000
4 -9 9 ffffff
5 -9 9 bf40bf
6 -9 9 ffffff
7 -9 9 000000
8 -9 9 ffffff
9 -9 9 000000
10 -9 9 ffffff
11 -9 9 000000
12 -9 9 ffffff
13 -9 9 000000
14 -9 9 ffffff
15 -9 9 000000
0 -8 9 000000
1 -8 9 bf40bf
2 -8 9 000000
3 -8 9 bf40bf
4 -8 9 000000
5 -8 9 ffffff
6 -8 9 bf40bf
7 -8 9 bf40bf
8 -8 9 000000
9 -8 9 ffffff
10 -8 9 000000
11 -8 9 ffffff
12 -8 9 bf40bf
13 -8 9 ffffff
14 -8 9 000000
15 -8 9 ffffff
0 -7 9 ffffff
1 -7 9 000000
2 -7 9 ffffff
3 -7 9 bf40bf
4 -7 9 bf40bf
5 -7 9 000000
6 -7 9 ffffff
7 -7 9 000000
8 -7 9 ffffff
9 -7 9 000000
10 -7 9 ffffff
11 -7 9 000000
12 -7 9 ffffff
13 -7 9 000000
14 -7 9 ffffff
15 -7 9 000000
0 -6 9 000000
1 -6 9 ffffff
2 -6 9 000000
3 -6 9 ffffff
4 -6 9 000000
5 -6 9 ffffff
6 -6 9 000000
7 -6 9 ffffff
8 -6 9 000000
9 -6 9 ffffff
10 -6 9 bf40bf
11 -6 9 ffffff
12 -6 9 bf40bf
13 -6 9 bf40bf
14 -6 9 000000
15 -6 9 ffffff
0 -5 9 ffffff
1 -5 9 000000
2 -5 9 ffffff
3 -5 9 bf40bf
4 -5 9 ffffff
5 -5 9 000000
6 -5 9 ffffff
7 -5 9 000000
8 -5 9 ffffff
9 -5 9 bf40bf
10 -5 9 ffffff
11 -5 9 bf40bf
12 -5 9 bf40bf
13 -5 9 000000
14 -5 9 bf40bf
15 -5 9 000000
0 -4 9 000000
1 -4 9 ffffff
2 -4 9 bf40bf
3 -4 9 ffffff
4 -4 9 000000
5 -4 9 ffffff
6 -4 9 000000
7 -4 9 ffffff
8 -4 9 000000
9 -4 9 ffffff
10 -4 9 000000
11 -4 9 ffffff
12 -4 9 000000
13 -4 9 ffffff
14 -4 9 000000
15 -4 9 ffffff
0 -3 9 ffffff
1 -3 9 bf40bf
2 -3 9 bf40bf
3 -3 9 bf40bf
4 -3 9 bf40bf
5 -3 9 000000
6 -3 9 bf40bf
7 -3 9 000000
8 -3 9 ffffff
9 -3 9 000000
10 -3 9 ffffff
11 -3 9 000000
12 -3 9 bf40bf
13 -3 9 000000
14 -3 9 ffffff
15 -3 9 000000
0 -2 9 bf40bf
1 -2 9 ffffff
2 -2 9 000000
3 -2 9 ffffff
4 -2 9 bf40bf
5 -2 9 ffffff
6 -2 9 000000
7 -2 9 bf40bf
8 -2 9 bf40bf
9 -2 9 ffffff
10 -2 9 000000
11 -2 9 ffffff
12 -2 9 000000
13 -2 9 ffffff
14 -2 9 000000
15 -2 9 ffffff
0 -1 9 ffffff
1 -1 9 bf40bf
2 -1 9 bf40bf
3 -1 9 000000
4 -1 9 bf40bf
5 -1 9 000000
6 -1 9 ffffff
7 -1 9 000000
8 -1 9 bf40bf
9 -1 9 000000
10 -1 9 ffffff
11 -1 9 bf40bf
12 -1 9 bf40bf
13 -1 9 000000
14 -1 9 ffffff
15 -1 9 000000
0 -16 10 000000
1 -16 10 ffffff
2 -16 10 000000
3 -16 10 ffffff
4 -16 10 bf40bf
5 -16 10 ffffff
6 -16 10 000000
12 -16 10 bf40bf
13 -16 10 ffffff
14 -16 10 000000
15 -16 10 ffffff
0 -15 10 bf40bf
1 -15 10 bf40bf
2 -15 10 ffffff
3 -15 10 bf40bf
4 -15 10 ffffff
5 -15 10 bf40bf
6 -15 10 ffffff
12 -15 10 ffffff
13 -15 10 000000
14 -15 10 ffffff
15 -15 10 000000
0 -14 10 000000
1 -14 10 ffffff
2 -14 10 bf40bf
3 -14 10 ffffff
4 -14 10 000000
5 -14 10 ffffff
6 -14 10 000000
7 -14 10 ffffff
12 -14 10 000000
13 -14 10 ffffff
14 -14 10 000000
15 -14 10 ffffff
0 -13 10 ffffff
1 -13 10 000000
2 -13 10 ffffff
3 -13 10 bf40bf
4 -13 10 ffffff
5 -13 10 000000
6 -13 10 ffffff
7 -13 10 000000
12 -13 10 ffffff
13 -13 10 000000
14 -13 10 bf40bf
15 -13 10 000000
0 -12 10 000000
1 -12 10 ffffff
2 -12 10 000000
3 -12 10 ffffff
4 -12 10 000000
5 -12 10 ffffff
6 -12 10 bf40bf
7 -12 10 bf40bf
12 -12 10 000000
13 -12 10 ffffff
14 -12 10 000000
0 -11 10 ffffff
1 -11 10 000000
2 -11 10 ffffff
3 -11 10 000000
4 -11 10 ffffff
5 -11 10 000000
6 -11 10 bf40bf
7 -11 10 000000
12 -11 10 ffffff
13 -11 10 000000
0 -10 10 000000
1 -10 10 ffffff
2 -10 10 000000
3 -10 10 ffffff
4 -10 10 000000
5 -10 10 ffffff
6 -10 10 000000
7 -10 10 ffffff
12 -10 10 000000
15 -10 10 ffffff
0 -9 10 ffffff
1 -9 10 000000
2 -9 10 ffffff
3 -9 10 000000
4 -9 10 ffffff
5 -9 10 bf40bf
6 -9 10 ffffff
7 -9 10 000000
13 -9 10 000000
14 -9 10 ffffff
15 -9 10 000000
0 -8 10 000000
1 -8 10 bf40bf
2 -8 10 000000
3 -8 10 bf40bf
4 -8 10 000000
5 -8 10 ffffff
6 -8 10 bf40bf
7 -8 10 bf40bf
12 -8 10 bf40bf
13 -8 10 ffffff
14 -8 10 000000
15 -8 10 ffffff
0 -7 10 ffffff
1 -7 10 000000
2 -7 10 ffffff
3 -7 10 bf40bf
4 -7 10 bf40bf
5 -7 10 000000
6 -7 10 ffffff
7 -7 10 000000
12 -7 10 ffffff
13 -7 10 000000
14 -7 10 ffffff
15 -7 10 000000
0 -6 10 000000
1 -6 10 ffffff
2 -6 10 000000
3 -6 10 ffffff
4 -6 10 000000
5 -6 10 ffffff
6 -6 10 000000
7 -6 10 ffffff
12 -6 10 bf40bf
13 -6 10 bf40bf
14 -6 10 000000
15 -6 10 ffffff
0 -5 10 ffffff
1 -5 10 000000
2 -5 10 ffffff
3 -5 10 bf40bf
4 -5 10 ffffff
5 -5 10 000000
6 -5 10 ffffff
7 -5 10 000000
12 -5 10 bf40bf
13 -5 10 000000
14 -5 10 bf40bf
15 -5 10 000000
0 -4 10 000000
1 -4 10 ffffff
2 -4 10 bf40bf
3 -4 10 ffffff
4 -4 10 000000
5 -4 10 ffffff
6 -4 10 000000
12 -4 10 000000
13 -4 10 ffffff
14 -4 10 000000
15 -4 10 ffffff
0 -3 10 ffffff
1 -3 10 bf40bf
2 -3 10 bf40bf
3 -3 10 bf40bf
4 -3 10 bf40bf
5 -3 10 000000
6 -3 10 bf40bf
12 -3 10 bf40bf
13 -3 10 000000
14 -3 10 ffffff
15 -3 10 000000
0 -2 10 bf40bf
1 -2 10 ffffff
2 -2 10 000000
3 -2 10 ffffff
4 -2 10 bf40bf
5 -2 10 ffffff
6 -2 10 000000
12 -2 10 000000
13 -2 10 ffffff
14 -2 10 000000
15 -2 10 ffffff
0 -1 10 ffffff
1 -1 10 bf40bf
2 -1 10 bf40bf
3 -1 10 000000
4 -1 10 bf40bf
5 -1 10 000000
6 -1 10 ffffff
11 -1 10 bf40bf
12 -1 10 bf40bf
13 -1 10 000000
14 -1 10 ffffff
15 -1 10 000000
0 -16 11 000000
1 -16 11 ffffff
2 -16 11 000000
3 -16 11 ffffff
4 -16 11 bf40bf
6 -16 11 000000
0 -15 11 bf40bf
1 -15 11 bf40bf
2 -15 11 ffffff
3 -15 11 bf40bf
4 -15 11 ffffff
6 -15 11 ffffff
0 -14 11 000000
1 -14 11 ffffff
2 -14 11 bf40bf
3 -14 11 ffffff
4 -14 11 000000
6 -14 11 000000
0 -13 11 ffffff
1 -13 11 000000
2 -13 11 ffffff
3 -13 11 bf40bf
4 -13 11 ffffff
6 -13 11 ffffff
0 -12 11 000000
1 -12 11 ffffff
2 -12 11 000000
3 -12 11 ffffff
4 -12 11 000000
6 -12 11 bf40bf
0 -11 11 ffffff
1 -11 11 000000
2 -11 11 ffffff
3 -11 11 000000
4 -11 11 ffffff
15 -11 11 000000
0 -10 11 000000
1 -10 11 ffffff
2 -10 11 000000
3 -10 11 ffffff
4 -10 11 000000
14 -10 11 000000
15 -10 11 ffffff
0 -9 11 ffffff
1 -9 11 000000
2 -9 11 ffffff
3 -9 11 000000
13 -9 11 000000
14 -9 11 ffffff
15 -9 11 000000
0 -8 11 000000
1 -8 11 bf40bf
13 -8 11 ffffff
14 -8 11 000000
15 -8 11 ffffff
13 -7 11 000000
14 -7 11 ffffff
15 -7 11 000000
3 -6 11 ffffff
4 -6 11 000000
13 -6 11 bf40bf
14 -6 11 000000
15 -6 11 ffffff
2 -5 11 ffffff
3 -5 11 bf40bf
13 -5 11 000000
14 -5 11 bf40bf
15 -5 11 000000
1 -4 11 ffffff
2 -4 11 bf40bf
13 -4 11 ffffff
14 -4 11 000000
15 -4 11 ffffff
1 -3 11 bf40bf
12 -3 11 bf40bf
13 -3 11 000000
14 -3 11 ffffff
15 -3 11 000000
12 -2 11 000000
13 -2 11 ffffff
14 -2 11 000000
15 -2 11 ffffff
4 -1 11 bf40bf
12 -1 11 bf40bf
13 -1 11 000000
14 -1 11 ffffff
15 -1 11 000000
-16 0 0 000000
-15 0 0 ffffff
-14 0 0 000000
-13 0 0 ffffff
-12 0 0 000000
-11 0 0 ffffff
-10 0 0 000000
-9 0 0 ffffff
-8 0 0 bf40bf
-7 0 0 ffffff
-6 0 0 000000
-5 0 0 bf40bf
-4 0 0 bf40bf
-3 0 0 ffffff
-2 0 0 000000
-1 0 0 bf40bf
-16 1 0 ffffff
-15 1 0 000000
-14 1 0 ffffff
-13 1 0 000000
-12 1 0 ffffff
-11 1 0 000000
-10 1 0 ffffff
-9 1 0 000000
-8 1 0 bf40bf
-7 1 0 000000
-6 1 0 ffffff
-5 1 0 000000
-4 1 0 ffffff
-3 1 0 000000
-2 1 0 ffffff
-1 1 0 000000
-16 2 0 000000
-15 2 0 ffffff
-14 2 0 bf40bf
-13 2 0 ffffff
-12 2 0 000000
-11 2 0 ffffff
-10 2 0 000000
-9 2 0 ffffff
-8 2 0 000000
-7 2 0 ffffff
-6 2 0 000000
-5 2 0 bf40bf
-4 2 0 000000
-3 2 0 ffffff
-2 2 0 000000
-1 2 0 bf40bf
-16 3 0 ffffff
-15 3 0 bf40bf
-14 3 0 ffffff
-13 3 0 000000
-12 3 0 ffffff
-11 3 0 000000
-10 3 0 ffffff
-9 3 0 000000
-8 3 0 ffffff
-7 3 0 000000
-6 3 0 ffffff
-5 3 0 000000
-4 3 0 ffffff
-3 3 0 000000
-2 3 0 ffffff
-1 3 0 000000
-16 4 0 000000
-15 4 0 ffffff
-14 4 0 000000
-13 4 0 bf40bf
-12 4 0 000000
-11 4 0 ffffff
-10 4 0 000000
-9 4 0 ffffff
-8 4 0 bf40bf
-7 4 0 ffffff
-6 4 0 bf40bf
-5 4 0 bf40bf
-4 4 0 000000
-3 4 0 bf40bf
-2 4 0 000000
-1 4 0 ffffff
-16 5 0 bf40bf
-15 5 0 000000
-14 5 0 ffffff
-13 5 0 000000
-12 5 0 ffffff
-11 5 0 000000
-10 5 0 bf40bf
-9 5 0 000000
-8 5 0 ffffff
-7 5 0 000000
-6 5 0 ffffff
-5 5 0 000000
-4 5 0 ffffff
-3 5 0 bf40bf
-2 5 0 ffffff
-1 5 0 bf40bf
-16 6 0 000000
-15 6 0 ffffff
-14 6 0 000000
-13 6 0 ffffff
-12 6 0 000000
-11 6 0 bf40bf
-10 6 0 000000
-9 6 0 ffffff
-8 6 0 000000
-7 6 0 ffffff
-6 6 0 000000
-5 6 0 ffffff
-4 6 0 000000
-3 6 0 ffffff
-2 6 0 000000
-1 6 0 bf40bf
-16 7 0 ffffff
-15 7 0 000000
-14 7 0 ffffff
-13 7 0 000000
-12 7 0 ffffff
-11 7 0 000000
-10 7 0 bf40bf
-9 7 0 000000
-8 7 0 ffffff
-7 7 0 000000
-6 7 0 ffffff
-5 7 0 000000
-4 7 0 ffffff
-3 7 0 000000
-2 7 0 ffffff
-1 7 0 000000
-16 8 0 bf40bf
-15 8 0 ffffff
-14 8 0 000000
-13 8 0 ffffff
-12 8 0 000000
-11 8 0 ffffff
-10 8 0 000000
-9 8 0 ffffff
-8 8 0 000000
-7 8 0 bf40bf
-6 8 0 bf40bf
-5 8 0 ffffff
-4 8 0 000000
-3 8 0 ffffff
-2 8 0 000000
-1 8 0 ffffff
-16 9 0 ffffff
-15 9 0 000000
-14 9 0 ffffff
-13 9 0 000000
-12 9 0 ffffff
-11 9 0 000000
-10 9 0 ffffff
-9 9 0 000000
-8 9 0 ffffff
-7 9 0 000000
-6 9 0 ffffff
-5 9 0 000000
-4 9 0 ffffff
-3 9 0 000000
-2 9 0 ffffff
-1 9 0 000000
-16 10 0 000000
-15 10 0 ffffff
-14 10 0 000000
-13 10 0 ffffff
-12 10 0 bf40bf
-11 10 0 ffffff
-10 10 0 000000
-9 10 0 bf40bf
-8 10 0 bf40bf
-7 10 0 ffffff
-6 10 0 000000
-5 10 0 ffffff
-4 10 0 000000
-3 10 0 bf40bf
-2 10 0 000000
-1 10 0 ffffff
-16 11 0 bf40bf
-15 11 0 000000
-14 11 0 ffffff
-13 11 0 000000
-12 11 0 ffffff
-11 11 0 000000
-10 11 0 ffffff
-9 11 0 000000
-8 11 0 ffffff
-7 11 0 000000
-6 11 0 ffffff
-5 11 0 000000
-4 11 0 ffffff
-3 11 0 bf40bf
-2 11 0 ffffff
-1 11 0 000000
-16 12 0 000000
-15 12 0 ffffff
-14 12 0 000000
-13 12 0 ffffff
-12 12 0 bf40bf
-11 12 0 ffffff
-10 12 0 000000
-9 12 0 ffffff
-8 12 0 000000
-7 12 0 bf40bf
-6 12 0 000000
-5 12 0 ffffff
-4 12 0 000000
-3 12 0 ffffff
-2 12 0 000000
-1 12 0 ffffff
-16 13 0 ffffff
-15 13 0 000000
-14 13 0 ffffff
-13 13 0 000000
-12 13 0 bf40bf
-11 13 0 000000
-10 13 0 ffffff
-9 13 0 bf40bf
-8 13 0 ffffff
-7 13 0 000000
-6 13 0 ffffff
-5 13 0 000000
-4 13 0 ffffff
-3 13 0 000000
-2 13 0 ffffff
-1 13 0 000000
-16 14 0 000000
-15 14 0 ffffff
-14 14 0 000000
-13 14 0 ffffff
-12 14 0 000000
-11 14 0 bf40bf
-10 14 0 000000
-9 14 0 ffffff
-8 14 0 000000
-7 14 0 ffffff
-6 14 0 000000
-5 14 0 ffffff
-4 14 0 000000
-3 14 0 ffffff
-2 14 0 000000
-1 14 0 ffffff
-16 15 0 ffffff
-15 15 0 000000
-14 15 0 ffffff
-13 15 0 000000
-12 15 0 ffffff
-11 15 0 000000
-10 15 0 ffffff
-9 15 0 000000
-8 15 0 ffffff
-7 15 0 000000
-6 15 0 ffffff
-5 15 0 000000
-4 15 0 ffffff
-3 15 0 000000
-2 15 0 ffffff
-1 15 0 000000
-16 0 1 000000
-15 0 1 ffffff
-14 0 1 000000
-13 0 1 ffffff
-12 0 1 000000
-11 0 1 ffffff
-10 0 1 000000
-9 0 1 ffffff
-8 0 1 bf40bf
-7 0 1 ffffff
-6 0 1 000000
-5 0 1 bf40bf
-4 0 1 bf40bf
-3 0 1 ffffff
-2 0 1 000000
-1 0 1 bf40bf
-16 1 1 ffffff
-15 1 1 000000
-14 1 1 ffffff
-13 1 1 000000
-12 1 1 ffffff
-11 1 1 000000
-10 1 1 ffffff
-9 1 1 000000
-8 1 1 bf40bf
-7 1 1 000000
-6 1 1 ffffff
-5 1 1 000000
-4 1 1 ffffff
-3 1 1 000000
-2 1 1 ffffff
-1 1 1 000000
-16 2 1 000000
-15 2 1 ffffff
-14 2 1 bf40bf
-13 2 1 ffffff
-12 2 1 000000
-11 2 1 ffffff
-10 2 1 000000
-9 2 1 ffffff
-8 2 1 000000
-7 2 1 ffffff
-6 2 1 000000
-5 2 1 bf40bf
-4 2 1 000000
-3 2 1 ffffff
-2 2 1 000000
-1 2 1 bf40bf
-16 3 1 ffffff
-15 3 1 bf40bf
-14 3 1 ffffff
-13 3 1 000000
-12 3 1 ffffff
-11 3 1 000000
-10 3 1 ffffff
-9 3 1 000000
-8 3 1 ffffff
-7 3 1 000000
-6 3 1 ffffff
-5 3 1 000000
-4 3 1 ffffff
-3 3 1 000000
-2 3 1 ffffff
-1 3 1 000000
-16 4 1 000000
-15 4 1 ffffff
-14 4 1 000000
-13 4 1 bf40bf
-12 4 1 000000
-11 4 1 ffffff
-10 4 1 000000
-9 4 1 ffffff
-8 4 1 bf40bf
-7 4 1 ffffff
-6 4 1 bf40bf
-5 4 1 bf40bf
-4 4 1 000000
-3 4 1 bf40bf
-2 4 1 000000
-1 4 1 ffffff
-16 5 1 bf40bf
-15 5 1 000000
-14 5 1 ffffff
-13 5 1 000000
-12 5 1 ffffff
-11 5 1 000000
-10 5 1 bf40bf
-9 5 1 000000
-8 5 1 ffffff
-7 5 1 000000
-6 5 1 ffffff
-5 5 1 000000
-4 5 1 ffffff
-3 5 1 bf40bf
-2 5 1 ffffff
-1 5 1 bf40bf
-16 6 1 000000
-15 6 1 ffffff
-14 6 1 000000
-13 6 1 ffffff
-12 6 1 000000
-11 6 1 bf40bf
-10 6 1 000000
-9 6 1 ffffff
-8 6 1 000000
-7 6 1 ffffff
-6 6 1 000000
-5 6 1 ffffff
-4 6 1 000000
-3 6 1 ffffff
-2 6 1 000000
-1 6 1 bf40bf
-16 7 1 ffffff
-15 7 1 000000
-14 7 1 ffffff
-13 7 1 000000
-12 7 1 ffffff
-11 7 1 000000
-10 7 1 bf40bf
-9 7 1 000000
-8 7 1 ffffff
-7 7 1 000000
-6 7 1 ffffff
-5 7 1 000000
-4 7 1 ffffff
-3 7 1 000000
-2 7 1 ffffff
-1 7 1 000000
-16 8 1 bf40bf
-15 8 1 ffffff
-14 8 1 000000
-13 8 1 ffffff
-12 8 1 000000
-11 8 1 ffffff
-10 8 1 000000
-9 8 1 ffffff
-8 8 1 000000
-7 8 1 bf40bf
-6 8 1 bf40bf
-5 8 1 ffffff
-4 8 1 000000
-3 8 1 ffffff
-2 8 1 000000
-1 8 1 ffffff
-16 9 1 ffffff
-15 9 1 000000
-14 9 1 ffffff
-13 9 1 000000
-12 9 1 ffffff
-11 9 1 000000
-10 9 1 ffffff
-9 9 1 000000
-8 9 1 ffffff
-7 9 1 000000
-6 9 1 ffffff
-5 9 1 000000
-4 9 1 ffffff
-3 9 1 000000
-2 9 1 ffffff
-1 9 1 000000
-16 10 1 000000
-15 10 1 ffffff
-14 10 1 000000
-13 10 1 ffffff
-12 10 1 bf40bf
-11 10 1 ffffff
-10 10 1 000000
-9 10 1 bf40bf
-8 10 1 bf40bf
-7 10 1 ffffff
-6 10 1 000000
-5 10 1 ffffff
-4 10 1 000000
-3 10 1 bf40bf
-2 10 1 000000
-1 10 1 ffffff
-16 11 1 bf40bf
-15 11 1 000000
-14 11 1 ffffff
-13 11 1 000000
-12 11 1 ffffff
-11 11 1 000000
-10 11 1 ffffff
-9 11 1 000000
-8 11 1 ffffff
-7 11 1 000000
-6 11 1 ffffff
-5 11 1 000000
-4 11 1 ffffff
-3 11 1 bf40bf
-2 11 1 ffffff
-1 11 1 000000
-16 12 1 000000
-15 12 1 ffffff
-14 12 1 000000
-13 12 1 ffffff
-12 12 1 bf40bf
-11 12 1 ffffff
-10 12 1 000000
-9 12 1 ffffff
-8 12 1 000000
-7 12 1 bf40bf
-6 12 1 000000
-5 12 1 ffffff
-4 12 1 000000
-3 12 1 ffffff
-2 12 1 000000
-1 12 1 ffffff
-16 13 1 ffffff
-15 13 1 000000
-14 13 1 ffffff
-13 13 1 000000
-12 13 1 bf40bf
-11 13 1 000000
-10 13 1 ffffff
-9 13 1 bf40bf
-8 13 1 ffffff
-7 13 1 000000
-6 13 1 ffffff
-5 13 1 000000
-4 13 1 ffffff
-3 13 1 000000
-2 13 1 ffffff
-1 13 1 000000
-16 14 1 000000
-15 14 1 ffffff
-14 14 1 000000
-13 14 1 ffffff
-12 14 1 000000
-11 14 1 bf40bf
-10 14 1 000000
-9 14 1 ffffff
-8 14 1 000000
-7 14 1 ffffff
-6 14 1 000000
-5 14 1 ffffff
-4 14 1 000000
-3 14 1 ffffff
-2 14 1 000000
-1 14 1 ffffff
-16 15 1 ffffff
-15 15 1 000000
-14 15 1 ffffff
-13 15 1 000000
-12 15 1 ffffff
-11 15 1 000000
-10 15 1 ffffff
-9 15 1 000000
-8 15 1 ffffff
-7 15 1 000000
-6 15 1 ffffff
-5 15 1 000000
-4 15 1 ffffff
-3 15 1 000000
-2 15 1 ffffff
-1 15 1 000000
-16 0 2 000000
-15 0 2 ffffff
-14 0 2 000000
-13 0 2 ffffff
-12 0 2 000000
-11 0 2 ffffff
-10 0 2 000000
-9 0 2 ffffff
-8 0 2 bf40bf
-7 0 2 ffffff
-6 0 2 000000
-5 0 2 bf40bf
-4 0 2 bf40bf
-3 0 2 ffffff
-2 0 2 000000
-1 0 2 bf40bf
-16 1 2 ffffff
-15 1 2 000000
-14 1 2 ffffff
-13 1 2 000000
-12 1 2 ffffff
-11 1 2 000000
-10 1 2 ffffff
-9 1 2 000000
-8 1 2 bf40bf
-7 1 2 000000
-6 1 2 ffffff
-5 1 2 000000
-4 1 2 ffffff
-3 1 2 000000
-2 1 2 ffffff
-1 1 2 000000
-16 2 2 000000
-15 2 2 ffffff
-14 2 2 bf40bf
-13 2 2 ffffff
-12 2 2 000000
-11 2 2 ffffff
-10 2 2 000000
-9 2 2 ffffff
-8 2 2 000000
-7 2 2 ffffff
-6 2 2 000000
-5 2 2 bf40bf
-4 2 2 000000
-3 2 2 ffffff
-2 2 2 000000
-1 2 2 bf40bf
-16 3 2 ffffff
-15 3 2 bf40bf
-14 3 2 ffffff
-13 3 2 000000
-12 3 2 ffffff
-11 3 2 000000
-10 3 2 ffffff
-9 3 2 000000
-8 3 2 ffffff
-7 3 2 000000
-6 3 2 ffffff
-5 3 2 000000
-4 3 2 ffffff
-3 3 2 000000
-2 3 2 ffffff
-1 3 2 000000
-16 4 2 000000
-15 4 2 ffffff
-14 4 2 000000
-13 4 2 bf40bf
-12 4 2 000000
-11 4 2 ffffff
-10 4 2 000000
-9 4 2 ffffff
-8 4 2 bf40bf
-7 4 2 ffffff
-6 4 2 bf40bf
-5 4 2 bf40bf
-4 4 2 000000
-3 4 2 bf40bf
-2 4 2 000000
-1 4 2 ffffff
-16 5 2 bf40bf
-15 5 2 000000
-14 5 2 ffffff
-13 5 2 000000
-12 5 2 ffffff
-11 5 2 000000
-10 5 2 bf40bf
-9 5 2 000000
-8 5 2 ffffff
-7 5 2 000000
-6 5 2 ffffff
-5 5 2 000000
-4 5 2 ffffff
-3 5 2 bf40bf
-2 5 2 ffffff
-1 5 2 bf40bf
-16 6 2 000000
-15 6 2 ffffff
-14 6 2 000000
-13 6 2 ffffff
-12 6 2 000000
-11 6 2 bf40bf
-10 6 2 000000
-9 6 2 ffffff
-8 6 2 000000
-7 6 2 ffffff
-6 6 2 000000
-5 6 2 ffffff
-4 6 2 000000
-3 6 2 ffffff
-2 6 2 000000
-1 6 2 bf40bf
-16 7 2 ffffff
-15 7 2 000000
-14 7 2 ffffff
-13 7 2 000000
-12 7 2 ffffff
-11 7 2 000000
-10 7 2 bf40bf
-9 7 2 000000
-8 7 2 ffffff
-7 7 2 000000
-6 7 2 ffffff
-5 7 2 000000
-4 7 2 ffffff
-3 7 2 000000
-2 7 2 ffffff
-1 7 2 000000
-16 8 2 bf40bf
-15 8 2 ffffff
-14 8 2 000000
-13 8 2 ffffff
-12 8 2 000000
-11 8 2 ffffff
-10 8 2 000000
-9 8 2 ffffff
-8 8 2 000000
-7 8 2 bf40bf
-6 8 2 bf40bf
-5 8 2 ffffff
-4 8 2 000000
-3 8 2 ffffff
-2 8 2 000000
-1 8 2 ffffff
-16 9 2 ffffff
-15 9 2 000000
-14 9 2 ffffff
-13 9 2 000000
-12 9 2 ffffff
-11 9 2 000000
-10 9 2 ffffff
-9 9 2 000000
-8 9 2 ffffff
-7 9 2 000000
-6 9 2 ffffff
-5 9 2 000000
-4 9 2 ffffff
-3 9 2 000000
-2 9 2 ffffff
-1 9 2 000000
-16 10 2 000000
-15 10 2 ffffff
-14 10 2 000000
-13 10 2 ffffff
-12 10 2 bf40bf
-11 10 2 ffffff
-10 10 2 000000
-9 10 2 bf40bf
-8 10 2 bf40bf
-7 10 2 ffffff
-6 10 2 000000
-5 10 2 ffffff
-4 10 2 000000
-3 10 2 bf40bf
-2 10 2 000000
-1 10 2 ffffff
-16 11 2 bf40bf
-15 11 2 000000
-14 11 2 ffffff
-13 11 2 000000
-12 11 2 ffffff
-11 11 2 000000
-10 11 2 ffffff
-9 11 2 000000
-8 11 2 ffffff
-7 11 2 000000
-6 11 2 ffffff
-5 11 2 000000
-4 11 2 ffffff
-3 11 2 bf40bf
-2 11 2 ffffff
-1 11 2 000000
-16 12 2 000000
-15 12 2 ffffff
-14 12 2 000000
-13 12 2 ffffff
-12 12 2 bf40bf
-11 12 2 ffffff
-10 12 2 000000
-9 12 2 ffffff
-8 12 2 000000
-7 12 2 bf40bf
-6 12 2 000000
-5 12 2 ffffff
-4 12 2 000000
-3 12 2 ffffff
-2 12 2 000000
-1 12 2 ffffff
-16 13 2 ffffff
-15 13 2 000000
-14 13 2 ffffff
-13 13 2 000000
-12 13 2 bf40bf
-11 13 2 000000
-10 13 2 ffffff
-9 13 2 bf40bf
-8 13 2 ffffff
-7 13 2 000000
-6 13 2 ffffff
-5 13 2 000000
-4 13 2 ffffff
-3 13 2 000000
-2 13 2 ffffff
-1 13 2 000000
-16 14 2 000000
-15 14 2 ffffff
-14 14 2 000000
-13 14 2 ffffff
-12 14 2 000000
-11 14 2 bf40bf
-10 14 2 000000
-9 14 2 ffffff
-8 14 2 000000
-7 14 2 ffffff
-6 14 2 000000
-5 14 2 ffffff
-4 14 2 000000
-3 14 2 ffffff
-2 14 2 000000
-1 14 2 ffffff
-16 15 2 ffffff
-15 15 2 000000
-14 15 2 ffffff
-13 15 2 000000
-12 15 2 ffffff
-11 15 2 000000
-10 15 2 ffffff
-9 15 2 000000
-8 15 2 ffffff
-7 15 2 000000
-6 15 2 ffffff
-5 15 2 000000
-4 15 2 ffffff
-3 15 2 000000
-2 15 2 ffffff
-1 15 2 000000
-16 0 3 000000
-15 0 3 ffffff
-14 0 3 000000
-13 0 3 ffffff
-12 0 3 000000
-11 0 3 ffffff
-10 0 3 000000
-9 0 3 ffffff
-8 0 3 bf40bf
-7 0 3 ffffff
-6 0 3 000000
-5 0 3 bf40bf
-4 0 3 bf40bf
-3 0 3 ffffff
-2 0 3 000000
-1 0 3 bf40bf
-16 1 3 ffffff
-15 1 3 000000
-14 1 3 ffffff
-13 1 3 000000
-12 1 3 ffffff
-11 1 3 000000
-10 1 3 ffffff
-9 1 3 000000
-8 1 3 bf40bf
-7 1 3 000000
-6 1 3 ffffff
-5 1 3 000000
-4 1 3 ffffff
-3 1 3 000000
-2 1 3 ffffff
-1 1 3 000000
-16 2 3 000000
-15 2 3 ffffff
-14 2 3 bf40bf
-13 2 3 ffffff
-12 2 3 000000
-11 2 3 ffffff
-10 2 3 000000
-9 2 3 ffffff
-8 2 3 000000
-7 2 3 ffffff
-6 2 3 000000
-5 2 3 bf40bf
-4 2 3 000000
-3 2 3 ffffff
-2 2 3 000000
-1 2 3 bf40bf
-16 3 3 ffffff
