# Goxel 0.10.4
# One line per voxel
# X Y Z RRGGBB
-2 -4 0 ffffff
-1 -4 0 ffffff
-3 -3 0 ffffff
-2 -3 0 ffffff
-1 -3 0 ffffff
-3 -2 0 ffffff
-2 -2 0 ffffff
-1 -2 0 ffffff
-3 -1 0 ffffff
-2 -1 0 ffffff
-1 -1 0 ffffff
-2 -7 1 ffffff
-1 -7 1 ffffff
-4 -6 1 ffffff
-3 -6 1 ffffff
-2 -6 1 ffffff
-1 -6 1 ffffff
-5 -5 1 ffffff
-4 -5 1 ffffff
-3 -5 1 ffffff
-2 -5 1 ffffff
-1 -5 1 ffffff
-5 -4 1 ffffff
-4 -4 1 ffffff
-3 -4 1 ffffff
-2 -4 1 ffffff
-1 -4 1 ffffff
-6 -3 1 ffffff
-5 -3 1 ffffff
-4 -3 1 ffffff
-3 -3 1 ffffff
-2 -3 1 ffffff
-1 -3 1 ffffff
-6 -2 1 ffffff
-5 -2 1 ffffff
-4 -2 1 ffffff
-3 -2 1 ffffff
-2 -2 1 ffffff
-1 -2 1 ffffff
-6 -1 1 ffffff
-5 -1 1 ffffff
-4 -1 1 ffffff
-3 -1 1 ffffff
-2 -1 1 ffffff
-1 -1 1 ffffff
-2 -9 2 ffffff
-1 -9 2 ffffff
-4 -8 2 ffffff
-3 -8 2 ffffff
-2 -8 2 ffffff
-1 -8 2 ffffff
-5 -7 2 ffffff
-4 -7 2 ffffff
-3 -7 2 ffffff
-2 -7 2 ffffff
-1 -7 2 ffffff
-6 -6 2 ffffff
-5 -6 2 ffffff
-4 -6 2 ffffff
-3 -6 2 ffffff
-2 -6 2 ffffff
-1 -6 2 ffffff
-7 -5 2 ffffff
-6 -5 2 ffffff
-5 -5 2 ffffff
-4 -5 2 ffffff
-3 -5 2 ffffff
-2 -5 2 ffffff
-1 -5 2 ffffff
-7 -4 2 ffffff
-6 -4 2 ffffff
-5 -4 2 ffffff
-4 -4 2 ffffff
-3 -4 2 ffffff
-2 -4 2 ffffff
-1 -4 2 ffffff
-8 -3 2 ffffff
-7 -3 2 ffffff
-6 -3 2 ffffff
-5 -3 2 ffffff
-4 -3 2 ffffff
-3 -3 2 ffffff
-2 -3 2 ffffff
-1 -3 2 ffffff
-8 -2 2 ffffff
-7 -2 2 ffffff
-6 -2 2 ffffff
-5 -2 2 ffffff
-4 -2 2 ffffff
-3 -2 2 ffffff
-2 -2 2 ffffff
-1 -2 2 ffffff
-8 -1 2 ffffff
-7 -1 2 ffffff
-6 -1 2 ffffff
-5 -1 2 ffffff
-4 -1 2 ffffff
-3 -1 2 ffffff
-2 -1 2 ffffff
-1 -1 2 ffffff
-3 -10 3 ffffff
-2 -10 3 ffffff
-1 -10 3 ffffff
-5 -9 3 ffffff
-4 -9 3 ffffff
-3 -9 3 ffffff
-2 -9 3 ffffff
-1 -9 3 ffffff
-6 -8 3 ffffff
-5 -8 3 ffffff
-4 -8 3 ffffff
-3 -8 3 ffffff
-2 -8 3 ffffff
-1 -8 3 ffffff
-7 -7 3 ffffff
-6 -7 3 ffffff
-5 -7 3 ffffff
-4 -7 3 ffffff
-3 -7 3 ffffff
-2 -7 3 ffffff
-1 -7 3 ffffff
-8 -6 3 ffffff
-7 -6 3 ffffff
-6 -6 3 ffffff
-5 -6 3 ffffff
-4 -6 3 ffffff
-3 -6 3 ffffff
-2 -6 3 ffffff
-1 -6 3 ffffff
-8 -5 3 ffffff
-7 -5 3 ffffff
-6 -5 3 ffffff
-5 -5 3 ffffff
-4 -5 3 ffffff
-3 -5 3 ffffff
-2 -5 3 ffffff
-1 -5 3 ffffff
-9 -4 3 ffffff
-8 -4 3 ffffff
-7 -4 3 ffffff
-6 -4 3 ffffff
-5 -4 3 ffffff
-4 -4 3 ffffff
-3 -4 3 ffffff
-2 -4 3 ffffff
-1 -4 3 ffffff
-9 -3 3 ffffff
-8 -3 3 ffffff
-7 -3 3 ffffff
-6 -3 3 ffffff
-5 -3 3 ffffff
-4 -3 3 ffffff
-3 -3 3 ffffff
-2 -3 3 ffffff
-1 -3 3 ffffff
-9 -2 3 ffffff
-8 -2 3 ffffff
-7 -2 3 ffffff
-6 -2 3 ffffff
-5 -2 3 ffffff
-4 -2 3 ffffff
-3 -2 3 ffffff
-2 -2 3 ffffff
-1 -2 3 ffffff
-9 -1 3 ffffff
-8 -1 3 ffffff
-7 -1 3 ffffff
-6 -1 3 ffffff
-5 -1 3 ffffff
-4 -1 3 ffffff
-3 -1 3 ffffff
-2 -1 3 ffffff
-1 -1 3 ffffff
-4 -11 4 ffffff
-3 -11 4 ffffff
-2 -11 4 ffffff
-1 -11 4 ffffff
-5 -10 4 ffffff
-4 -10 4 ffffff
-3 -10 4 ffffff
-2 -10 4 ffffff
-1 -10 4 ffffff
-7 -9 4 ffffff
-6 -9 4 ffffff
-5 -9 4 ffffff
-4 -9 4 ffffff
-3 -9 4 ffffff
-2 -9 4 ffffff
-1 -9 4 ffffff
-8 -8 4 ffffff
-7 -8 4 ffffff
-6 -8 4 ffffff
-5 -8 4 ffffff
-4 -8 4 ffffff
-3 -8 4 ffffff
-2 -8 4 ffffff
-1 -8 4 ffffff
-8 -7 4 ffffff
-7 -7 4 ffffff
-6 -7 4 ffffff
-5 -7 4 ffffff
-4 -7 4 ffffff
-3 -7 4 ffffff
-2 -7 4 ffffff
-1 -7 4 ffffff
-9 -6 4 ffffff
-8 -6 4 ffffff
-7 -6 4 ffffff
-6 -6 4 ffffff
-5 -6 4 ffffff
-4 -6 4 ffffff
-3 -6 4 ffffff
-2 -6 4 ffffff
-1 -6 4 ffffff
-10 -5 4 ffffff
-9 -5 4 ffffff
-8 -5 4 ffffff
-7 -5 4 ffffff
-6 -5 4 ffffff
-5 -5 4 ffffff
-4 -5 4 ffffff
-3 -5 4 ffffff
-2 -5 4 ffffff
-1 -5 4 ffffff
-10 -4 4 ffffff
-9 -4 4 ffffff
-8 -4 4 ffffff
-7 -4 4 ffffff
-6 -4 4 ffffff
-5 -4 4 ffffff
-4 -4 4 ffffff
-3 -4 4 ffffff
-2 -4 4 ffffff
-1 -4 4 ffffff
-10 -3 4 ffffff
-9 -3 4 ffffff
-8 -3 4 ffffff
-7 -3 4 ffffff
-6 -3 4 ffffff
-5 -3 4 ffffff
-4 -3 4 ffffff
-3 -3 4 ffffff
-2 -3 4 ffffff
-1 -3 4 ffffff
-10 -2 4 ffffff
-9 -2 4 ffffff
-8 -2 4 ffffff
-7 -2 4 ffffff
-6 -2 4 ffffff
-5 -2 4 ffffff
-4 -2 4 ffffff
-3 -2 4 ffffff
-2 -2 4 ffffff
-1 -2 4 ffffff
-10 -1 4 ffffff
-9 -1 4 ffffff
-8 -1 4 ffffff
-7 -1 4 ffffff
-6 -1 4 ffffff
-5 -1 4 ffffff
-4 -1 4 ffffff
-3 -1 4 ffffff
-2 -1 4 ffffff
-1 -1 4 ffffff
-3 -12 5 ffffff
-2 -12 5 ffffff
-1 -12 5 ffffff
-6 -11 5 ffffff
-5 -11 5 ffffff
-4 -11 5 ffffff
-3 -11 5 ffffff
-2 -11 5 ffffff
-1 -11 5 ffffff
-7 -10 5 ffffff
-6 -10 5 ffffff
-5 -10 5 ffffff
-4 -10 5 ffffff
-3 -10 5 ffffff
-2 -10 5 ffffff
-1 -10 5 ffffff
-8 -9 5 ffffff
-7 -9 5 ffffff
-6 -9 5 ffffff
-5 -9 5 ffffff
-4 -9 5 ffffff
-3 -9 5 ffffff
-2 -9 5 ffffff
-1 -9 5 ffffff
-9 -8 5 ffffff
-8 -8 5 ffffff
-7 -8 5 ffffff
-6 -8 5 ffffff
-5 -8 5 ffffff
-4 -8 5 ffffff
-3 -8 5 ffffff
-2 -8 5 ffffff
-1 -8 5 ffffff
-10 -7 5 ffffff
-9 -7 5 ffffff
-8 -7 5 ffffff
-7 -7 5 ffffff
-6 -7 5 ffffff
-5 -7 5 ffffff
-4 -7 5 ffffff
-3 -7 5 ffffff
-2 -7 5 ffffff
-1 -7 5 ffffff
-10 -6 5 ffffff
-9 -6 5 ffffff
-8 -6 5 ffffff
-7 -6 5 ffffff
-6 -6 5 ffffff
-5 -6 5 ffffff
-4 -6 5 ffffff
-3 -6 5 ffffff
-2 -6 5 ffffff
-1 -6 5 ffffff
-10 -5 5 ffffff
-9 -5 5 ffffff
-8 -5 5 ffffff
-7 -5 5 ffffff
-6 -5 5 ffffff
-5 -5 5 ffffff
-4 -5 5 ffffff
-3 -5 5 ffffff
-2 -5 5 ffffff
-1 -5 5 ffffff
-11 -4 5 ffffff
-10 -4 5 ffffff
-9 -4 5 ffffff
-8 -4 5 ffffff
-7 -4 5 ffffff
-6 -4 5 ffffff
-5 -4 5 ffffff
-4 -4 5 ffffff
-3 -4 5 ffffff
-2 -4 5 ffffff
-1 -4 5 ffffff
-11 -3 5 ffffff
-10 -3 5 ffffff
-9 -3 5 ffffff
-8 -3 5 ffffff
-7 -3 5 ffffff
-6 -3 5 ffffff
-5 -3 5 ffffff
-4 -3 5 ffffff
-3 -3 5 ffffff
-2 -3 5 ffffff
-1 -3 5 ffffff
-11 -2 5 ffffff
-10 -2 5 ffffff
-9 -2 5 ffffff
-8 -2 5 ffffff
-7 -2 5 ffffff
-6 -2 5 ffffff
-5 -2 5 ffffff
-4 -2 5 ffffff
-3 -2 5 ffffff
-2 -2 5 ffffff
-1 -2 5 ffffff
-11 -1 5 ffffff
-10 -1 5 ffffff
-9 -1 5 ffffff
-8 -1 5 ffffff
-7 -1 5 ffffff
-6 -1 5 ffffff
-5 -1 5 ffffff
-4 -1 5 ffffff
-3 -1 5 ffffff
-2 -1 5 ffffff
-1 -1 5 ffffff
-3 -13 6 ffffff
-2 -13 6 ffffff
-1 -13 6 ffffff
-5 -12 6 ffffff
-4 -12 6 ffffff
-3 -12 6 ffffff
-2 -12 6 ffffff
-1 -12 6 ffffff
-7 -11 6 ffffff
-6 -11 6 ffffff
-5 -11 6 ffffff
-4 -11 6 ffffff
-3 -11 6 ffffff
-2 -11 6 ffffff
-1 -11 6 ffffff
-8 -10 6 ffffff
-7 -10 6 ffffff
-6 -10 6 ffffff
-5 -10 6 ffffff
-4 -10 6 ffffff
-3 -10 6 ffffff
-2 -10 6 ffffff
-1 -10 6 ffffff
-9 -9 6 ffffff
-8 -9 6 ffffff
-7 -9 6 ffffff
-6 -9 6 ffffff
-5 -9 6 ffffff
-4 -9 6 ffffff
-3 -9 6 ffffff
-2 -9 6 ffffff
-1 -9 6 ffffff
-10 -8 6 ffffff
-9 -8 6 ffffff
-8 -8 6 ffffff
-7 -8 6 ffffff
-6 -8 6 ffffff
-5 -8 6 ffffff
-4 -8 6 ffffff
-3 -8 6 ffffff
-2 -8 6 ffffff
-1 -8 6 ffffff
-10 -7 6 ffffff
-9 -7 6 ffffff
-8 -7 6 ffffff
-7 -7 6 ffffff
-6 -7 6 ffffff
-5 -7 6 ffffff
-4 -7 6 ffffff
-3 -7 6 ffffff
-2 -7 6 ffffff
-1 -7 6 ffffff
-11 -6 6 ffffff
-10 -6 6 ffffff
-9 -6 6 ffffff
-8 -6 6 ffffff
-7 -6 6 ffffff
-6 -6 6 ffffff
-5 -6 6 ffffff
-4 -6 6 ffffff
-3 -6 6 ffffff
-2 -6 6 ffffff
-1 -6 6 ffffff
-11 -5 6 ffffff
-10 -5 6 ffffff
-9 -5 6 ffffff
-8 -5 6 ffffff
-7 -5 6 ffffff
-6 -5 6 ffffff
-5 -5 6 ffffff
-4 -5 6 ffffff
-3 -5 6 ffffff
-2 -5 6 ffffff
-1 -5 6 ffffff
-12 -4 6 ffffff
-11 -4 6 ffffff
-10 -4 6 ffffff
-9 -4 6 ffffff
-8 -4 6 ffffff
-7 -4 6 ffffff
-6 -4 6 ffffff
-5 -4 6 ffffff
-4 -4 6 ffffff
-3 -4 6 ffffff
-2 -4 6 ffffff
-1 -4 6 ffffff
-12 -3 6 ffffff
-11 -3 6 ffffff
-10 -3 6 ffffff
-9 -3 6 ffffff
-8 -3 6 ffffff
-7 -3 6 ffffff
-6 -3 6 ffffff
-5 -3 6 ffffff
-4 -3 6 ffffff
-3 -3 6 ffffff
-2 -3 6 ffffff
-1 -3 6 ffffff
-12 -2 6 ffffff
-11 -2 6 ffffff
-10 -2 6 ffffff
-9 -2 6 ffffff
-8 -2 6 ffffff
-7 -2 6 ffffff
-6 -2 6 ffffff
-5 -2 6 ffffff
-4 -2 6 ffffff
-3 -2 6 ffffff
-2 -2 6 ffffff
-1 -2 6 ffffff
-12 -1 6 ffffff
-11 -1 6 ffffff
-10 -1 6 ffffff
-9 -1 6 ffffff
-8 -1 6 ffffff
-7 -1 6 ffffff
-6 -1 6 ffffff
-5 -1 6 ffffff
-4 -1 6 ffffff
-3 -1 6 ffffff
-2 -1 6 ffffff
-1 -1 6 ffffff
-1 -14 7 ffffff
-5 -13 7 ffffff
-4 -13 7 ffffff
-3 -13 7 ffffff
-2 -13 7 ffffff
-1 -13 7 ffffff
-7 -12 7 ffffff
-6 -12 7 ffffff
-5 -12 7 ffffff
-4 -12 7 ffffff
-3 -12 7 ffffff
-2 -12 7 ffffff
-1 -12 7 ffffff
-8 -11 7 ffffff
-7 -11 7 ffffff
-6 -11 7 ffffff
-5 -11 7 ffffff
-4 -11 7 ffffff
-3 -11 7 ffffff
-2 -11 7 ffffff
-1 -11 7 ffffff
-9 -10 7 ffffff
-8 -10 7 ffffff
-7 -10 7 ffffff
-6 -10 7 ffffff
-5 -10 7 ffffff
-4 -10 7 ffffff
-3 -10 7 ffffff
-2 -10 7 ffffff
-1 -10 7 ffffff
-10 -9 7 ffffff
-9 -9 7 ffffff
-8 -9 7 ffffff
-7 -9 7 ffffff
-6 -9 7 ffffff
-5 -9 7 ffffff
-4 -9 7 ffffff
-3 -9 7 ffffff
-2 -9 7 ffffff
-1 -9 7 ffffff
-11 -8 7 ffffff
-10 -8 7 ffffff
-9 -8 7 ffffff
-8 -8 7 ffffff
-7 -8 7 ffffff
-6 -8 7 ffffff
-5 -8 7 ffffff
-4 -8 7 ffffff
-3 -8 7 ffffff
-2 -8 7 ffffff
-1 -8 7 ffffff
-11 -7 7 ffffff
-10 -7 7 ffffff
-9 -7 7 ffffff
-8 -7 7 ffffff
-7 -7 7 ffffff
-6 -7 7 ffffff
-5 -7 7 ffffff
-4 -7 7 ffffff
-3 -7 7 ffffff
-2 -7 7 ffffff
-1 -7 7 ffffff
-12 -6 7 ffffff
-11 -6 7 ffffff
-10 -6 7 ffffff
-9 -6 7 ffffff
-8 -6 7 ffffff
-7 -6 7 ffffff
-6 -6 7 ffffff
-5 -6 7 ffffff
-4 -6 7 ffffff
-3 -6 7 ffffff
-2 -6 7 ffffff
-1 -6 7 ffffff
-12 -5 7 ffffff
-11 -5 7 ffffff
-10 -5 7 ffffff
-9 -5 7 ffffff
-8 -5 7 ffffff
-7 -5 7 ffffff
-6 -5 7 ffffff
-5 -5 7 ffffff
-4 -5 7 ffffff
-3 -5 7 ffffff
-2 -5 7 ffffff
-1 -5 7 ffffff
-12 -4 7 ffffff
-11 -4 7 ffffff
-10 -4 7 ffffff
-9 -4 7 ffffff
-8 -4 7 ffffff
-7 -4 7 ffffff
-6 -4 7 ffffff
-5 -4 7 ffffff
-4 -4 7 ffffff
-3 -4 7 ffffff
-2 -4 7 ffffff
-1 -4 7 ffffff
-12 -3 7 ffffff
-11 -3 7 ffffff
-10 -3 7 ffffff
-9 -3 7 ffffff
-8 -3 7 ffffff
-7 -3 7 ffffff
-6 -3 7 ffffff
-5 -3 7 ffffff
-4 -3 7 ffffff
-3 -3 7 ffffff
-2 -3 7 ffffff
-1 -3 7 ffffff
-13 -2 7 ffffff
-12 -2 7 ffffff
-11 -2 7 ffffff
-10 -2 7 ffffff
-9 -2 7 ffffff
-8 -2 7 ffffff
-7 -2 7 ffffff
-6 -2 7 ffffff
-5 -2 7 ffffff
-4 -2 7 ffffff
-3 -2 7 ffffff
-2 -2 7 ffffff
-1 -2 7 ffffff
-13 -1 7 ffffff
-12 -1 7 ffffff
-11 -1 7 ffffff
-10 -1 7 ffffff
-9 -1 7 ffffff
-8 -1 7 ffffff
-7 -1 7 ffffff
-6 -1 7 ffffff
-5 -1 7 ffffff
-4 -1 7 ffffff
-3 -1 7 ffffff
-2 -1 7 ffffff
-1 -1 7 ffffff
-4 -14 8 ffffff
-3 -14 8 ffffff
-2 -14 8 ffffff
-1 -14 8 ffffff
-6 -13 8 ffffff
-5 -13 8 ffffff
-4 -13 8 ffffff
-3 -13 8 ffffff
-2 -13 8 ffffff
-1 -13 8 ffffff
-8 -12 8 ffffff
-7 -12 8 ffffff
-6 -12 8 ffffff
-5 -12 8 ffffff
-4 -12 8 ffffff
-3 -12 8 ffffff
-2 -12 8 ffffff
-1 -12 8 ffffff
-9 -11 8 ffffff
-8 -11 8 ffffff
-7 -11 8 ffffff
-6 -11 8 ffffff
-5 -11 8 ffffff
-4 -11 8 ffffff
-3 -11 8 ffffff
-2 -11 8 ffffff
-1 -11 8 ffffff
-10 -10 8 ffffff
-9 -10 8 ffffff
-8 -10 8 ffffff
-7 -10 8 ffffff
-6 -10 8 ffffff
-5 -10 8 ffffff
-4 -10 8 ffffff
-3 -10 8 ffffff
-2 -10 8 ffffff
-1 -10 8 ffffff
-11 -9 8 ffffff
-10 -9 8 ffffff
-9 -9 8 ffffff
-8 -9 8 ffffff
-7 -9 8 ffffff
-6 -9 8 ffffff
-5 -9 8 ffffff
-4 -9 8 ffffff
-3 -9 8 ffffff
-2 -9 8 ffffff
-1 -9 8 ffffff
-11 -8 8 ffffff
-10 -8 8 ffffff
-9 -8 8 ffffff
-8 -8 8 ffffff
-7 -8 8 ffffff
-6 -8 8 ffffff
-5 -8 8 ffffff
-4 -8 8 ffffff
-3 -8 8 ffffff
-2 -8 8 ffffff
-1 -8 8 ffffff
-12 -7 8 ffffff
-11 -7 8 ffffff
-10 -7 8 ffffff
-9 -7 8 ffffff
-8 -7 8 ffffff
-7 -7 8 ffffff
-6 -7 8 ffffff
-5 -7 8 ffffff
-4 -7 8 ffffff
-3 -7 8 ffffff
-2 -7 8 ffffff
-1 -7 8 ffffff
-12 -6 8 ffffff
-11 -6 8 ffffff
-10 -6 8 ffffff
-9 -6 8 ffffff
-8 -6 8 ffffff
-7 -6 8 ffffff
-6 -6 8 ffffff
-5 -6 8 ffffff
-4 -6 8 ffffff
-3 -6 8 ffffff
-2 -6 8 ffffff
-1 -6 8 ffffff
-13 -5 8 ffffff
-12 -5 8 ffffff
-11 -5 8 ffffff
-10 -5 8 ffffff
-9 -5 8 ffffff
-8 -5 8 ffffff
-7 -5 8 ffffff
-6 -5 8 ffffff
-5 -5 8 ffffff
-4 -5 8 ffffff
-3 -5 8 ffffff
-2 -5 8 ffffff
-1 -5 8 ffffff
-13 -4 8 ffffff
-12 -4 8 ffffff
-11 -4 8 ffffff
-10 -4 8 ffffff
-9 -4 8 ffffff
-8 -4 8 ffffff
-7 -4 8 ffffff
-6 -4 8 ffffff
-5 -4 8 ffffff
-4 -4 8 ffffff
-3 -4 8 ffffff
-2 -4 8 ffffff
-1 -4 8 ffffff
-13 -3 8 ffffff
-12 -3 8 ffffff
-11 -3 8 ffffff
-10 -3 8 ffffff
-9 -3 8 ffffff
-8 -3 8 ffffff
-7 -3 8 ffffff
-6 -3 8 ffffff
-5 -3 8 ffffff
-4 -3 8 ffffff
-3 -3 8 ffffff
-2 -3 8 ffffff
-1 -3 8 ffffff
-13 -2 8 ffffff
-12 -2 8 ffffff
-11 -2 8 ffffff
-10 -2 8 ffffff
-9 -2 8 ffffff
-8 -2 8 ffffff
-7 -2 8 ffffff
-6 -2 8 ffffff
-5 -2 8 ffffff
-4 -2 8 ffffff
-3 -2 8 ffffff
-2 -2 8 ffffff
-1 -2 8 ffffff
-13 -1 8 ffffff
-12 -1 8 ffffff
-11 -1 8 ffffff
-10 -1 8 ffffff
-9 -1 8 ffffff
-8 -1 8 ffffff
-7 -1 8 ffffff
-6 -1 8 ffffff
-5 -1 8 ffffff
-4 -1 8 ffffff
-3 -1 8 ffffff
-2 -1 8 ffffff
-1 -1 8 ffffff
-2 -15 9 ffffff
-1 -15 9 ffffff
-5 -14 9 ffffff
-4 -14 9 ffffff
-3 -14 9 ffffff
-2 -14 9 ffffff
-1 -14 9 ffffff
-7 -13 9 ffffff
-6 -13 9 ffffff
-5 -13 9 ffffff
-4 -13 9 ffffff
-3 -13 9 ffffff
-2 -13 9 ffffff
-1 -13 9 ffffff
-8 -12 9 ffffff
-7 -12 9 ffffff
-6 -12 9 ffffff
-5 -12 9 ffffff
-4 -12 9 ffffff
-3 -12 9 ffffff
-2 -12 9 ffffff
-1 -12 9 ffffff
-10 -11 9 ffffff
-9 -11 9 ffffff
-8 -11 9 ffffff
-7 -11 9 ffffff
-6 -11 9 ffffff
-5 -11 9 ffffff
-4 -11 9 ffffff
-3 -11 9 ffffff
-2 -11 9 ffffff
-1 -11 9 ffffff
-10 -10 9 ffffff
-9 -10 9 ffffff
-8 -10 9 ffffff
-7 -10 9 ffffff
-6 -10 9 ffffff
-5 -10 9 ffffff
-4 -10 9 ffffff
-3 -10 9 ffffff
-2 -10 9 ffffff
-1 -10 9 ffffff
-11 -9 9 ffffff
-10 -9 9 ffffff
-9 -9 9 ffffff
-8 -9 9 ffffff
-7 -9 9 ffffff
-6 -9 9 ffffff
-5 -9 9 ffffff
-4 -9 9 ffffff
-3 -9 9 ffffff
-2 -9 9 ffffff
-1 -9 9 ffffff
-12 -8 9 ffffff
-11 -8 9 ffffff
-10 -8 9 ffffff
-9 -8 9 ffffff
-8 -8 9 ffffff
-7 -8 9 ffffff
-6 -8 9 ffffff
-5 -8 9 ffffff
-4 -8 9 ffffff
-3 -8 9 ffffff
-2 -8 9 ffffff
-1 -8 9 ffffff
-12 -7 9 ffffff
-11 -7 9 ffffff
-10 -7 9 ffffff
-9 -7 9 ffffff
-8 -7 9 ffffff
-7 -7 9 ffffff
-6 -7 9 ffffff
-5 -7 9 ffffff
-4 -7 9 ffffff
-3 -7 9 ffffff
-2 -7 9 ffffff
-1 -7 9 ffffff
-13 -6 9 ffffff
-12 -6 9 ffffff
-11 -6 9 ffffff
-10 -6 9 ffffff
-9 -6 9 ffffff
-8 -6 9 ffffff
-7 -6 9 ffffff
-6 -6 9 ffffff
-5 -6 9 ffffff
-4 -6 9 ffffff
-3 -6 9 ffffff
-2 -6 9 ffffff
-1 -6 9 ffffff
-13 -5 9 ffffff
-12 -5 9 ffffff
-11 -5 9 ffffff
-10 -5 9 ffffff
-9 -5 9 ffffff
-8 -5 9 ffffff
-7 -5 9 ffffff
-6 -5 9 ffffff
-5 -5 9 ffffff
-4 -5 9 ffffff
-3 -5 9 ffffff
-2 -5 9 ffffff
-1 -5 9 ffffff
-13 -4 9 ffffff
-12 -4 9 ffffff
-11 -4 9 ffffff
-10 -4 9 ffffff
-9 -4 9 ffffff
-8 -4 9 ffffff
-7 -4 9 ffffff
-6 -4 9 ffffff
-5 -4 9 ffffff
-4 -4 9 ffffff
-3 -4 9 ffffff
-2 -4 9 ffffff
-1 -4 9 ffffff
-14 -3 9 ffffff
-13 -3 9 ffffff
-12 -3 9 ffffff
-11 -3 9 ffffff
-10 -3 9 ffffff
-9 -3 9 ffffff
-8 -3 9 ffffff
-7 -3 9 ffffff
-6 -3 9 ffffff
-5 -3 9 ffffff
-4 -3 9 ffffff
-3 -3 9 ffffff
-2 -3 9 ffffff
-1 -3 9 ffffff
-14 -2 9 ffffff
-13 -2 9 ffffff
-12 -2 9 ffffff
-11 -2 9 ffffff
-10 -2 9 ffffff
-9 -2 9 ffffff
-8 -2 9 ffffff
-7 -2 9 ffffff
-6 -2 9 ffffff
-5 -2 9 ffffff
-4 -2 9 ffffff
-3 -2 9 ffffff
-2 -2 9 ffffff
-1 -2 9 ffffff
-14 -1 9 ffffff
-13 -1 9 ffffff
-12 -1 9 ffffff
-11 -1 9 ffffff
-10 -1 9 ffffff
-9 -1 9 ffffff
-8 -1 9 ffffff
-7 -1 9 ffffff
-6 -1 9 ffffff
-5 -1 9 ffffff
-4 -1 9 ffffff
-3 -1 9 ffffff
-2 -1 9 ffffff
-1 -1 9 ffffff
-3 -15 10 ffffff
-2 -15 10 ffffff
-1 -15 10 ffffff
-6 -14 10 ffffff
-5 -14 10 ffffff
-4 -14 10 ffffff
-3 -14 10 ffffff
-2 -14 10 ffffff
-1 -14 10 ffffff
-8 -13 10 ffffff
-7 -13 10 ffffff
-6 -13 10 ffffff
-5 -13 10 ffffff
-4 -13 10 ffffff
-3 -13 10 ffffff
-2 -13 10 ffffff
-1 -13 10 ffffff
-9 -12 10 ffffff
-8 -12 10 ffffff
-7 -12 10 ffffff
-6 -12 10 ffffff
-5 -12 10 ffffff
-4 -12 10 ffffff
-3 -12 10 ffffff
-2 -12 10 ffffff
-1 -12 10 ffffff
-10 -11 10 ffffff
-9 -11 10 ffffff
-8 -11 10 ffffff
-7 -11 10 ffffff
-6 -11 10 ffffff
-5 -11 10 ffffff
-4 -11 10 ffffff
-3 -11 10 ffffff
-2 -11 10 ffffff
-1 -11 10 ffffff
-11 -10 10 ffffff
-10 -10 10 ffffff
-9 -10 10 ffffff
-8 -10 10 ffffff
-7 -10 10 ffffff
-6 -10 10 ffffff
-5 -10 10 ffffff
-4 -10 10 ffffff
-3 -10 10 ffffff
-2 -10 10 ffffff
-1 -10 10 ffffff
-12 -9 10 ffffff
-11 -9 10 ffffff
-10 -9 10 ffffff
-9 -9 10 ffffff
-8 -9 10 ffffff
-7 -9 10 ffffff
-6 -9 10 ffffff
-5 -9 10 ffffff
-4 -9 10 ffffff
-3 -9 10 ffffff
-2 -9 10 ffffff
-1 -9 10 ffffff
-12 -8 10 ffffff
-11 -8 10 ffffff
-10 -8 10 ffffff
-9 -8 10 ffffff
-8 -8 10 ffffff
-7 -8 10 ffffff
-6 -8 10 ffffff
-5 -8 10 ffffff
-4 -8 10 ffffff
-3 -8 10 ffffff
-2 -8 10 ffffff
-1 -8 10 ffffff
-13 -7 10 ffffff
-12 -7 10 ffffff
-11 -7 10 ffffff
-10 -7 10 ffffff
-9 -7 10 ffffff
-8 -7 10 ffffff
-7 -7 10 ffffff
-6 -7 10 ffffff
-5 -7 10 ffffff
-4 -7 10 ffffff
-3 -7 10 ffffff
-2 -7 10 ffffff
-1 -7 10 ffffff
-13 -6 10 ffffff
-12 -6 10 ffffff
-11 -6 10 ffffff
-10 -6 10 ffffff
-9 -6 10 ffffff
-8 -6 10 ffffff
-7 -6 10 ffffff
-6 -6 10 ffffff
-5 -6 10 ffffff
-4 -6 10 ffffff
-3 -6 10 ffffff
-2 -6 10 ffffff
-1 -6 10 ffffff
-13 -5 10 ffffff
-12 -5 10 ffffff
-11 -5 10 ffffff
-10 -5 10 ffffff
-9 -5 10 ffffff
-8 -5 10 ffffff
-7 -5 10 ffffff
-6 -5 10 ffffff
-5 -5 10 ffffff
-4 -5 10 ffffff
-3 -5 10 ffffff
-2 -5 10 ffffff
-1 -5 10 ffffff
-14 -4 10 ffffff
-13 -4 10 ffffff
-12 -4 10 ffffff
-11 -4 10 ffffff
-10 -4 10 ffffff
-9 -4 10 ffffff
-8 -4 10 ffffff
-7 -4 10 ffffff
-6 -4 10 ffffff
-5 -4 10 ffffff
-4 -4 10 ffffff
-3 -4 10 ffffff
-2 -4 10 ffffff
-1 -4 10 ffffff
-14 -3 10 ffffff
-13 -3 10 ffffff
-12 -3 10 ffffff
-11 -3 10 ffffff
-10 -3 10 ffffff
-9 -3 10 ffffff
-8 -3 10 ffffff
-7 -3 10 ffffff
-6 -3 10 ffffff
-5 -3 10 ffffff
-4 -3 10 ffffff
-3 -3 10 ffffff
-2 -3 10 ffffff
-1 -3 10 ffffff
-14 -2 10 ffffff
-13 -2 10 ffffff
-12 -2 10 ffffff
-11 -2 10 ffffff
-10 -2 10 ffffff
-9 -2 10 ffffff
-8 -2 10 ffffff
-7 -2 10 ffffff
-6 -2 10 ffffff
-5 -2 10 ffffff
-4 -2 10 ffffff
-3 -2 10 ffffff
-2 -2 10 ffffff
-1 -2 10 ffffff
-14 -1 10 ffffff
-13 -1 10 ffffff
-12 -1 10 ffffff
-11 -1 10 ffffff
-10 -1 10 ffffff
-9 -1 10 ffffff
-8 -1 10 ffffff
-7 -1 10 ffffff
-6 -1 10 ffffff
-5 -1 10 ffffff
-4 -1 10 ffffff
-3 -1 10 ffffff
-2 -1 10 ffffff
-1 -1 10 ffffff
-5 -15 11 ffffff
-4 -15 11 ffffff
-3 -15 11 ffffff
-2 -15 11 ffffff
-1 -15 11 ffffff
-7 -14 11 ffffff
-6 -14 11 ffffff
-5 -14 11 ffffff
-4 -14 11 ffffff
-3 -14 11 ffffff
-2 -14 11 ffffff
-1 -14 11 ffffff
-8 -13 11 ffffff
-7 -13 11 ffffff
-6 -13 11 ffffff
-5 -13 11 ffffff
-4 -13 11 ffffff
-3 -13 11 ffffff
-2 -13 11 ffffff
-1 -13 11 ffffff
-10 -12 11 ffffff
-9 -12 11 ffffff
-8 -12 11 ffffff
-7 -12 11 ffffff
-6 -12 11 ffffff
-5 -12 11 ffffff
-4 -12 11 ffffff
-3 -12 11 ffffff
-2 -12 11 ffffff
-1 -12 11 ffffff
-11 -11 11 ffffff
-10 -11 11 ffffff
-9 -11 11 ffffff
-8 -11 11 ffffff
-7 -11 11 ffffff
-6 -11 11 ffffff
-5 -11 11 ffffff
-4 -11 11 ffffff
-3 -11 11 ffffff
-2 -11 11 ffffff
-1 -11 11 ffffff
-11 -10 11 ffffff
-10 -10 11 ffffff
-9 -10 11 ffffff
-8 -10 11 ffffff
-7 -10 11 ffffff
-6 -10 11 ffffff
-5 -10 11 ffffff
-4 -10 11 ffffff
-3 -10 11 ffffff
-2 -10 11 ffffff
-1 -10 11 ffffff
-12 -9 11 ffffff
-11 -9 11 ffffff
-10 -9 11 ffffff
-9 -9 11 ffffff
-8 -9 11 ffffff
-7 -9 11 ffffff
-6 -9 11 ffffff
-5 -9 11 ffffff
-4 -9 11 ffffff
-3 -9 11 ffffff
-2 -9 11 ffffff
-1 -9 11 ffffff
-13 -8 11 ffffff
-12 -8 11 ffffff
-11 -8 11 ffffff
-10 -8 11 ffffff
-9 -8 11 ffffff
-8 -8 11 ffffff
-7 -8 11 ffffff
-6 -8 11 ffffff
-5 -8 11 ffffff
-4 -8 11 ffffff
-3 -8 11 ffffff
-2 -8 11 ffffff
-1 -8 11 ffffff
-13 -7 11 ffffff
-12 -7 11 ffffff
-11 -7 11 ffffff
-10 -7 11 ffffff
-9 -7 11 ffffff
-8 -7 11 ffffff
-7 -7 11 ffffff
-6 -7 11 ffffff
-5 -7 11 ffffff
-4 -7 11 ffffff
-3 -7 11 ffffff
-2 -7 11 ffffff
-1 -7 11 ffffff
-14 -6 11 ffffff
-13 -6 11 ffffff
-12 -6 11 ffffff
-11 -6 11 ffffff
-10 -6 11 ffffff
-9 -6 11 ffffff
-8 -6 11 ffffff
-7 -6 11 ffffff
-6 -6 11 ffffff
-5 -6 11 ffffff
-4 -6 11 ffffff
-3 -6 11 ffffff
-2 -6 11 ffffff
-1 -6 11 ffffff
-14 -5 11 ffffff
-13 -5 11 ffffff
-12 -5 11 ffffff
-11 -5 11 ffffff
-10 -5 11 ffffff
-9 -5 11 ffffff
-8 -5 11 ffffff
-7 -5 11 ffffff
-6 -5 11 ffffff
-5 -5 11 ffffff
-4 -5 11 ffffff
-3 -5 11 ffffff
-2 -5 11 ffffff
-1 -5 11 ffffff
-14 -4 11 ffffff
-13 -4 11 ffffff
-12 -4 11 ffffff
-11 -4 11 ffffff
-10 -4 11 ffffff
-9 -4 11 ffffff
-8 -4 11 ffffff
-7 -4 11 ffffff
-6 -4 11 ffffff
-5 -4 11 ffffff
-4 -4 11 ffffff
-3 -4 11 ffffff
-2 -4 11 ffffff
-1 -4 11 ffffff
-14 -3 11 ffffff
-13 -3 11 ffffff
-12 -3 11 ffffff
-11 -3 11 ffffff
-10 -3 11 ffffff
-9 -3 11 ffffff
-8 -3 11 ffffff
-7 -3 11 ffffff
-6 -3 11 ffffff
-5 -3 11 ffffff
-4 -3 11 ffffff
-3 -3 11 ffffff
-2 -3 11 ffffff
-1 -3 11 ffffff
-14 -2 11 ffffff
-13 -2 11 ffffff
-12 -2 11 ffffff
-11 -2 11 ffffff
-10 -2 11 ffffff
-9 -2 11 ffffff
-8 -2 11 ffffff
-7 -2 11 ffffff
-6 -2 11 ffffff
-5 -2 11 ffffff
-4 -2 11 ffffff
-3 -2 11 ffffff
-2 -2 11 ffffff
-1 -2 11 ffffff
-14 -1 11 ffffff
-13 -1 11 ffffff
-12 -1 11 ffffff
-11 -1 11 ffffff
-10 -1 11 ffffff
-9 -1 11 ffffff
-8 -1 11 ffffff
-7 -1 11 ffffff
-6 -1 11 ffffff
-5 -1 11 ffffff
-4 -1 11 ffffff
-3 -1 11 ffffff
-2 -1 11 ffffff
-1 -1 11 ffffff
-1 -16 12 ffffff
-5 -15 12 ffffff
-4 -15 12 ffffff
-3 -15 12 ffffff
-2 -15 12 ffffff
-1 -15 12 ffffff
-7 -14 12 ffffff
-6 -14 12 ffffff
-5 -14 12 ffffff
-4 -14 12 ffffff
-3 -14 12 ffffff
-2 -14 12 ffffff
-1 -14 12 ffffff
-9 -13 12 ffffff
-8 -13 12 ffffff
-7 -13 12 ffffff
-6 -13 12 ffffff
-5 -13 12 ffffff
-4 -13 12 ffffff
-3 -13 12 ffffff
-2 -13 12 ffffff
-1 -13 12 ffffff
-10 -12 12 ffffff
-9 -12 12 ffffff
-8 -12 12 ffffff
-7 -12 12 ffffff
-6 -12 12 ffffff
-5 -12 12 ffffff
-4 -12 12 ffffff
-3 -12 12 ffffff
-2 -12 12 ffffff
-1 -12 12 ffffff
-11 -11 12 ffffff
-10 -11 12 ffffff
-9 -11 12 ffffff
-8 -11 12 ffffff
-7 -11 12 ffffff
-6 -11 12 ffffff
-5 -11 12 ffffff
-4 -11 12 ffffff
-3 -11 12 ffffff
-2 -11 12 ffffff
-1 -11 12 ffffff
-12 -10 12 ffffff
-11 -10 12 ffffff
-10 -10 12 ffffff
-9 -10 12 ffffff
-8 -10 12 ffffff
-7 -10 12 ffffff
-6 -10 12 ffffff
-5 -10 12 ffffff
-4 -10 12 ffffff
-3 -10 12 ffffff
-2 -10 12 ffffff
-1 -10 12 ffffff
-12 -9 12 ffffff
-11 -9 12 ffffff
-10 -9 12 ffffff
-9 -9 12 ffffff
-8 -9 12 ffffff
-7 -9 12 ffffff
-6 -9 12 ffffff
-5 -9 12 ffffff
-4 -9 12 ffffff
-3 -9 12 ffffff
-2 -9 12 ffffff
-1 -9 12 ffffff
-13 -8 12 ffffff
-12 -8 12 ffffff
-11 -8 12 ffffff
-10 -8 12 ffffff
-9 -8 12 ffffff
-8 -8 12 ffffff
-7 -8 12 ffffff
-6 -8 12 ffffff
-5 -8 12 ffffff
-4 -8 12 ffffff
-3 -8 12 ffffff
-2 -8 12 ffffff
-1 -8 12 ffffff
-13 -7 12 ffffff
-12 -7 12 ffffff
-11 -7 12 ffffff
-10 -7 12 ffffff
-9 -7 12 ffffff
-8 -7 12 ffffff
-7 -7 12 ffffff
-6 -7 12 ffffff
-5 -7 12 ffffff
-4 -7 12 ffffff
-3 -7 12 ffffff
-2 -7 12 ffffff
-1 -7 12 ffffff
-14 -6 12 ffffff
-13 -6 12 ffffff
-12 -6 12 ffffff
-11 -6 12 ffffff
-10 -6 12 ffffff
-9 -6 12 ffffff
-8 -6 12 ffffff
-7 -6 12 ffffff
-6 -6 12 ffffff
-5 -6 12 ffffff
-4 -6 12 ffffff
-3 -6 12 ffffff
-2 -6 12 ffffff
-1 -6 12 ffffff
-14 -5 12 ffffff
-13 -5 12 ffffff
-12 -5 12 ffffff
-11 -5 12 ffffff
-10 -5 12 ffffff
-9 -5 12 ffffff
-8 -5 12 ffffff
-7 -5 12 ffffff
-6 -5 12 ffffff
-5 -5 12 ffffff
-4 -5 12 ffffff
-3 -5 12 ffffff
-2 -5 12 ffffff
-1 -5 12 ffffff
-14 -4 12 ffffff
-13 -4 12 ffffff
-12 -4 12 ffffff
-11 -4 12 ffffff
-10 -4 12 ffffff
-9 -4 12 ffffff
-8 -4 12 ffffff
-7 -4 12 ffffff
-6 -4 12 ffffff
-5 -4 12 ffffff
-4 -4 12 ffffff
-3 -4 12 ffffff
-2 -4 12 ffffff
-1 -4 12 ffffff
-14 -3 12 ffffff
-13 -3 12 ffffff
-12 -3 12 ffffff
-11 -3 12 ffffff
-10 -3 12 ffffff
-9 -3 12 ffffff
-8 -3 12 ffffff
-7 -3 12 ffffff
-6 -3 12 ffffff
-5 -3 12 ffffff
-4 -3 12 ffffff
-3 -3 12 ffffff
-2 -3 12 ffffff
-1 -3 12 ffffff
-15 -2 12 ffffff
-14 -2 12 ffffff
-13 -2 12 ffffff
-12 -2 12 ffffff
-11 -2 12 ffffff
-10 -2 12 ffffff
-9 -2 12 ffffff
-8 -2 12 ffffff
-7 -2 12 ffffff
-6 -2 12 ffffff
-5 -2 12 ffffff
-4 -2 12 ffffff
-3 -2 12 ffffff
-2 -2 12 ffffff
-1 -2 12 ffffff
-15 -1 12 ffffff
-14 -1 12 ffffff
-13 -1 12 ffffff
-12 -1 12 ffffff
-11 -1 12 ffffff
-10 -1 12 ffffff
-9 -1 12 ffffff
-8 -1 12 ffffff
-7 -1 12 ffffff
-6 -1 12 ffffff
-5 -1 12 ffffff
-4 -1 12 ffffff
-3 -1 12 ffffff
-2 -1 12 ffffff
-1 -1 12 ffffff
-3 -16 13 ffffff
-2 -16 13 ffffff
-1 -16 13 ffffff
-6 -15 13 ffffff
-5 -15 13 ffffff
-4 -15 13 ffffff
-3 -15 13 ffffff
-2 -15 13 ffffff
-1 -15 13 ffffff
-8 -14 13 ffffff
-7 -14 13 ffffff
-6 -14 13 ffffff
-5 -14 13 ffffff
-4 -14 13 ffffff
-3 -14 13 ffffff
-2 -14 13 ffffff
-1 -14 13 ffffff
-9 -13 13 ffffff
-8 -13 13 ffffff
-7 -13 13 ffffff
-6 -13 13 ffffff
-5 -13 13 ffffff
-4 -13 13 ffffff
-3 -13 13 ffffff
-2 -13 13 ffffff
-1 -13 13 ffffff
-10 -12 13 ffffff
-9 -12 13 ffffff
-8 -12 13 ffffff
-7 -12 13 ffffff
-6 -12 13 ffffff
-5 -12 13 ffffff
-4 -12 13 ffffff
-3 -12 13 ffffff
-2 -12 13 ffffff
-1 -12 13 ffffff
-11 -11 13 ffffff
-10 -11 13 ffffff
-9 -11 13 ffffff
-8 -11 13 ffffff
-7 -11 13 ffffff
-6 -11 13 ffffff
-5 -11 13 ffffff
-4 -11 13 ffffff
-3 -11 13 ffffff
-2 -11 13 ffffff
-1 -11 13 ffffff
-12 -10 13 ffffff
-11 -10 13 ffffff
-10 -10 13 ffffff
-9 -10 13 ffffff
-8 -10 13 ffffff
-7 -10 13 ffffff
-6 -10 13 ffffff
-5 -10 13 ffffff
-4 -10 13 ffffff
-3 -10 13 ffffff
-2 -10 13 ffffff
-1 -10 13 ffffff
-13 -9 13 ffffff
-12 -9 13 ffffff
-11 -9 13 ffffff
-10 -9 13 ffffff
-9 -9 13 ffffff
-8 -9 13 ffffff
-7 -9 13 ffffff
-6 -9 13 ffffff
-5 -9 13 ffffff
-4 -9 13 ffffff
-3 -9 13 ffffff
-2 -9 13 ffffff
-1 -9 13 ffffff
-13 -8 13 ffffff
-12 -8 13 ffffff
-11 -8 13 ffffff
-10 -8 13 ffffff
-9 -8 13 ffffff
-8 -8 13 ffffff
-7 -8 13 ffffff
-6 -8 13 ffffff
-5 -8 13 ffffff
-4 -8 13 ffffff
-3 -8 13 ffffff
-2 -8 13 ffffff
-1 -8 13 ffffff
-14 -7 13 ffffff
-13 -7 13 ffffff
-12 -7 13 ffffff
-11 -7 13 ffffff
-10 -7 13 ffffff
-9 -7 13 ffffff
-8 -7 13 ffffff
-7 -7 13 ffffff
-6 -7 13 ffffff
-5 -7 13 ffffff
-4 -7 13 ffffff
-3 -7 13 ffffff
-2 -7 13 ffffff
-1 -7 13 ffffff
-14 -6 13 ffffff
-13 -6 13 ffffff
-12 -6 13 ffffff
-11 -6 13 ffffff
-10 -6 13 ffffff
-9 -6 13 ffffff
-8 -6 13 ffffff
-7 -6 13 ffffff
-6 -6 13 ffffff
-5 -6 13 ffffff
-4 -6 13 ffffff
-3 -6 13 ffffff
-2 -6 13 ffffff
-1 -6 13 ffffff
-14 -5 13 ffffff
-13 -5 13 ffffff
-12 -5 13 ffffff
-11 -5 13 ffffff
-10 -5 13 ffffff
-9 -5 13 ffffff
-8 -5 13 ffffff
-7 -5 13 ffffff
-6 -5 13 ffffff
-5 -5 13 ffffff
-4 -5 13 ffffff
-3 -5 13 ffffff
-2 -5 13 ffffff
-1 -5 13 ffffff
-15 -4 13 ffffff
-14 -4 13 ffffff
-13 -4 13 ffffff
-12 -4 13 ffffff
-11 -4 13 ffffff
-10 -4 13 ffffff
-9 -4 13 ffffff
-8 -4 13 ffffff
-7 -4 13 ffffff
-6 -4 13 ffffff
-5 -4 13 ffffff
-4 -4 13 ffffff
-3 -4 13 ffffff
-2 -4 13 ffffff
-1 -4 13 ffffff
-15 -3 13 ffffff
-14 -3 13 ffffff
-13 -3 13 ffffff
-12 -3 13 ffffff
-11 -3 13 ffffff
-10 -3 13 ffffff
-9 -3 13 ffffff
-8 -3 13 ffffff
-7 -3 13 ffffff
-6 -3 13 ffffff
-5 -3 13 ffffff
-4 -3 13 ffffff
-3 -3 13 ffffff
-2 -3 13 ffffff
-1 -3 13 ffffff
-15 -2 13 ffffff
-14 -2 13 ffffff
-13 -2 13 ffffff
-12 -2 13 ffffff
-11 -2 13 ffffff
-10 -2 13 ffffff
-9 -2 13 ffffff
-8 -2 13 ffffff
-7 -2 13 ffffff
-6 -2 13 ffffff
-5 -2 13 ffffff
-4 -2 13 ffffff
-3 -2 13 ffffff
-2 -2 13 ffffff
-1 -2 13 ffffff
-15 -1 13 ffffff
-14 -1 13 ffffff
-13 -1 13 ffffff
-12 -1 13 ffffff
-11 -1 13 ffffff
-10 -1 13 ffffff
-9 -1 13 ffffff
-8 -1 13 ffffff
-7 -1 13 ffffff
-6 -1 13 ffffff
-5 -1 13 ffffff
-4 -1 13 ffffff
-3 -1 13 ffffff
-2 -1 13 ffffff
-1 -1 13 ffffff
-3 -16 14 ffffff
-2 -16 14 ffffff
-1 -16 14 ffffff
-6 -15 14 ffffff
-5 -15 14 ffffff
-4 -15 14 ffffff
-3 -15 14 ffffff
-2 -15 14 ffffff
-1 -15 14 ffffff
-8 -14 14 ffffff
-7 -14 14 ffffff
-6 -14 14 ffffff
-5 -14 14 ffffff
-4 -14 14 ffffff
-3 -14 14 ffffff
-2 -14 14 ffffff
-1 -14 14 ffffff
-9 -13 14 ffffff
-8 -13 14 ffffff
-7 -13 14 ffffff
-6 -13 14 ffffff
-5 -13 14 ffffff
-4 -13 14 ffffff
-3 -13 14 ffffff
-2 -13 14 ffffff
-1 -13 14 ffffff
-10 -12 14 ffffff
-9 -12 14 ffffff
-8 -12 14 ffffff
-7 -12 14 ffffff
-6 -12 14 ffffff
-5 -12 14 ffffff
-4 -12 14 ffffff
-3 -12 14 ffffff
-2 -12 14 ffffff
-1 -12 14 ffffff
-11 -11 14 ffffff
-10 -11 14 ffffff
-9 -11 14 ffffff
-8 -11 14 ffffff
-7 -11 14 ffffff
-6 -11 14 ffffff
-5 -11 14 ffffff
-4 -11 14 ffffff
-3 -11 14 ffffff
-2 -11 14 ffffff
-1 -11 14 ffffff
-12 -10 14 ffffff
-11 -10 14 ffffff
-10 -10 14 ffffff
-9 -10 14 ffffff
-8 -10 14 ffffff
-7 -10 14 ffffff
-6 -10 14 ffffff
-5 -10 14 ffffff
-4 -10 14 ffffff
-3 -10 14 ffffff
-2 -10 14 ffffff
-1 -10 14 ffffff
-13 -9 14 ffffff
-12 -9 14 ffffff
-11 -9 14 ffffff
-10 -9 14 ffffff
-9 -9 14 ffffff
-8 -9 14 ffffff
-7 -9 14 ffffff
-6 -9 14 ffffff
-5 -9 14 ffffff
-4 -9 14 ffffff
-3 -9 14 ffffff
-2 -9 14 ffffff
-1 -9 14 ffffff
-13 -8 14 ffffff
-12 -8 14 ffffff
-11 -8 14 ffffff
-10 -8 14 ffffff
-9 -8 14 ffffff
-8 -8 14 ffffff
-7 -8 14 ffffff
-6 -8 14 ffffff
-5 -8 14 ffffff
-4 -8 14 ffffff
-3 -8 14 ffffff
-2 -8 14 ffffff
-1 -8 14 ffffff
-14 -7 14 ffffff
-13 -7 14 ffffff
-12 -7 14 ffffff
-11 -7 14 ffffff
-10 -7 14 ffffff
-9 -7 14 ffffff
-8 -7 14 ffffff
-7 -7 14 ffffff
-6 -7 14 ffffff
-5 -7 14 ffffff
-4 -7 14 ffffff
-3 -7 14 ffffff
-2 -7 14 ffffff
-1 -7 14 ffffff
-14 -6 14 ffffff
-13 -6 14 ffffff
-12 -6 14 ffffff
-11 -6 14 ffffff
-10 -6 14 ffffff
-9 -6 14 ffffff
-8 -6 14 ffffff
-7 -6 14 ffffff
-6 -6 14 ffffff
-5 -6 14 ffffff
-4 -6 14 ffffff
-3 -6 14 ffffff
-2 -6 14 ffffff
-1 -6 14 ffffff
-14 -5 14 ffffff
-13 -5 14 ffffff
-12 -5 14 ffffff
-11 -5 14 ffffff
-10 -5 14 ffffff
-9 -5 14 ffffff
-8 -5 14 ffffff
-7 -5 14 ffffff
-6 -5 14 ffffff
-5 -5 14 ffffff
-4 -5 14 ffffff
-3 -5 14 ffffff
-2 -5 14 ffffff
-1 -5 14 ffffff
-15 -4 14 ffffff
-14 -4 14 ffffff
-13 -4 14 ffffff
-12 -4 14 ffffff
-11 -4 14 ffffff
-10 -4 14 ffffff
-9 -4 14 ffffff
-8 -4 14 ffffff
-7 -4 14 ffffff
-6 -4 14 ffffff
-5 -4 14 ffffff
-4 -4 14 ffffff
-3 -4 14 ffffff
-2 -4 14 ffffff
-1 -4 14 ffffff
-15 -3 14 ffffff
-14 -3 14 ffffff
-13 -3 14 ffffff
-12 -3 14 ffffff
-11 -3 14 ffffff
-10 -3 14 ffffff
-9 -3 14 ffffff
-8 -3 14 ffffff
-7 -3 14 ffffff
-6 -3 14 ffffff
-5 -3 14 ffffff
-4 -3 14 ffffff
-3 -3 14 ffffff
-2 -3 14 ffffff
-1 -3 14 ffffff
-15 -2 14 ffffff
-14 -2 14 ffffff
-13 -2 14 ffffff
-12 -2 14 ffffff
-11 -2 14 ffffff
-10 -2 14 ffffff
-9 -2 14 ffffff
-8 -2 14 ffffff
-7 -2 14 ffffff
-6 -2 14 ffffff
-5 -2 14 ffffff
-4 -2 14 ffffff
-3 -2 14 ffffff
-2 -2 14 ffffff
-1 -2 14 ffffff
-15 -1 14 ffffff
-14 -1 14 ffffff
-13 -1 14 ffffff
-12 -1 14 ffffff
-11 -1 14 ffffff
-10 -1 14 ffffff
-9 -1 14 ffffff
-8 -1 14 ffffff
-7 -1 14 ffffff
-6 -1 14 ffffff
-5 -1 14 ffffff
-4 -1 14 ffffff
-3 -1 14 ffffff
-2 -1 14 ffffff
-1 -1 14 ffffff
-3 -16 15 ffffff
-2 -16 15 ffffff
-1 -16 15 ffffff
-6 -15 15 ffffff
-5 -15 15 ffffff
-4 -15 15 ffffff
-3 -15 15 ffffff
-2 -15 15 ffffff
-1 -15 15 ffffff
-8 -14 15 ffffff
-7 -14 15 ffffff
-6 -14 15 ffffff
-5 -14 15 ffffff
-4 -14 15 ffffff
-3 -14 15 ffffff
-2 -14 15 ffffff
-1 -14 15 ffffff
-9 -13 15 ffffff
-8 -13 15 ffffff
-7 -13 15 ffffff
-6 -13 15 ffffff
-5 -13 15 ffffff
-4 -13 15 ffffff
-3 -13 15 ffffff
-2 -13 15 ffffff
-1 -13 15 ffffff
-10 -12 15 ffffff
-9 -12 15 ffffff
-8 -12 15 ffffff
-7 -12 15 ffffff
-6 -12 15 ffffff
-5 -12 15 ffffff
-4 -12 15 ffffff
-3 -12 15 ffffff
-2 -12 15 ffffff
-1 -12 15 ffffff
-11 -11 15 ffffff
-10 -11 15 ffffff
-9 -11 15 ffffff
-8 -11 15 ffffff
-7 -11 15 ffffff
-6 -11 15 ffffff
-5 -11 15 ffffff
-4 -11 15 ffffff
-3 -11 15 ffffff
-2 -11 15 ffffff
-1 -11 15 ffffff
-12 -10 15 ffffff
-11 -10 15 ffffff
-10 -10 15 ffffff
-9 -10 15 ffffff
-8 -10 15 ffffff
-7 -10 15 ffffff
-6 -10 15 ffffff
-5 -10 15 ffffff
-4 -10 15 ffffff
-3 -10 15 ffffff
-2 -10 15 ffffff
-1 -10 15 ffffff
-13 -9 15 ffffff
-12 -9 15 ffffff
-11 -9 15 ffffff
-10 -9 15 ffffff
-9 -9 15 ffffff
-8 -9 15 ffffff
-7 -9 15 ffffff
-6 -9 15 ffffff
-5 -9 15 ffffff
-4 -9 15 ffffff
-3 -9 15 ffffff
-2 -9 15 ffffff
-1 -9 15 ffffff
-13 -8 15 ffffff
-12 -8 15 ffffff
-11 -8 15 ffffff
-10 -8 15 ffffff
-9 -8 15 ffffff
-8 -8 15 ffffff
-7 -8 15 ffffff
-6 -8 15 ffffff
-5 -8 15 ffffff
-4 -8 15 ffffff
-3 -8 15 ffffff
-2 -8 15 ffffff
-1 -8 15 ffffff
-14 -7 15 ffffff
-13 -7 15 ffffff
-12 -7 15 ffffff
-11 -7 15 ffffff
-10 -7 15 ffffff
-9 -7 15 ffffff
-8 -7 15 ffffff
-7 -7 15 ffffff
-6 -7 15 ffffff
-5 -7 15 ffffff
-4 -7 15 ffffff
-3 -7 15 ffffff
-2 -7 15 ffffff
-1 -7 15 ffffff
-14 -6 15 ffffff
-13 -6 15 ffffff
-12 -6 15 ffffff
-11 -6 15 ffffff
-10 -6 15 ffffff
-9 -6 15 ffffff
-8 -6 15 ffffff
-7 -6 15 ffffff
-6 -6 15 ffffff
-5 -6 15 ffffff
-4 -6 15 ffffff
-3 -6 15 ffffff
-2 -6 15 ffffff
-1 -6 15 ffffff
-14 -5 15 ffffff
-13 -5 15 ffffff
-12 -5 15 ffffff
-11 -5 15 ffffff
-10 -5 15 ffffff
-9 -5 15 ffffff
-8 -5 15 ffffff
-7 -5 15 ffffff
-6 -5 15 ffffff
-5 -5 15 ffffff
-4 -5 15 ffffff
-3 -5 15 ffffff
-2 -5 15 ffffff
-1 -5 15 ffffff
-15 -4 15 ffffff
-14 -4 15 ffffff
-13 -4 15 ffffff
-12 -4 15 ffffff
-11 -4 15 ffffff
-10 -4 15 ffffff
-9 -4 15 ffffff
-8 -4 15 ffffff
-7 -4 15 ffffff
-6 -4 15 ffffff
-5 -4 15 ffffff
-4 -4 15 ffffff
-3 -4 15 ffffff
-2 -4 15 ffffff
-1 -4 15 ffffff
-15 -3 15 ffffff
-14 -3 15 ffffff
-13 -3 15 ffffff
-12 -3 15 ffffff
-11 -3 15 ffffff
-10 -3 15 ffffff
-9 -3 15 ffffff
-8 -3 15 ffffff
-7 -3 15 ffffff
-6 -3 15 ffffff
-5 -3 15 ffffff
-4 -3 15 ffffff
-3 -3 15 ffffff
-2 -3 15 ffffff
-1 -3 15 ffffff
-15 -2 15 ffffff
-14 -2 15 ffffff
-13 -2 15 ffffff
-12 -2 15 ffffff
-11 -2 15 ffffff
-10 -2 15 ffffff
-9 -2 15 ffffff
-8 -2 15 ffffff
-7 -2 15 ffffff
-6 -2 15 ffffff
-5 -2 15 ffffff
-4 -2 15 ffffff
-3 -2 15 ffffff
-2 -2 15 ffffff
-1 -2 15 ffffff
-15 -1 15 ffffff
-14 -1 15 ffffff
-13 -1 15 ffffff
-12 -1 15 ffffff
-11 -1 15 ffffff
-10 -1 15 ffffff
-9 -1 15 ffffff
-8 -1 15 ffffff
-7 -1 15 ffffff
-6 -1 15 ffffff
-5 -1 15 ffffff
-4 -1 15 ffffff
-3 -1 15 ffffff
-2 -1 15 ffffff
-1 -1 15 ffffff
0 -4 0 ffffff
1 -4 0 ffffff
2 -4 0 ffffff
0 -3 0 ffffff
1 -3 0 ffffff
2 -3 0 ffffff
3 -3 0 ffffff
0 -2 0 ffffff
1 -2 0 ffffff
2 -2 0 ffffff
3 -2 0 ffffff
0 -1 0 ffffff
1 -1 0 ffffff
2 -1 0 ffffff
3 -1 0 ffffff
0 -7 1 ffffff
1 -7 1 ffffff
2 -7 1 ffffff
0 -6 1 ffffff
1 -6 1 ffffff
2 -6 1 ffffff
3 -6 1 ffffff
4 -6 1 ffffff
0 -5 1 ffffff
1 -5 1 ffffff
2 -5 1 ffffff
3 -5 1 ffffff
4 -5 1 ffffff
5 -5 1 ffffff
0 -4 1 ffffff
1 -4 1 ffffff
2 -4 1 ffffff
3 -4 1 ffffff
4 -4 1 ffffff
5 -4 1 ffffff
0 -3 1 ffffff
1 -3 1 ffffff
2 -3 1 ffffff
3 -3 1 ffffff
4 -3 1 ffffff
5 -3 1 ffffff
6 -3 1 ffffff
0 -2 1 ffffff
1 -2 1 ffffff
2 -2 1 ffffff
3 -2 1 ffffff
4 -2 1 ffffff
5 -2 1 ffffff
6 -2 1 ffffff
0 -1 1 ffffff
1 -1 1 ffffff
2 -1 1 ffffff
3 -1 1 ffffff
4 -1 1 ffffff
5 -1 1 ffffff
6 -1 1 ffffff
0 -9 2 ffffff
1 -9 2 ffffff
2 -9 2 ffffff
0 -8 2 ffffff
1 -8 2 ffffff
2 -8 2 ffffff
3 -8 2 ffffff
4 -8 2 ffffff
0 -7 2 ffffff
1 -7 2 ffffff
2 -7 2 ffffff
3 -7 2 ffffff
4 -7 2 ffffff
5 -7 2 ffffff
0 -6 2 ffffff
1 -6 2 ffffff
2 -6 2 ffffff
3 -6 2 ffffff
4 -6 2 ffffff
5 -6 2 ffffff
6 -6 2 ffffff
0 -5 2 ffffff
1 -5 2 ffffff
2 -5 2 ffffff
3 -5 2 ffffff
4 -5 2 ffffff
5 -5 2 ffffff
6 -5 2 ffffff
7 -5 2 ffffff
0 -4 2 ffffff
1 -4 2 ffffff
2 -4 2 ffffff
3 -4 2 ffffff
4 -4 2 ffffff
5 -4 2 ffffff
6 -4 2 ffffff
7 -4 2 ffffff
0 -3 2 ffffff
1 -3 2 ffffff
2 -3 2 ffffff
3 -3 2 ffffff
4 -3 2 ffffff
5 -3 2 ffffff
6 -3 2 ffffff
7 -3 2 ffffff
8 -3 2 ffffff
0 -2 2 ffffff
1 -2 2 ffffff
2 -2 2 ffffff
3 -2 2 ffffff
4 -2 2 ffffff
5 -2 2 ffffff
6 -2 2 ffffff
7 -2 2 ffffff
8 -2 2 ffffff
0 -1 2 ffffff
1 -1 2 ffffff
2 -1 2 ffffff
3 -1 2 ffffff
4 -1 2 ffffff
5 -1 2 ffffff
6 -1 2 ffffff
7 -1 2 ffffff
8 -1 2 ffffff
0 -10 3 ffffff
1 -10 3 ffffff
2 -10 3 ffffff
3 -10 3 ffffff
0 -9 3 ffffff
1 -9 3 ffffff
2 -9 3 ffffff
3 -9 3 ffffff
4 -9 3 ffffff
5 -9 3 ffffff
0 -8 3 ffffff
1 -8 3 ffffff
2 -8 3 ffffff
3 -8 3 ffffff
4 -8 3 ffffff
5 -8 3 ffffff
6 -8 3 ffffff
0 -7 3 ffffff
1 -7 3 ffffff
2 -7 3 ffffff
3 -7 3 ffffff
4 -7 3 ffffff
5 -7 3 ffffff
6 -7 3 ffffff
7 -7 3 ffffff
0 -6 3 ffffff
1 -6 3 ffffff
2 -6 3 ffffff
3 -6 3 ffffff
4 -6 3 ffffff
5 -6 3 ffffff
6 -6 3 ffffff
7 -6 3 ffffff
8 -6 3 ffffff
0 -5 3 ffffff
1 -5 3 ffffff
2 -5 3 ffffff
3 -5 3 ffffff
4 -5 3 ffffff
5 -5 3 ffffff
6 -5 3 ffffff
7 -5 3 ffffff
8 -5 3 ffffff
0 -4 3 ffffff
1 -4 3 ffffff
2 -4 3 ffffff
3 -4 3 ffffff
4 -4 3 ffffff
5 -4 3 ffffff
6 -4 3 ffffff
7 -4 3 ffffff
8 -4 3 ffffff
9 -4 3 ffffff
0 -3 3 ffffff
1 -3 3 ffffff
2 -3 3 ffffff
3 -3 3 ffffff
4 -3 3 ffffff
5 -3 3 ffffff
6 -3 3 ffffff
7 -3 3 ffffff
8 -3 3 ffffff
9 -3 3 ffffff
0 -2 3 ffffff
1 -2 3 ffffff
2 -2 3 ffffff
3 -2 3 ffffff
4 -2 3 ffffff
5 -2 3 ffffff
6 -2 3 ffffff
7 -2 3 ffffff
8 -2 3 ffffff
9 -2 3 ffffff
0 -1 3 ffffff
1 -1 3 ffffff
2 -1 3 ffffff
3 -1 3 ffffff
4 -1 3 ffffff
5 -1 3 ffffff
6 -1 3 ffffff
7 -1 3 ffffff
8 -1 3 ffffff
9 -1 3 ffffff
0 -11 4 ffffff
1 -11 4 ffffff
2 -11 4 ffffff
3 -11 4 ffffff
4 -11 4 ffffff
0 -10 4 ffffff
1 -10 4 ffffff
2 -10 4 ffffff
3 -10 4 ffffff
4 -10 4 ffffff
5 -10 4 ffffff
0 -9 4 ffffff
1 -9 4 ffffff
2 -9 4 ffffff
3 -9 4 ffffff
4 -9 4 ffffff
5 -9 4 ffffff
6 -9 4 ffffff
7 -9 4 ffffff
0 -8 4 ffffff
1 -8 4 ffffff
2 -8 4 ffffff
3 -8 4 ffffff
4 -8 4 ffffff
5 -8 4 ffffff
6 -8 4 ffffff
7 -8 4 ffffff
8 -8 4 ffffff
0 -7 4 ffffff
1 -7 4 ffffff
2 -7 4 ffffff
3 -7 4 ffffff
4 -7 4 ffffff
5 -7 4 ffffff
6 -7 4 ffffff
7 -7 4 ffffff
8 -7 4 ffffff
0 -6 4 ffffff
1 -6 4 ffffff
2 -6 4 ffffff
3 -6 4 ffffff
4 -6 4 ffffff
5 -6 4 ffffff
6 -6 4 ffffff
7 -6 4 ffffff
8 -6 4 ffffff
9 -6 4 ffffff
0 -5 4 ffffff
1 -5 4 ffffff
2 -5 4 ffffff
3 -5 4 ffffff
4 -5 4 ffffff
5 -5 4 ffffff
6 -5 4 ffffff
7 -5 4 ffffff
8 -5 4 ffffff
9 -5 4 ffffff
10 -5 4 ffffff
0 -4 4 ffffff
1 -4 4 ffffff
2 -4 4 ffffff
3 -4 4 ffffff
4 -4 4 ffffff
5 -4 4 ffffff
6 -4 4 ffffff
7 -4 4 ffffff
8 -4 4 ffffff
9 -4 4 ffffff
10 -4 4 ffffff
0 -3 4 ffffff
1 -3 4 ffffff
2 -3 4 ffffff
3 -3 4 ffffff
4 -3 4 ffffff
5 -3 4 ffffff
6 -3 4 ffffff
7 -3 4 ffffff
8 -3 4 ffffff
9 -3 4 ffffff
10 -3 4 ffffff
0 -2 4 ffffff
1 -2 4 ffffff
2 -2 4 ffffff
3 -2 4 ffffff
4 -2 4 ffffff
5 -2 4 ffffff
6 -2 4 ffffff
7 -2 4 ffffff
8 -2 4 ffffff
9 -2 4 ffffff
10 -2 4 ffffff
0 -1 4 ffffff
1 -1 4 ffffff
2 -1 4 ffffff
3 -1 4 ffffff
4 -1 4 ffffff
5 -1 4 ffffff
6 -1 4 ffffff
7 -1 4 ffffff
8 -1 4 ffffff
9 -1 4 ffffff
10 -1 4 ffffff
0 -12 5 ffffff
1 -12 5 ffffff
2 -12 5 ffffff
3 -12 5 ffffff
0 -11 5 ffffff
1 -11 5 ffffff
2 -11 5 ffffff
3 -11 5 ffffff
4 -11 5 ffffff
5 -11 5 ffffff
6 -11 5 ffffff
0 -10 5 ffffff
1 -10 5 ffffff
2 -10 5 ffffff
3 -10 5 ffffff
4 -10 5 ffffff
5 -10 5 ffffff
6 -10 5 ffffff
7 -10 5 ffffff
0 -9 5 ffffff
1 -9 5 ffffff
2 -9 5 ffffff
3 -9 5 ffffff
4 -9 5 ffffff
5 -9 5 ffffff
6 -9 5 ffffff
7 -9 5 ffffff
8 -9 5 ffffff
0 -8 5 ffffff
1 -8 5 ffffff
2 -8 5 ffffff
3 -8 5 ffffff
4 -8 5 ffffff
5 -8 5 ffffff
6 -8 5 ffffff
7 -8 5 ffffff
8 -8 5 ffffff
9 -8 5 ffffff
0 -7 5 ffffff
1 -7 5 ffffff
2 -7 5 ffffff
3 -7 5 ffffff
4 -7 5 ffffff
5 -7 5 ffffff
6 -7 5 ffffff
7 -7 5 ffffff
8 -7 5 ffffff
9 -7 5 ffffff
10 -7 5 ffffff
0 -6 5 ffffff
1 -6 5 ffffff
2 -6 5 ffffff
3 -6 5 ffffff
4 -6 5 ffffff
5 -6 5 ffffff
6 -6 5 ffffff
7 -6 5 ffffff
8 -6 5 ffffff
9 -6 5 ffffff
10 -6 5 ffffff
0 -5 5 ffffff
1 -5 5 ffffff
2 -5 5 ffffff
3 -5 5 ffffff
4 -5 5 ffffff
5 -5 5 ffffff
6 -5 5 ffffff
7 -5 5 ffffff
8 -5 5 ffffff
9 -5 5 ffffff
10 -5 5 ffffff
0 -4 5 ffffff
1 -4 5 ffffff
2 -4 5 ffffff
3 -4 5 ffffff
4 -4 5 ffffff
5 -4 5 ffffff
6 -4 5 ffffff
7 -4 5 ffffff
8 -4 5 ffffff
9 -4 5 ffffff
10 -4 5 ffffff
11 -4 5 ffffff
0 -3 5 ffffff
1 -3 5 ffffff
2 -3 5 ffffff
3 -3 5 ffffff
4 -3 5 ffffff
5 -3 5 ffffff
6 -3 5 ffffff
7 -3 5 ffffff
8 -3 5 ffffff
9 -3 5 ffffff
10 -3 5 ffffff
11 -3 5 ffffff
0 -2 5 ffffff
1 -2 5 ffffff
2 -2 5 ffffff
3 -2 5 ffffff
4 -2 5 ffffff
5 -2 5 ffffff
6 -2 5 ffffff
7 -2 5 ffffff
8 -2 5 ffffff
9 -2 5 ffffff
10 -2 5 ffffff
11 -2 5 ffffff
0 -1 5 ffffff
1 -1 5 ffffff
2 -1 5 ffffff
3 -1 5 ffffff
4 -1 5 ffffff
5 -1 5 ffffff
6 -1 5 ffffff
7 -1 5 ffffff
8 -1 5 ffffff
9 -1 5 ffffff
10 -1 5 ffffff
11 -1 5 ffffff
0 -13 6 ffffff
1 -13 6 ffffff
2 -13 6 ffffff
3 -13 6 ffffff
0 -12 6 ffffff
1 -12 6 ffffff
2 -12 6 ffffff
3 -12 6 ffffff
4 -12 6 ffffff
5 -12 6 ffffff
0 -11 6 ffffff
1 -11 6 ffffff
2 -11 6 ffffff
3 -11 6 ffffff
4 -11 6 ffffff
5 -11 6 ffffff
6 -11 6 ffffff
7 -11 6 ffffff
0 -10 6 ffffff
1 -10 6 ffffff
2 -10 6 ffffff
3 -10 6 ffffff
4 -10 6 ffffff
5 -10 6 ffffff
6 -10 6 ffffff
7 -10 6 ffffff
8 -10 6 ffffff
0 -9 6 ffffff
1 -9 6 ffffff
2 -9 6 ffffff
3 -9 6 ffffff
4 -9 6 ffffff
5 -9 6 ffffff
6 -9 6 ffffff
7 -9 6 ffffff
8 -9 6 ffffff
9 -9 6 ffffff
0 -8 6 ffffff
1 -8 6 ffffff
2 -8 6 ffffff
3 -8 6 ffffff
4 -8 6 ffffff
5 -8 6 ffffff
6 -8 6 ffffff
7 -8 6 ffffff
8 -8 6 ffffff
9 -8 6 ffffff
10 -8 6 ffffff
0 -7 6 ffffff
1 -7 6 ffffff
2 -7 6 ffffff
3 -7 6 ffffff
4 -7 6 ffffff
5 -7 6 ffffff
6 -7 6 ffffff
7 -7 6 ffffff
8 -7 6 ffffff
9 -7 6 ffffff
10 -7 6 ffffff
0 -6 6 ffffff
1 -6 6 ffffff
2 -6 6 ffffff
3 -6 6 ffffff
4 -6 6 ffffff
5 -6 6 ffffff
6 -6 6 ffffff
7 -6 6 ffffff
8 -6 6 ffffff
9 -6 6 ffffff
10 -6 6 ffffff
11 -6 6 ffffff
0 -5 6 ffffff
1 -5 6 ffffff
2 -5 6 ffffff
3 -5 6 ffffff
4 -5 6 ffffff
5 -5 6 ffffff
6 -5 6 ffffff
7 -5 6 ffffff
8 -5 6 ffffff
9 -5 6 ffffff
10 -5 6 ffffff
11 -5 6 ffffff
0 -4 6 ffffff
1 -4 6 ffffff
2 -4 6 ffffff
3 -4 6 ffffff
4 -4 6 ffffff
5 -4 6 ffffff
6 -4 6 ffffff
7 -4 6 ffffff
8 -4 6 ffffff
9 -4 6 ffffff
10 -4 6 ffffff
11 -4 6 ffffff
12 -4 6 ffffff
0 -3 6 ffffff
1 -3 6 ffffff
2 -3 6 ffffff
3 -3 6 ffffff
4 -3 6 ffffff
5 -3 6 ffffff
6 -3 6 ffffff
7 -3 6 ffffff
8 -3 6 ffffff
9 -3 6 ffffff
10 -3 6 ffffff
11 -3 6 ffffff
12 -3 6 ffffff
0 -2 6 ffffff
1 -2 6 ffffff
2 -2 6 ffffff
3 -2 6 ffffff
4 -2 6 ffffff
5 -2 6 ffffff
6 -2 6 ffffff
7 -2 6 ffffff
8 -2 6 ffffff
9 -2 6 ffffff
10 -2 6 ffffff
11 -2 6 ffffff
12 -2 6 ffffff
0 -1 6 ffffff
1 -1 6 ffffff
2 -1 6 ffffff
3 -1 6 ffffff
4 -1 6 ffffff
5 -1 6 ffffff
6 -1 6 ffffff
7 -1 6 ffffff
8 -1 6 ffffff
9 -1 6 ffffff
10 -1 6 ffffff
11 -1 6 ffffff
12 -1 6 ffffff
0 -14 7 ffffff
1 -14 7 ffffff
0 -13 7 ffffff
1 -13 7 ffffff
2 -13 7 ffffff
3 -13 7 ffffff
4 -13 7 ffffff
5 -13 7 ffffff
0 -12 7 ffffff
1 -12 7 ffffff
2 -12 7 ffffff
3 -12 7 ffffff
4 -12 7 ffffff
5 -12 7 ffffff
6 -12 7 ffffff
7 -12 7 ffffff
0 -11 7 ffffff
1 -11 7 ffffff
2 -11 7 ffffff
3 -11 7 ffffff
4 -11 7 ffffff
5 -11 7 ffffff
6 -11 7 ffffff
7 -11 7 ffffff
8 -11 7 ffffff
0 -10 7 ffffff
1 -10 7 ffffff
2 -10 7 ffffff
3 -10 7 ffffff
4 -10 7 ffffff
5 -10 7 ffffff
6 -10 7 ffffff
7 -10 7 ffffff
8 -10 7 ffffff
9 -10 7 ffffff
0 -9 7 ffffff
1 -9 7 ffffff
2 -9 7 ffffff
3 -9 7 ffffff
4 -9 7 ffffff
5 -9 7 ffffff
6 -9 7 ffffff
7 -9 7 ffffff
8 -9 7 ffffff
9 -9 7 ffffff
10 -9 7 ffffff
0 -8 7 ffffff
1 -8 7 ffffff
2 -8 7 ffffff
3 -8 7 ffffff
4 -8 7 ffffff
5 -8 7 ffffff
6 -8 7 ffffff
7 -8 7 ffffff
8 -8 7 ffffff
9 -8 7 ffffff
10 -8 7 ffffff
11 -8 7 ffffff
0 -7 7 ffffff
1 -7 7 ffffff
2 -7 7 ffffff
3 -7 7 ffffff
4 -7 7 ffffff
5 -7 7 ffffff
6 -7 7 ffffff
7 -7 7 ffffff
8 -7 7 ffffff
9 -7 7 ffffff
10 -7 7 ffffff
11 -7 7 ffffff
0 -6 7 ffffff
1 -6 7 ffffff
2 -6 7 ffffff
3 -6 7 ffffff
4 -6 7 ffffff
5 -6 7 ffffff
6 -6 7 ffffff
7 -6 7 ffffff
8 -6 7 ffffff
9 -6 7 ffffff
10 -6 7 ffffff
11 -6 7 ffffff
12 -6 7 ffffff
0 -5 7 ffffff
1 -5 7 ffffff
2 -5 7 ffffff
3 -5 7 ffffff
4 -5 7 ffffff
5 -5 7 ffffff
6 -5 7 ffffff
7 -5 7 ffffff
8 -5 7 ffffff
9 -5 7 ffffff
10 -5 7 ffffff
11 -5 7 ffffff
12 -5 7 ffffff
0 -4 7 ffffff
1 -4 7 ffffff
2 -4 7 ffffff
3 -4 7 ffffff
4 -4 7 ffffff
5 -4 7 ffffff
6 -4 7 ffffff
7 -4 7 ffffff
8 -4 7 ffffff
9 -4 7 ffffff
10 -4 7 ffffff
11 -4 7 ffffff
12 -4 7 ffffff
0 -3 7 ffffff
1 -3 7 ffffff
2 -3 7 ffffff
3 -3 7 ffffff
4 -3 7 ffffff
5 -3 7 ffffff
6 -3 7 ffffff
7 -3 7 ffffff
8 -3 7 ffffff
9 -3 7 ffffff
10 -3 7 ffffff
11 -3 7 ffffff
12 -3 7 ffffff
0 -2 7 ffffff
1 -2 7 ffffff
2 -2 7 ffffff
3 -2 7 ffffff
4 -2 7 ffffff
5 -2 7 ffffff
6 -2 7 ffffff
7 -2 7 ffffff
8 -2 7 ffffff
9 -2 7 ffffff
10 -2 7 ffffff
11 -2 7 ffffff
12 -2 7 ffffff
13 -2 7 ffffff
0 -1 7 ffffff
1 -1 7 ffffff
2 -1 7 ffffff
3 -1 7 ffffff
4 -1 7 ffffff
5 -1 7 ffffff
6 -1 7 ffffff
7 -1 7 ffffff
8 -1 7 ffffff
9 -1 7 ffffff
10 -1 7 ffffff
11 -1 7 ffffff
12 -1 7 ffffff
13 -1 7 ffffff
0 -14 8 ffffff
1 -14 8 ffffff
2 -14 8 ffffff
3 -14 8 ffffff
4 -14 8 ffffff
0 -13 8 ffffff
1 -13 8 ffffff
2 -13 8 ffffff
3 -13 8 ffffff
4 -13 8 ffffff
5 -13 8 ffffff
6 -13 8 ffffff
0 -12 8 ffffff
1 -12 8 ffffff
2 -12 8 ffffff
3 -12 8 ffffff
4 -12 8 ffffff
5 -12 8 ffffff
6 -12 8 ffffff
7 -12 8 ffffff
8 -12 8 ffffff
0 -11 8 ffffff
1 -11 8 ffffff
2 -11 8 ffffff
3 -11 8 ffffff
4 -11 8 ffffff
5 -11 8 ffffff
6 -11 8 ffffff
7 -11 8 ffffff
8 -11 8 ffffff
9 -11 8 ffffff
0 -10 8 ffffff
1 -10 8 ffffff
2 -10 8 ffffff
3 -10 8 ffffff
4 -10 8 ffffff
5 -10 8 ffffff
6 -10 8 ffffff
7 -10 8 ffffff
8 -10 8 ffffff
9 -10 8 ffffff
10 -10 8 ffffff
0 -9 8 ffffff
1 -9 8 ffffff
2 -9 8 ffffff
3 -9 8 ffffff
4 -9 8 ffffff
5 -9 8 ffffff
6 -9 8 ffffff
7 -9 8 ffffff
8 -9 8 ffffff
9 -9 8 ffffff
10 -9 8 ffffff
11 -9 8 ffffff
0 -8 8 ffffff
1 -8 8 ffffff
2 -8 8 ffffff
3 -8 8 ffffff
4 -8 8 ffffff
5 -8 8 ffffff
6 -8 8 ffffff
7 -8 8 ffffff
8 -8 8 ffffff
9 -8 8 ffffff
10 -8 8 ffffff
11 -8 8 ffffff
0 -7 8 ffffff
1 -7 8 ffffff
2 -7 8 ffffff
3 -7 8 ffffff
4 -7 8 ffffff
5 -7 8 ffffff
6 -7 8 ffffff
7 -7 8 ffffff
8 -7 8 ffffff
9 -7 8 ffffff
10 -7 8 ffffff
11 -7 8 ffffff
12 -7 8 ffffff
0 -6 8 ffffff
1 -6 8 ffffff
2 -6 8 ffffff
3 -6 8 ffffff
4 -6 8 ffffff
5 -6 8 ffffff
6 -6 8 ffffff
7 -6 8 ffffff
8 -6 8 ffffff
9 -6 8 ffffff
10 -6 8 ffffff
11 -6 8 ffffff
12 -6 8 ffffff
0 -5 8 ffffff
1 -5 8 ffffff
2 -5 8 ffffff
3 -5 8 ffffff
4 -5 8 ffffff
5 -5 8 ffffff
6 -5 8 ffffff
7 -5 8 ffffff
8 -5 8 ffffff
9 -5 8 ffffff
10 -5 8 ffffff
11 -5 8 ffffff
12 -5 8 ffffff
13 -5 8 ffffff
0 -4 8 ffffff
1 -4 8 ffffff
2 -4 8 ffffff
3 -4 8 ffffff
4 -4 8 ffffff
5 -4 8 ffffff
6 -4 8 ffffff
7 -4 8 ffffff
8 -4 8 ffffff
9 -4 8 ffffff
10 -4 8 ffffff
11 -4 8 ffffff
12 -4 8 ffffff
13 -4 8 ffffff
0 -3 8 ffffff
1 -3 8 ffffff
2 -3 8 ffffff
3 -3 8 ffffff
4 -3 8 ffffff
5 -3 8 ffffff
6 -3 8 ffffff
7 -3 8 ffffff
8 -3 8 ffffff
9 -3 8 ffffff
10 -3 8 ffffff
11 -3 8 ffffff
12 -3 8 ffffff
13 -3 8 ffffff
0 -2 8 ffffff
1 -2 8 ffffff
2 -2 8 ffffff
3 -2 8 ffffff
4 -2 8 ffffff
5 -2 8 ffffff
6 -2 8 ffffff
7 -2 8 ffffff
8 -2 8 ffffff
9 -2 8 ffffff
10 -2 8 ffffff
11 -2 8 ffffff
12 -2 8 ffffff
13 -2 8 ffffff
0 -1 8 ffffff
1 -1 8 ffffff
2 -1 8 ffffff
3 -1 8 ffffff
4 -1 8 ffffff
5 -1 8 ffffff
6 -1 8 ffffff
7 -1 8 ffffff
8 -1 8 ffffff
9 -1 8 ffffff
10 -1 8 ffffff
11 -1 8 ffffff
12 -1 8 ffffff
13 -1 8 ffffff
0 -15 9 ffffff
1 -15 9 ffffff
2 -15 9 ffffff
0 -14 9 ffffff
1 -14 9 ffffff
2 -14 9 ffffff
3 -14 9 ffffff
4 -14 9 ffffff
5 -14 9 ffffff
0 -13 9 ffffff
1 -13 9 ffffff
2 -13 9 ffffff
3 -13 9 ffffff
4 -13 9 ffffff
5 -13 9 ffffff
6 -13 9 ffffff
7 -13 9 ffffff
0 -12 9 ffffff
1 -12 9 ffffff
2 -12 9 ffffff
3 -12 9 ffffff
4 -12 9 ffffff
5 -12 9 ffffff
6 -12 9 ffffff
7 -12 9 ffffff
8 -12 9 ffffff
0 -11 9 ffffff
1 -11 9 ffffff
2 -11 9 ffffff
3 -11 9 ffffff
4 -11 9 ffffff
5 -11 9 ffffff
6 -11 9 ffffff
7 -11 9 ffffff
8 -11 9 ffffff
9 -11 9 ffffff
10 -11 9 ffffff
0 -10 9 ffffff
1 -10 9 ffffff
2 -10 9 ffffff
3 -10 9 ffffff
4 -10 9 ffffff
5 -10 9 ffffff
6 -10 9 ffffff
7 -10 9 ffffff
8 -10 9 ffffff
9 -10 9 ffffff
10 -10 9 ffffff
0 -9 9 ffffff
1 -9 9 ffffff
2 -9 9 ffffff
3 -9 9 ffffff
4 -9 9 ffffff
5 -9 9 ffffff
6 -9 9 ffffff
7 -9 9 ffffff
8 -9 9 ffffff
9 -9 9 ffffff
10 -9 9 ffffff
11 -9 9 ffffff
0 -8 9 ffffff
1 -8 9 ffffff
2 -8 9 ffffff
3 -8 9 ffffff
4 -8 9 ffffff
5 -8 9 ffffff
6 -8 9 ffffff
7 -8 9 ffffff
8 -8 9 ffffff
9 -8 9 ffffff
10 -8 9 ffffff
11 -8 9 ffffff
12 -8 9 ffffff
0 -7 9 ffffff
1 -7 9 ffffff
2 -7 9 ffffff
3 -7 9 ffffff
4 -7 9 ffffff
5 -7 9 ffffff
6 -7 9 ffffff
7 -7 9 ffffff
8 -7 9 ffffff
9 -7 9 ffffff
10 -7 9 ffffff
11 -7 9 ffffff
12 -7 9 ffffff
0 -6 9 ffffff
1 -6 9 ffffff
2 -6 9 ffffff
3 -6 9 ffffff
4 -6 9 ffffff
5 -6 9 ffffff
6 -6 9 ffffff
7 -6 9 ffffff
8 -6 9 ffffff
9 -6 9 ffffff
10 -6 9 ffffff
11 -6 9 ffffff
12 -6 9 ffffff
13 -6 9 ffffff
0 -5 9 ffffff
1 -5 9 ffffff
2 -5 9 ffffff
3 -5 9 ffffff
4 -5 9 ffffff
5 -5 9 ffffff
6 -5 9 ffffff
7 -5 9 ffffff
8 -5 9 ffffff
9 -5 9 ffffff
10 -5 9 ffffff
11 -5 9 ffffff
12 -5 9 ffffff
13 -5 9 ffffff
0 -4 9 ffffff
1 -4 9 ffffff
2 -4 9 ffffff
3 -4 9 ffffff
4 -4 9 ffffff
5 -4 9 ffffff
6 -4 9 ffffff
7 -4 9 ffffff
8 -4 9 ffffff
9 -4 9 ffffff
10 -4 9 ffffff
11 -4 9 ffffff
12 -4 9 ffffff
13 -4 9 ffffff
0 -3 9 ffffff
1 -3 9 ffffff
2 -3 9 ffffff
3 -3 9 ffffff
4 -3 9 ffffff
5 -3 9 ffffff
6 -3 9 ffffff
7 -3 9 ffffff
8 -3 9 ffffff
9 -3 9 ffffff
10 -3 9 ffffff
11 -3 9 ffffff
12 -3 9 ffffff
13 -3 9 ffffff
14 -3 9 ffffff
0 -2 9 ffffff
1 -2 9 ffffff
2 -2 9 ffffff
3 -2 9 ffffff
4 -2 9 ffffff
5 -2 9 ffffff
6 -2 9 ffffff
7 -2 9 ffffff
8 -2 9 ffffff
9 -2 9 ffffff
10 -2 9 ffffff
11 -2 9 ffffff
12 -2 9 ffffff
13 -2 9 ffffff
14 -2 9 ffffff
0 -1 9 ffffff
1 -1 9 ffffff
2 -1 9 ffffff
3 -1 9 ffffff
4 -1 9 ffffff
5 -1 9 ffffff
6 -1 9 ffffff
7 -1 9 ffffff
8 -1 9 ffffff
9 -1 9 ffffff
10 -1 9 ffffff
11 -1 9 ffffff
12 -1 9 ffffff
13 -1 9 ffffff
14 -1 9 ffffff
0 -15 10 ffffff
1 -15 10 ffffff
2 -15 10 ffffff
3 -15 10 ffffff
0 -14 10 ffffff
1 -14 10 ffffff
2 -14 10 ffffff
3 -14 10 ffffff
4 -14 10 ffffff
5 -14 10 ffffff
6 -14 10 ffffff
0 -13 10 ffffff
1 -13 10 ffffff
2 -13 10 ffffff
3 -13 10 ffffff
4 -13 10 ffffff
5 -13 10 ffffff
6 -13 10 ffffff
7 -13 10 ffffff
8 -13 10 ffffff
0 -12 10 ffffff
1 -12 10 ffffff
2 -12 10 ffffff
3 -12 10 ffffff
4 -12 10 ffffff
5 -12 10 ffffff
6 -12 10 ffffff
7 -12 10 ffffff
8 -12 10 ffffff
9 -12 10 ffffff
0 -11 10 ffffff
1 -11 10 ffffff
2 -11 10 ffffff
3 -11 10 ffffff
4 -11 10 ffffff
5 -11 10 ffffff
6 -11 10 ffffff
7 -11 10 ffffff
8 -11 10 ffffff
9 -11 10 ffffff
10 -11 10 ffffff
0 -10 10 ffffff
1 -10 10 ffffff
2 -10 10 ffffff
3 -10 10 ffffff
4 -10 10 ffffff
5 -10 10 ffffff
6 -10 10 ffffff
7 -10 10 ffffff
8 -10 10 ffffff
9 -10 10 ffffff
10 -10 10 ffffff
11 -10 10 ffffff
0 -9 10 ffffff
1 -9 10 ffffff
2 -9 10 ffffff
3 -9 10 ffffff
4 -9 10 ffffff
5 -9 10 ffffff
6 -9 10 ffffff
7 -9 10 ffffff
8 -9 10 ffffff
9 -9 10 ffffff
10 -9 10 ffffff
11 -9 10 ffffff
12 -9 10 ffffff
0 -8 10 ffffff
1 -8 10 ffffff
2 -8 10 ffffff
3 -8 10 ffffff
4 -8 10 ffffff
5 -8 10 ffffff
6 -8 10 ffffff
7 -8 10 ffffff
8 -8 10 ffffff
9 -8 10 ffffff
10 -8 10 ffffff
11 -8 10 ffffff
12 -8 10 ffffff
0 -7 10 ffffff
1 -7 10 ffffff
2 -7 10 ffffff
3 -7 10 ffffff
4 -7 10 ffffff
5 -7 10 ffffff
6 -7 10 ffffff
7 -7 10 ffffff
8 -7 10 ffffff
9 -7 10 ffffff
10 -7 10 ffffff
11 -7 10 ffffff
12 -7 10 ffffff
13 -7 10 ffffff
0 -6 10 ffffff
1 -6 10 ffffff
2 -6 10 ffffff
3 -6 10 ffffff
4 -6 10 ffffff
5 -6 10 ffffff
6 -6 10 ffffff
7 -6 10 ffffff
8 -6 10 ffffff
9 -6 10 ffffff
10 -6 10 ffffff
11 -6 10 ffffff
12 -6 10 ffffff
13 -6 10 ffffff
0 -5 10 ffffff
1 -5 10 ffffff
2 -5 10 ffffff
3 -5 10 ffffff
4 -5 10 ffffff
5 -5 10 ffffff
6 -5 10 ffffff
7 -5 10 ffffff
8 -5 10 ffffff
9 -5 10 ffffff
10 -5 10 ffffff
11 -5 10 ffffff
12 -5 10 ffffff
13 -5 10 ffffff
0 -4 10 ffffff
1 -4 10 ffffff
2 -4 10 ffffff
3 -4 10 ffffff
4 -4 10 ffffff
5 -4 10 ffffff
6 -4 10 ffffff
7 -4 10 ffffff
8 -4 10 ffffff
9 -4 10 ffffff
10 -4 10 ffffff
11 -4 10 ffffff
12 -4 10 ffffff
13 -4 10 ffffff
14 -4 10 ffffff
0 -3 10 ffffff
1 -3 10 ffffff
2 -3 10 ffffff
3 -3 10 ffffff
4 -3 10 ffffff
5 -3 10 ffffff
6 -3 10 ffffff
7 -3 10 ffffff
8 -3 10 ffffff
9 -3 10 ffffff
10 -3 10 ffffff
11 -3 10 ffffff
12 -3 10 ffffff
13 -3 10 ffffff
14 -3 10 ffffff
0 -2 10 ffffff
1 -2 10 ffffff
2 -2 10 ffffff
3 -2 10 ffffff
4 -2 10 ffffff
5 -2 10 ffffff
6 -2 10 ffffff
7 -2 10 ffffff
8 -2 10 ffffff
9 -2 10 ffffff
10 -2 10 ffffff
11 -2 10 ffffff
12 -2 10 ffffff
13 -2 10 ffffff
14 -2 10 ffffff
0 -1 10 ffffff
1 -1 10 ffffff
2 -1 10 ffffff
3 -1 10 ffffff
4 -1 10 ffffff
5 -1 10 ffffff
6 -1 10 ffffff
7 -1 10 ffffff
8 -1 10 ffffff
9 -1 10 ffffff
10 -1 10 ffffff
11 -1 10 ffffff
12 -1 10 ffffff
13 -1 10 ffffff
14 -1 10 ffffff
0 -15 11 ffffff
1 -15 11 ffffff
2 -15 11 ffffff
3 -15 11 ffffff
4 -15 11 ffffff
5 -15 11 ffffff
0 -14 11 ffffff
1 -14 11 ffffff
2 -14 11 ffffff
3 -14 11 ffffff
4 -14 11 ffffff
5 -14 11 ffffff
6 -14 11 ffffff
7 -14 11 ffffff
0 -13 11 ffffff
1 -13 11 ffffff
2 -13 11 ffffff
3 -13 11 ffffff
4 -13 11 ffffff
5 -13 11 ffffff
6 -13 11 ffffff
7 -13 11 ffffff
8 -13 11 ffffff
0 -12 11 ffffff
1 -12 11 ffffff
2 -12 11 ffffff
3 -12 11 ffffff
4 -12 11 ffffff
5 -12 11 ffffff
6 -12 11 ffffff
7 -12 11 ffffff
8 -12 11 ffffff
9 -12 11 ffffff
10 -12 11 ffffff
0 -11 11 ffffff
1 -11 11 ffffff
2 -11 11 ffffff
3 -11 11 ffffff
4 -11 11 ffffff
5 -11 11 ffffff
6 -11 11 ffffff
7 -11 11 ffffff
8 -11 11 ffffff
9 -11 11 ffffff
10 -11 11 ffffff
11 -11 11 ffffff
0 -10 11 ffffff
1 -10 11 ffffff
2 -10 11 ffffff
3 -10 11 ffffff
4 -10 11 ffffff
5 -10 11 ffffff
6 -10 11 ffffff
7 -10 11 ffffff
8 -10 11 ffffff
9 -10 11 ffffff
10 -10 11 ffffff
11 -10 11 ffffff
0 -9 11 ffffff
1 -9 11 ffffff
2 -9 11 ffffff
3 -9 11 ffffff
4 -9 11 ffffff
5 -9 11 ffffff
6 -9 11 ffffff
7 -9 11 ffffff
8 -9 11 ffffff
9 -9 11 ffffff
10 -9 11 ffffff
11 -9 11 ffffff
12 -9 11 ffffff
0 -8 11 ffffff
1 -8 11 ffffff
2 -8 11 ffffff
3 -8 11 ffffff
4 -8 11 ffffff
5 -8 11 ffffff
6 -8 11 ffffff
7 -8 11 ffffff
8 -8 11 ffffff
9 -8 11 ffffff
10 -8 11 ffffff
11 -8 11 ffffff
12 -8 11 ffffff
13 -8 11 ffffff
0 -7 11 ffffff
1 -7 11 ffffff
2 -7 11 ffffff
3 -7 11 ffffff
4 -7 11 ffffff
5 -7 11 ffffff
6 -7 11 ffffff
7 -7 11 ffffff
8 -7 11 ffffff
9 -7 11 ffffff
10 -7 11 ffffff
11 -7 11 ffffff
12 -7 11 ffffff
13 -7 11 ffffff
0 -6 11 ffffff
1 -6 11 ffffff
2 -6 11 ffffff
3 -6 11 ffffff
4 -6 11 ffffff
5 -6 11 ffffff
6 -6 11 ffffff
7 -6 11 ffffff
8 -6 11 ffffff
9 -6 11 ffffff
10 -6 11 ffffff
11 -6 11 ffffff
12 -6 11 ffffff
13 -6 11 ffffff
14 -6 11 ffffff
0 -5 11 ffffff
1 -5 11 ffffff
2 -5 11 ffffff
3 -5 11 ffffff
4 -5 11 ffffff
5 -5 11 ffffff
6 -5 11 ffffff
7 -5 11 ffffff
8 -5 11 ffffff
9 -5 11 ffffff
10 -5 11 ffffff
11 -5 11 ffffff
12 -5 11 ffffff
13 -5 11 ffffff
14 -5 11 ffffff
0 -4 11 ffffff
1 -4 11 ffffff
2 -4 11 ffffff
3 -4 11 ffffff
4 -4 11 ffffff
5 -4 11 ffffff
6 -4 11 ffffff
7 -4 11 ffffff
8 -4 11 ffffff
9 -4 11 ffffff
10 -4 11 ffffff
11 -4 11 ffffff
12 -4 11 ffffff
13 -4 11 ffffff
14 -4 11 ffffff
0 -3 11 ffffff
1 -3 11 ffffff
2 -3 11 ffffff
3 -3 11 ffffff
4 -3 11 ffffff
5 -3 11 ffffff
6 -3 11 ffffff
7 -3 11 ffffff
8 -3 11 ffffff
9 -3 11 ffffff
10 -3 11 ffffff
11 -3 11 ffffff
12 -3 11 ffffff
13 -3 11 ffffff
14 -3 11 ffffff
0 -2 11 ffffff
1 -2 11 ffffff
2 -2 11 ffffff
3 -2 11 ffffff
4 -2 11 ffffff
5 -2 11 ffffff
6 -2 11 ffffff
7 -2 11 ffffff
8 -2 11 ffffff
9 -2 11 ffffff
10 -2 11 ffffff
11 -2 11 ffffff
12 -2 11 ffffff
13 -2 11 ffffff
14 -2 11 ffffff
0 -1 11 ffffff
1 -1 11 ffffff
2 -1 11 ffffff
3 -1 11 ffffff
4 -1 11 ffffff
5 -1 11 ffffff
6 -1 11 ffffff
7 -1 11 ffffff
8 -1 11 ffffff
9 -1 11 ffffff
10 -1 11 ffffff
11 -1 11 ffffff
12 -1 11 ffffff
13 -1 11 ffffff
14 -1 11 ffffff
0 -16 12 ffffff
1 -16 12 ffffff
0 -15 12 ffffff
1 -15 12 ffffff
2 -15 12 ffffff
3 -15 12 ffffff
4 -15 12 ffffff
5 -15 12 ffffff
0 -14 12 ffffff
1 -14 12 ffffff
2 -14 12 ffffff
3 -14 12 ffffff
4 -14 12 ffffff
5 -14 12 ffffff
6 -14 12 ffffff
7 -14 12 ffffff
0 -13 12 ffffff
1 -13 12 ffffff
2 -13 12 ffffff
3 -13 12 ffffff
4 -13 12 ffffff
5 -13 12 ffffff
6 -13 12 ffffff
7 -13 12 ffffff
8 -13 12 ffffff
9 -13 12 ffffff
0 -12 12 ffffff
1 -12 12 ffffff
2 -12 12 ffffff
3 -12 12 ffffff
4 -12 12 ffffff
5 -12 12 ffffff
6 -12 12 ffffff
7 -12 12 ffffff
8 -12 12 ffffff
9 -12 12 ffffff
10 -12 12 ffffff
0 -11 12 ffffff
1 -11 12 ffffff
2 -11 12 ffffff
3 -11 12 ffffff
4 -11 12 ffffff
5 -11 12 ffffff
6 -11 12 ffffff
7 -11 12 ffffff
8 -11 12 ffffff
9 -11 12 ffffff
10 -11 12 ffffff
11 -11 12 ffffff
0 -10 12 ffffff
1 -10 12 ffffff
2 -10 12 ffffff
3 -10 12 ffffff
4 -10 12 ffffff
5 -10 12 ffffff
6 -10 12 ffffff
7 -10 12 ffffff
8 -10 12 ffffff
9 -10 12 ffffff
10 -10 12 ffffff
11 -10 12 ffffff
12 -10 12 ffffff
0 -9 12 ffffff
1 -9 12 ffffff
2 -9 12 ffffff
3 -9 12 ffffff
4 -9 12 ffffff
5 -9 12 ffffff
6 -9 12 ffffff
7 -9 12 ffffff
8 -9 12 ffffff
9 -9 12 ffffff
10 -9 12 ffffff
11 -9 12 ffffff
12 -9 12 ffffff
0 -8 12 ffffff
1 -8 12 ffffff
2 -8 12 ffffff
3 -8 12 ffffff
4 -8 12 ffffff
5 -8 12 ffffff
6 -8 12 ffffff
7 -8 12 ffffff
8 -8 12 ffffff
9 -8 12 ffffff
10 -8 12 ffffff
11 -8 12 ffffff
12 -8 12 ffffff
13 -8 12 ffffff
0 -7 12 ffffff
1 -7 12 ffffff
2 -7 12 ffffff
3 -7 12 ffffff
4 -7 12 ffffff
5 -7 12 ffffff
6 -7 12 ffffff
7 -7 12 ffffff
8 -7 12 ffffff
9 -7 12 ffffff
10 -7 12 ffffff
11 -7 12 ffffff
12 -7 12 ffffff
13 -7 12 ffffff
0 -6 12 ffffff
1 -6 12 ffffff
2 -6 12 ffffff
3 -6 12 ffffff
4 -6 12 ffffff
5 -6 12 ffffff
6 -6 12 ffffff
7 -6 12 ffffff
8 -6 12 ffffff
9 -6 12 ffffff
10 -6 12 ffffff
11 -6 12 ffffff
12 -6 12 ffffff
13 -6 12 ffffff
14 -6 12 ffffff
0 -5 12 ffffff
1 -5 12 ffffff
2 -5 12 ffffff
3 -5 12 ffffff
4 -5 12 ffffff
5 -5 12 ffffff
6 -5 12 ffffff
7 -5 12 ffffff
8 -5 12 ffffff
9 -5 12 ffffff
10 -5 12 ffffff
11 -5 12 ffffff
12 -5 12 ffffff
13 -5 12 ffffff
14 -5 12 ffffff
0 -4 12 ffffff
1 -4 12 ffffff
2 -4 12 ffffff
3 -4 12 ffffff
4 -4 12 ffffff
5 -4 12 ffffff
6 -4 12 ffffff
7 -4 12 ffffff
8 -4 12 ffffff
9 -4 12 ffffff
10 -4 12 ffffff
11 -4 12 ffffff
12 -4 12 ffffff
13 -4 12 ffffff
14 -4 12 ffffff
0 -3 12 ffffff
1 -3 12 ffffff
2 -3 12 ffffff
3 -3 12 ffffff
4 -3 12 ffffff
5 -3 12 ffffff
6 -3 12 ffffff
7 -3 12 ffffff
8 -3 12 ffffff
9 -3 12 ffffff
10 -3 12 ffffff
11 -3 12 ffffff
12 -3 12 ffffff
13 -3 12 ffffff
14 -3 12 ffffff
0 -2 12 ffffff
1 -2 12 ffffff
2 -2 12 ffffff
3 -2 12 ffffff
4 -2 12 ffffff
5 -2 12 ffffff
6 -2 12 ffffff
7 -2 12 ffffff
8 -2 12 ffffff
9 -2 12 ffffff
10 -2 12 ffffff
11 -2 12 ffffff
12 -2 12 ffffff
13 -2 12 ffffff
14 -2 12 ffffff
15 -2 12 ffffff
0 -1 12 ffffff
1 -1 12 ffffff
2 -1 12 ffffff
3 -1 12 ffffff
4 -1 12 ffffff
5 -1 12 ffffff
6 -1 12 ffffff
7 -1 12 ffffff
8 -1 12 ffffff
9 -1 12 ffffff
10 -1 12 ffffff
11 -1 12 ffffff
12 -1 12 ffffff
13 -1 12 ffffff
14 -1 12 ffffff
15 -1 12 ffffff
0 -16 13 ffffff
1 -16 13 ffffff
2 -16 13 ffffff
3 -16 13 ffffff
0 -15 13 ffffff
1 -15 13 ffffff
2 -15 13 ffffff
3 -15 13 ffffff
4 -15 13 ffffff
5 -15 13 ffffff
6 -15 13 ffffff
0 -14 13 ffffff
1 -14 13 ffffff
2 -14 13 ffffff
3 -14 13 ffffff
4 -14 13 ffffff
5 -14 13 ffffff
6 -14 13 ffffff
7 -14 13 ffffff
8 -14 13 ffffff
0 -13 13 ffffff
1 -13 13 ffffff
2 -13 13 ffffff
3 -13 13 ffffff
4 -13 13 ffffff
5 -13 13 ffffff
6 -13 13 ffffff
7 -13 13 ffffff
8 -13 13 ffffff
9 -13 13 ffffff
0 -12 13 ffffff
1 -12 13 ffffff
2 -12 13 ffffff
3 -12 13 ffffff
4 -12 13 ffffff
5 -12 13 ffffff
6 -12 13 ffffff
7 -12 13 ffffff
8 -12 13 ffffff
9 -12 13 ffffff
10 -12 13 ffffff
0 -11 13 ffffff
1 -11 13 ffffff
2 -11 13 ffffff
3 -11 13 ffffff
4 -11 13 ffffff
5 -11 13 ffffff
6 -11 13 ffffff
7 -11 13 ffffff
8 -11 13 ffffff
9 -11 13 ffffff
10 -11 13 ffffff
11 -11 13 ffffff
0 -10 13 ffffff
1 -10 13 ffffff
2 -10 13 ffffff
3 -10 13 ffffff
4 -10 13 ffffff
5 -10 13 ffffff
6 -10 13 ffffff
7 -10 13 ffffff
8 -10 13 ffffff
9 -10 13 ffffff
10 -10 13 ffffff
11 -10 13 ffffff
12 -10 13 ffffff
0 -9 13 ffffff
1 -9 13 ffffff
2 -9 13 ffffff
3 -9 13 ffffff
4 -9 13 ffffff
5 -9 13 ffffff
6 -9 13 ffffff
7 -9 13 ffffff
8 -9 13 ffffff
9 -9 13 ffffff
10 -9 13 ffffff
11 -9 13 ffffff
12 -9 13 ffffff
13 -9 13 ffffff
0 -8 13 ffffff
1 -8 13 ffffff
2 -8 13 ffffff
3 -8 13 ffffff
4 -8 13 ffffff
5 -8 13 ffffff
6 -8 13 ffffff
7 -8 13 ffffff
8 -8 13 ffffff
9 -8 13 ffffff
10 -8 13 ffffff
11 -8 13 ffffff
12 -8 13 ffffff
13 -8 13 ffffff
0 -7 13 ffffff
1 -7 13 ffffff
2 -7 13 ffffff
3 -7 13 ffffff
4 -7 13 ffffff
5 -7 13 ffffff
6 -7 13 ffffff
7 -7 13 ffffff
8 -7 13 ffffff
9 -7 13 ffffff
10 -7 13 ffffff
11 -7 13 ffffff
12 -7 13 ffffff
13 -7 13 ffffff
14 -7 13 ffffff
0 -6 13 ffffff
1 -6 13 ffffff
2 -6 13 ffffff
3 -6 13 ffffff
4 -6 13 ffffff
5 -6 13 ffffff
6 -6 13 ffffff
7 -6 13 ffffff
8 -6 13 ffffff
9 -6 13 ffffff
10 -6 13 ffffff
11 -6 13 ffffff
12 -6 13 ffffff
13 -6 13 ffffff
14 -6 13 ffffff
0 -5 13 ffffff
1 -5 13 ffffff
2 -5 13 ffffff
3 -5 13 ffffff
4 -5 13 ffffff
5 -5 13 ffffff
6 -5 13 ffffff
7 -5 13 ffffff
8 -5 13 ffffff
9 -5 13 ffffff
10 -5 13 ffffff
11 -5 13 ffffff
12 -5 13 ffffff
13 -5 13 ffffff
14 -5 13 ffffff
0 -4 13 ffffff
1 -4 13 ffffff
2 -4 13 ffffff
3 -4 13 ffffff
4 -4 13 ffffff
5 -4 13 ffffff
6 -4 13 ffffff
7 -4 13 ffffff
8 -4 13 ffffff
9 -4 13 ffffff
10 -4 13 ffffff
11 -4 13 ffffff
12 -4 13 ffffff
13 -4 13 ffffff
14 -4 13 ffffff
15 -4 13 ffffff
0 -3 13 ffffff
1 -3 13 ffffff
2 -3 13 ffffff
3 -3 13 ffffff
4 -3 13 ffffff
5 -3 13 ffffff
6 -3 13 ffffff
7 -3 13 ffffff
8 -3 13 ffffff
9 -3 13 ffffff
10 -3 13 ffffff
11 -3 13 ffffff
12 -3 13 ffffff
13 -3 13 ffffff
14 -3 13 ffffff
15 -3 13 ffffff
0 -2 13 ffffff
1 -2 13 ffffff
2 -2 13 ffffff
3 -2 13 ffffff
4 -2 13 ffffff
5 -2 13 ffffff
6 -2 13 ffffff
7 -2 13 ffffff
8 -2 13 ffffff
9 -2 13 ffffff
10 -2 13 ffffff
11 -2 13 ffffff
12 -2 13 ffffff
13 -2 13 ffffff
14 -2 13 ffffff
15 -2 13 ffffff
0 -1 13 ffffff
1 -1 13 ffffff
2 -1 13 ffffff
3 -1 13 ffffff
4 -1 13 ffffff
5 -1 13 ffffff
6 -1 13 ffffff
7 -1 13 ffffff
8 -1 13 ffffff
9 -1 13 ffffff
10 -1 13 ffffff
11 -1 13 ffffff
12 -1 13 ffffff
13 -1 13 ffffff
14 -1 13 ffffff
15 -1 13 ffffff
0 -16 14 ffffff
1 -16 14 ffffff
2 -16 14 ffffff
3 -16 14 ffffff
0 -15 14 ffffff
1 -15 14 ffffff
2 -15 14 ffffff
3 -15 14 ffffff
4 -15 14 ffffff
5 -15 14 ffffff
6 -15 14 ffffff
0 -14 14 ffffff
1 -14 14 ffffff
2 -14 14 ffffff
3 -14 14 ffffff
4 -14 14 ffffff
5 -14 14 ffffff
6 -14 14 ffffff
7 -14 14 ffffff
8 -14 14 ffffff
0 -13 14 ffffff
1 -13 14 ffffff
2 -13 14 ffffff
3 -13 14 ffffff
4 -13 14 ffffff
5 -13 14 ffffff
6 -13 14 ffffff
7 -13 14 ffffff
8 -13 14 ffffff
9 -13 14 ffffff
0 -12 14 ffffff
1 -12 14 ffffff
2 -12 14 ffffff
3 -12 14 ffffff
4 -12 14 ffffff
5 -12 14 ffffff
6 -12 14 ffffff
7 -12 14 ffffff
8 -12 14 ffffff
9 -12 14 ffffff
10 -12 14 ffffff
0 -11 14 ffffff
1 -11 14 ffffff
2 -11 14 ffffff
3 -11 14 ffffff
4 -11 14 ffffff
5 -11 14 ffffff
6 -11 14 ffffff
7 -11 14 ffffff
8 -11 14 ffffff
9 -11 14 ffffff
10 -11 14 ffffff
11 -11 14 ffffff
0 -10 14 ffffff
1 -10 14 ffffff
2 -10 14 ffffff
3 -10 14 ffffff
4 -10 14 ffffff
5 -10 14 ffffff
6 -10 14 ffffff
7 -10 14 ffffff
8 -10 14 ffffff
9 -10 14 ffffff
10 -10 14 ffffff
11 -10 14 ffffff
12 -10 14 ffffff
0 -9 14 ffffff
1 -9 14 ffffff
2 -9 14 ffffff
3 -9 14 ffffff
4 -9 14 ffffff
5 -9 14 ffffff
6 -9 14 ffffff
7 -9 14 ffffff
8 -9 14 ffffff
9 -9 14 ffffff
10 -9 14 ffffff
11 -9 14 ffffff
12 -9 14 ffffff
13 -9 14 ffffff
0 -8 14 ffffff
1 -8 14 ffffff
2 -8 14 ffffff
3 -8 14 ffffff
4 -8 14 ffffff
5 -8 14 ffffff
6 -8 14 ffffff
7 -8 14 ffffff
8 -8 14 ffffff
9 -8 14 ffffff
10 -8 14 ffffff
11 -8 14 ffffff
12 -8 14 ffffff
13 -8 14 ffffff
0 -7 14 ffffff
1 -7 14 ffffff
2 -7 14 ffffff
3 -7 14 ffffff
4 -7 14 ffffff
5 -7 14 ffffff
6 -7 14 ffffff
7 -7 14 ffffff
8 -7 14 ffffff
9 -7 14 ffffff
10 -7 14 ffffff
11 -7 14 ffffff
12 -7 14 ffffff
13 -7 14 ffffff
14 -7 14 ffffff
0 -6 14 ffffff
1 -6 14 ffffff
2 -6 14 ffffff
3 -6 14 ffffff
4 -6 14 ffffff
5 -6 14 ffffff
6 -6 14 ffffff
7 -6 14 ffffff
8 -6 14 ffffff
9 -6 14 ffffff
10 -6 14 ffffff
11 -6 14 ffffff
12 -6 14 ffffff
13 -6 14 ffffff
14 -6 14 ffffff
0 -5 14 ffffff
1 -5 14 ffffff
2 -5 14 ffffff
3 -5 14 ffffff
4 -5 14 ffffff
5 -5 14 ffffff
6 -5 14 ffffff
7 -5 14 ffffff
8 -5 14 ffffff
9 -5 14 ffffff
10 -5 14 ffffff
11 -5 14 ffffff
12 -5 14 ffffff
13 -5 14 ffffff
14 -5 14 ffffff
0 -4 14 ffffff
1 -4 14 ffffff
2 -4 14 ffffff
3 -4 14 ffffff
4 -4 14 ffffff
5 -4 14 ffffff
6 -4 14 ffffff
7 -4 14 ffffff
8 -4 14 ffffff
9 -4 14 ffffff
10 -4 14 ffffff
11 -4 14 ffffff
12 -4 14 ffffff
13 -4 14 ffffff
14 -4 14 ffffff
15 -4 14 ffffff
0 -3 14 ffffff
1 -3 14 ffffff
2 -3 14 ffffff
3 -3 14 ffffff
4 -3 14 ffffff
5 -3 14 ffffff
6 -3 14 ffffff
7 -3 14 ffffff
8 -3 14 ffffff
9 -3 14 ffffff
10 -3 14 ffffff
11 -3 14 ffffff
12 -3 14 ffffff
13 -3 14 ffffff
14 -3 14 ffffff
15 -3 14 ffffff
0 -2 14 ffffff
1 -2 14 ffffff
2 -2 14 ffffff
3 -2 14 ffffff
4 -2 14 ffffff
5 -2 14 ffffff
6 -2 14 ffffff
7 -2 14 ffffff
8 -2 14 ffffff
9 -2 14 ffffff
10 -2 14 ffffff
11 -2 14 ffffff
12 -2 14 ffffff
13 -2 14 ffffff
14 -2 14 ffffff
15 -2 14 ffffff
0 -1 14 ffffff
1 -1 14 ffffff
2 -1 14 ffffff
3 -1 14 ffffff
4 -1 14 ffffff
5 -1 14 ffffff
6 -1 14 ffffff
7 -1 14 ffffff
8 -1 14 ffffff
9 -1 14 ffffff
10 -1 14 ffffff
11 -1 14 ffffff
12 -1 14 ffffff
13 -1 14 ffffff
14 -1 14 ffffff
15 -1 14 ffffff
0 -16 15 ffffff
1 -16 15 ffffff
2 -16 15 ffffff
3 -16 15 ffffff
0 -15 15 ffffff
1 -15 15 ffffff
2 -15 15 ffffff
3 -15 15 ffffff
4 -15 15 ffffff
5 -15 15 ffffff
6 -15 15 ffffff
0 -14 15 ffffff
1 -14 15 ffffff
2 -14 15 ffffff
3 -14 15 ffffff
4 -14 15 ffffff
5 -14 15 ffffff
6 -14 15 ffffff
7 -14 15 ffffff
8 -14 15 ffffff
0 -13 15 ffffff
1 -13 15 ffffff
2 -13 15 ffffff
3 -13 15 ffffff
4 -13 15 ffffff
5 -13 15 ffffff
6 -13 15 ffffff
7 -13 15 ffffff
8 -13 15 ffffff
9 -13 15 ffffff
0 -12 15 ffffff
1 -12 15 ffffff
2 -12 15 ffffff
3 -12 15 ffffff
4 -12 15 ffffff
5 -12 15 ffffff
6 -12 15 ffffff
7 -12 15 ffffff
8 -12 15 ffffff
9 -12 15 ffffff
10 -12 15 ffffff
0 -11 15 ffffff
1 -11 15 ffffff
2 -11 15 ffffff
3 -11 15 ffffff
4 -11 15 ffffff
5 -11 15 ffffff
6 -11 15 ffffff
7 -11 15 ffffff
8 -11 15 ffffff
9 -11 15 ffffff
10 -11 15 ffffff
11 -11 15 ffffff
0 -10 15 ffffff
1 -10 15 ffffff
2 -10 15 ffffff
3 -10 15 ffffff
4 -10 15 ffffff
5 -10 15 ffffff
6 -10 15 ffffff
7 -10 15 ffffff
8 -10 15 ffffff
9 -10 15 ffffff
10 -10 15 ffffff
11 -10 15 ffffff
12 -10 15 ffffff
0 -9 15 ffffff
1 -9 15 ffffff
2 -9 15 ffffff
3 -9 15 ffffff
4 -9 15 ffffff
5 -9 15 ffffff
6 -9 15 ffffff
7 -9 15 ffffff
8 -9 15 ffffff
9 -9 15 ffffff
10 -9 15 ffffff
11 -9 15 ffffff
12 -9 15 ffffff
13 -9 15 ffffff
0 -8 15 ffffff
1 -8 15 ffffff
2 -8 15 ffffff
3 -8 15 ffffff
4 -8 15 ffffff
5 -8 15 ffffff
6 -8 15 ffffff
7 -8 15 ffffff
8 -8 15 ffffff
9 -8 15 ffffff
10 -8 15 ffffff
11 -8 15 ffffff
12 -8 15 ffffff
13 -8 15 ffffff
0 -7 15 ffffff
1 -7 15 ffffff
2 -7 15 ffffff
3 -7 15 ffffff
4 -7 15 ffffff
5 -7 15 ffffff
6 -7 15 ffffff
7 -7 15 ffffff
8 -7 15 ffffff
9 -7 15 ffffff
10 -7 15 ffffff
11 -7 15 ffffff
12 -7 15 ffffff
13 -7 15 ffffff
14 -7 15 ffffff
0 -6 15 ffffff
1 -6 15 ffffff
2 -6 15 ffffff
3 -6 15 ffffff
4 -6 15 ffffff
5 -6 15 ffffff
6 -6 15 ffffff
7 -6 15 ffffff
8 -6 15 ffffff
9 -6 15 ffffff
10 -6 15 ffffff
11 -6 15 ffffff
12 -6 15 ffffff
13 -6 15 ffffff
14 -6 15 ffffff
0 -5 15 ffffff
1 -5 15 ffffff
2 -5 15 ffffff
3 -5 15 ffffff
4 -5 15 ffffff
5 -5 15 ffffff
6 -5 15 ffffff
7 -5 15 ffffff
8 -5 15 ffffff
9 -5 15 ffffff
10 -5 15 ffffff
11 -5 15 ffffff
12 -5 15 ffffff
13 -5 15 ffffff
14 -5 15 ffffff
0 -4 15 ffffff
1 -4 15 ffffff
2 -4 15 ffffff
3 -4 15 ffffff
4 -4 15 ffffff
5 -4 15 ffffff
6 -4 15 ffffff
7 -4 15 ffffff
8 -4 15 ffffff
9 -4 15 ffffff
10 -4 15 ffffff
11 -4 15 ffffff
12 -4 15 ffffff
13 -4 15 ffffff
14 -4 15 ffffff
15 -4 15 ffffff
0 -3 15 ffffff
1 -3 15 ffffff
2 -3 15 ffffff
3 -3 15 ffffff
4 -3 15 ffffff
5 -3 15 ffffff
6 -3 15 ffffff
7 -3 15 ffffff
8 -3 15 ffffff
9 -3 15 ffffff
10 -3 15 ffffff
11 -3 15 ffffff
12 -3 15 ffffff
13 -3 15 ffffff
14 -3 15 ffffff
15 -3 15 ffffff
0 -2 15 ffffff
1 -2 15 ffffff
2 -2 15 ffffff
3 -2 15 ffffff
4 -2 15 ffffff
5 -2 15 ffffff
6 -2 15 ffffff
7 -2 15 ffffff
8 -2 15 ffffff
9 -2 15 ffffff
10 -2 15 ffffff
11 -2 15 ffffff
12 -2 15 ffffff
13 -2 15 ffffff
14 -2 15 ffffff
15 -2 15 ffffff
0 -1 15 ffffff
1 -1 15 ffffff
2 -1 15 ffffff
3 -1 15 ffffff
4 -1 15 ffffff
5 -1 15 ffffff
6 -1 15 ffffff
7 -1 15 ffffff
8 -1 15 ffffff
9 -1 15 ffffff
10 -1 15 ffffff
11 -1 15 ffffff
12 -1 15 ffffff
13 -1 15 ffffff
14 -1 15 ffffff
15 -1 15 ffffff
-3 0 0 ffffff
-2 0 0 ffffff
-1 0 0 ffffff
-3 1 0 ffffff
-2 1 0 ffffff
-1 1 0 ffffff
-2 2 0 ffffff
-1 2 0 ffffff
-6 0 1 ffffff
-5 0 1 ffffff
-4 0 1 ffffff
-3 0 1 ffffff
-2 0 1 ffffff
-1 0 1 ffffff
-6 1 1 ffffff
-5 1 1 ffffff
-4 1 1 ffffff
-3 1 1 ffffff
-2 1 1 ffffff
-1 1 1 ffffff
-5 2 1 ffffff
-4 2 1 ffffff
-3 2 1 ffffff
-2 2 1 ffffff
-1 2 1 ffffff
-5 3 1 ffffff
-4 3 1 ffffff
-3 3 1 ffffff
-2 3 1 ffffff
-1 3 1 ffffff
-4 4 1 ffffff
-3 4 1 ffffff
-2 4 1 ffffff
-1 4 1 ffffff
-2 5 1 ffffff
-1 5 1 ffffff
-8 0 2 ffffff
-7 0 2 ffffff
-6 0 2 ffffff
-5 0 2 ffffff
-4 0 2 ffffff
-3 0 2 ffffff
-2 0 2 ffffff
-1 0 2 ffffff
-8 1 2 ffffff
-7 1 2 ffffff
-6 1 2 ffffff
-5 1 2 ffffff
-4 1 2 ffffff
-3 1 2 ffffff
-2 1 2 ffffff
-1 1 2 ffffff
-7 2 2 ffffff
-6 2 2 ffffff
-5 2 2 ffffff
-4 2 2 ffffff
-3 2 2 ffffff
-2 2 2 ffffff
-1 2 2 ffffff
-7 3 2 ffffff
-6 3 2 ffffff
-5 3 2 ffffff
-4 3 2 ffffff
-3 3 2 ffffff
-2 3 2 ffffff
-1 3 2 ffffff
-6 4 2 ffffff
-5 4 2 ffffff
-4 4 2 ffffff
-3 4 2 ffffff
-2 4 2 ffffff
-1 4 2 ffffff
-5 5 2 ffffff
-4 5 2 ffffff
-3 5 2 ffffff
-2 5 2 ffffff
-1 5 2 ffffff
-4 6 2 ffffff
-3 6 2 ffffff
-2 6 2 ffffff
-1 6 2 ffffff
-2 7 2 ffffff
-1 7 2 ffffff
-9 0 3 ffffff
-8 0 3 ffffff
-7 0 3 ffffff
-6 0 3 ffffff
-5 0 3 ffffff
-4 0 3 ffffff
-3 0 3 ffffff
-2 0 3 ffffff
-1 0 3 ffffff
-9 1 3 ffffff
-8 1 3 ffffff
-7 1 3 ffffff
-6 1 3 ffffff
-5 1 3 ffffff
-4 1 3 ffffff
-3 1 3 ffffff
-2 1 3 ffffff
-1 1 3 ffffff
-9 2 3 ffffff
-8 2 3 ffffff
-7 2 3 ffffff
-6 2 3 ffffff
-5 2 3 ffffff
-4 2 3 ffffff
-3 2 3 ffffff
-2 2 3 ffffff
-1 2 3 ffffff
-8 3 3 ffffff
-7 3 3 ffffff
-6 3 3 ffffff
-5 3 3 ffffff
-4 3 3 ffffff
-3 3 3 ffffff
-2 3 3 ffffff
-1 3 3 ffffff
-8 4 3 ffffff
-7 4 3 ffffff
-6 4 3 ffffff
-5 4 3 ffffff
-4 4 3 ffffff
-3 4 3 ffffff
-2 4 3 ffffff
-1 4 3 ffffff
-7 5 3 ffffff
-6 5 3 ffffff
-5 5 3 ffffff
-4 5 3 ffffff
-3 5 3 ffffff
-2 5 3 ffffff
-1 5 3 ffffff
-6 6 3 ffffff
-5 6 3 ffffff
-4 6 3 ffffff
-3 6 3 ffffff
-2 6 3 ffffff
-1 6 3 ffffff
-5 7 3 ffffff
-4 7 3 ffffff
-3 7 3 ffffff
-2 7 3 ffffff
-1 7 3 ffffff
-3 8 3 ffffff
-2 8 3 ffffff
-1 8 3 ffffff
-10 0 4 ffffff
-9 0 4 ffffff
-8 0 4 ffffff
-7 0 4 ffffff
-6 0 4 ffffff
-5 0 4 ffffff
-4 0 4 ffffff
-3 0 4 ffffff
-2 0 4 ffffff
-1 0 4 ffffff
-10 1 4 ffffff
-9 1 4 ffffff
-8 1 4 ffffff
-7 1 4 ffffff
-6 1 4 ffffff
-5 1 4 ffffff
-4 1 4 ffffff
-3 1 4 ffffff
-2 1 4 ffffff
-1 1 4 ffffff
-10 2 4 ffffff
-9 2 4 ffffff
-8 2 4 ffffff
-7 2 4 ffffff
-6 2 4 ffffff
-5 2 4 ffffff
-4 2 4 ffffff
-3 2 4 ffffff
-2 2 4 ffffff
-1 2 4 ffffff
-10 3 4 ffffff
-9 3 4 ffffff
-8 3 4 ffffff
-7 3 4 ffffff
-6 3 4 ffffff
-5 3 4 ffffff
-4 3 4 ffffff
-3 3 4 ffffff
-2 3 4 ffffff
-1 3 4 ffffff
-9 4 4 ffffff
-8 4 4 ffffff
-7 4 4 ffffff
-6 4 4 ffffff
-5 4 4 ffffff
-4 4 4 ffffff
-3 4 4 ffffff
-2 4 4 ffffff
-1 4 4 ffffff
-8 5 4 ffffff
-7 5 4 ffffff
-6 5 4 ffffff
-5 5 4 ffffff
-4 5 4 ffffff
-3 5 4 ffffff
-2 5 4 ffffff
-1 5 4 ffffff
-8 6 4 ffffff
-7 6 4 ffffff
-6 6 4 ffffff
-5 6 4 ffffff
-4 6 4 ffffff
-3 6 4 ffffff
-2 6 4 ffffff
-1 6 4 ffffff
-7 7 4 ffffff
-6 7 4 ffffff
-5 7 4 ffffff
-4 7 4 ffffff
-3 7 4 ffffff
-2 7 4 ffffff
-1 7 4 ffffff
-5 8 4 ffffff
-4 8 4 ffffff
-3 8 4 ffffff
-2 8 4 ffffff
-1 8 4 ffffff
-4 9 4 ffffff
-3 9 4 ffffff
-2 9 4 ffffff
-1 9 4 ffffff
-11 0 5 ffffff
-10 0 5 ffffff
-9 0 5 ffffff
-8 0 5 ffffff
-7 0 5 ffffff
-6 0 5 ffffff
-5 0 5 ffffff
-4 0 5 ffffff
-3 0 5 ffffff
-2 0 5 ffffff
-1 0 5 ffffff
-11 1 5 ffffff
-10 1 5 ffffff
-9 1 5 ffffff
-8 1 5 ffffff
-7 1 5 ffffff
-6 1 5 ffffff
-5 1 5 ffffff
-4 1 5 ffffff
-3 1 5 ffffff
-2 1 5 ffffff
-1 1 5 ffffff
-11 2 5 ffffff
-10 2 5 ffffff
-9 2 5 ffffff
-8 2 5 ffffff
-7 2 5 ffffff
-6 2 5 ffffff
-5 2 5 ffffff
-4 2 5 ffffff
-3 2 5 ffffff
-2 2 5 ffffff
-1 2 5 ffffff
-10 3 5 ffffff
-9 3 5 ffffff
-8 3 5 ffffff
-7 3 5 ffffff
-6 3 5 ffffff
-5 3 5 ffffff
-4 3 5 ffffff
-3 3 5 ffffff
-2 3 5 ffffff
-1 3 5 ffffff
-10 4 5 ffffff
-9 4 5 ffffff
-8 4 5 ffffff
-7 4 5 ffffff
-6 4 5 ffffff
-5 4 5 ffffff
-4 4 5 ffffff
-3 4 5 ffffff
-2 4 5 ffffff
-1 4 5 ffffff
-10 5 5 ffffff
-9 5 5 ffffff
-8 5 5 ffffff
-7 5 5 ffffff
-6 5 5 ffffff
-5 5 5 ffffff
-4 5 5 ffffff
-3 5 5 ffffff
-2 5 5 ffffff
-1 5 5 ffffff
-9 6 5 ffffff
-8 6 5 ffffff
-7 6 5 ffffff
-6 6 5 ffffff
-5 6 5 ffffff
-4 6 5 ffffff
-3 6 5 ffffff
-2 6 5 ffffff
-1 6 5 ffffff
-8 7 5 ffffff
-7 7 5 ffffff
-6 7 5 ffffff
-5 7 5 ffffff
-4 7 5 ffffff
-3 7 5 ffffff
-2 7 5 ffffff
-1 7 5 ffffff
-7 8 5 ffffff
-6 8 5 ffffff
-5 8 5 ffffff
-4 8 5 ffffff
-3 8 5 ffffff
-2 8 5 ffffff
-1 8 5 ffffff
-6 9 5 ffffff
-5 9 5 ffffff
-4 9 5 ffffff
-3 9 5 ffffff
-2 9 5 ffffff
-1 9 5 ffffff
-3 10 5 ffffff
-2 10 5 ffffff
-1 10 5 ffffff
-12 0 6 ffffff
-11 0 6 ffffff
-10 0 6 ffffff
-9 0 6 ffffff
-8 0 6 ffffff
-7 0 6 ffffff
-6 0 6 ffffff
-5 0 6 ffffff
-4 0 6 ffffff
-3 0 6 ffffff
-2 0 6 ffffff
-1 0 6 ffffff
-12 1 6 ffffff
-11 1 6 ffffff
-10 1 6 ffffff
-9 1 6 ffffff
-8 1 6 ffffff
-7 1 6 ffffff
-6 1 6 ffffff
-5 1 6 ffffff
-4 1 6 ffffff
-3 1 6 ffffff
-2 1 6 ffffff
-1 1 6 ffffff
-12 2 6 ffffff
-11 2 6 ffffff
-10 2 6 ffffff
-9 2 6 ffffff
-8 2 6 ffffff
-7 2 6 ffffff
-6 2 6 ffffff
-5 2 6 ffffff
-4 2 6 ffffff
-3 2 6 ffffff
-2 2 6 ffffff
-1 2 6 ffffff
-11 3 6 ffffff
-10 3 6 ffffff
-9 3 6 ffffff
-8 3 6 ffffff
-7 3 6 ffffff
-6 3 6 ffffff
-5 3 6 ffffff
-4 3 6 ffffff
-3 3 6 ffffff
-2 3 6 ffffff
-1 3 6 ffffff
-11 4 6 ffffff
-10 4 6 ffffff
-9 4 6 ffffff
-8 4 6 ffffff
-7 4 6 ffffff
-6 4 6 ffffff
-5 4 6 ffffff
-4 4 6 ffffff
-3 4 6 ffffff
-2 4 6 ffffff
-1 4 6 ffffff
-10 5 6 ffffff
-9 5 6 ffffff
-8 5 6 ffffff
-7 5 6 ffffff
-6 5 6 ffffff
-5 5 6 ffffff
-4 5 6 ffffff
-3 5 6 ffffff
-2 5 6 ffffff
-1 5 6 ffffff
-10 6 6 ffffff
-9 6 6 ffffff
-8 6 6 ffffff
-7 6 6 ffffff
-6 6 6 ffffff
-5 6 6 ffffff
-4 6 6 ffffff
-3 6 6 ffffff
-2 6 6 ffffff
-1 6 6 ffffff
-9 7 6 ffffff
-8 7 6 ffffff
-7 7 6 ffffff
-6 7 6 ffffff
-5 7 6 ffffff
-4 7 6 ffffff
-3 7 6 ffffff
-2 7 6 ffffff
-1 7 6 ffffff
-8 8 6 ffffff
-7 8 6 ffffff
-6 8 6 ffffff
-5 8 6 ffffff
-4 8 6 ffffff
-3 8 6 ffffff
-2 8 6 ffffff
-1 8 6 ffffff
-7 9 6 ffffff
-6 9 6 ffffff
-5 9 6 ffffff
-4 9 6 ffffff
-3 9 6 ffffff
-2 9 6 ffffff
-1 9 6 ffffff
-5 10 6 ffffff
-4 10 6 ffffff
-3 10 6 ffffff
-2 10 6 ffffff
-1 10 6 ffffff
-3 11 6 ffffff
-2 11 6 ffffff
-1 11 6 ffffff
-13 0 7 ffffff
-12 0 7 ffffff
-11 0 7 ffffff
-10 0 7 ffffff
-9 0 7 ffffff
-8 0 7 ffffff
-7 0 7 ffffff
-6 0 7 ffffff
-5 0 7 ffffff
-4 0 7 ffffff
-3 0 7 ffffff
-2 0 7 ffffff
-1 0 7 ffffff
-12 1 7 ffffff
-11 1 7 ffffff
-10 1 7 ffffff
-9 1 7 ffffff
-8 1 7 ffffff
-7 1 7 ffffff
-6 1 7 ffffff
-5 1 7 ffffff
-4 1 7 ffffff
-3 1 7 ffffff
-2 1 7 ffffff
-1 1 7 ffffff
-12 2 7 ffffff
-11 2 7 ffffff
-10 2 7 ffffff
-9 2 7 ffffff
-8 2 7 ffffff
-7 2 7 ffffff
-6 2 7 ffffff
-5 2 7 ffffff
-4 2 7 ffffff
-3 2 7 ffffff
-2 2 7 ffffff
-1 2 7 ffffff
-12 3 7 ffffff
-11 3 7 ffffff
-10 3 7 ffffff
-9 3 7 ffffff
-8 3 7 ffffff
-7 3 7 ffffff
-6 3 7 ffffff
-5 3 7 ffffff
-4 3 7 ffffff
-3 3 7 ffffff
-2 3 7 ffffff
-1 3 7 ffffff
-12 4 7 ffffff
-11 4 7 ffffff
-10 4 7 ffffff
-9 4 7 ffffff
-8 4 7 ffffff
-7 4 7 ffffff
-6 4 7 ffffff
-5 4 7 ffffff
-4 4 7 ffffff
-3 4 7 ffffff
-2 4 7 ffffff
-1 4 7 ffffff
-11 5 7 ffffff
-10 5 7 ffffff
-9 5 7 ffffff
-8 5 7 ffffff
-7 5 7 ffffff
-6 5 7 ffffff
-5 5 7 ffffff
-4 5 7 ffffff
-3 5 7 ffffff
-2 5 7 ffffff
-1 5 7 ffffff
-11 6 7 ffffff
-10 6 7 ffffff
-9 6 7 ffffff
-8 6 7 ffffff
-7 6 7 ffffff
-6 6 7 ffffff
-5 6 7 ffffff
-4 6 7 ffffff
-3 6 7 ffffff
-2 6 7 ffffff
-1 6 7 ffffff
-10 7 7 ffffff
-9 7 7 ffffff
-8 7 7 ffffff
-7 7 7 ffffff
-6 7 7 ffffff
-5 7 7 ffffff
-4 7 7 ffffff
-3 7 7 ffffff
-2 7 7 ffffff
-1 7 7 ffffff
-9 8 7 ffffff
-8 8 7 ffffff
-7 8 7 ffffff
-6 8 7 ffffff
-5 8 7 ffffff
-4 8 7 ffffff
-3 8 7 ffffff
-2 8 7 ffffff
-1 8 7 ffffff
-8 9 7 ffffff
-7 9 7 ffffff
-6 9 7 ffffff
-5 9 7 ffffff
-4 9 7 ffffff
-3 9 7 ffffff
-2 9 7 ffffff
-1 9 7 ffffff
-7 10 7 ffffff
-6 10 7 ffffff
-5 10 7 ffffff
-4 10 7 ffffff
-3 10 7 ffffff
-2 10 7 ffffff
-1 10 7 ffffff
-5 11 7 ffffff
-4 11 7 ffffff
-3 11 7 ffffff
-2 11 7 ffffff
-1 11 7 ffffff
-1 12 7 ffffff
-13 0 8 ffffff
-12 0 8 ffffff
-11 0 8 ffffff
-10 0 8 ffffff
-9 0 8 ffffff
-8 0 8 ffffff
-7 0 8 ffffff
-6 0 8 ffffff
-5 0 8 ffffff
-4 0 8 ffffff
-3 0 8 ffffff
-2 0 8 ffffff
-1 0 8 ffffff
-13 1 8 ffffff
-12 1 8 ffffff
-11 1 8 ffffff
-10 1 8 ffffff
-9 1 8 ffffff
-8 1 8 ffffff
-7 1 8 ffffff
-6 1 8 ffffff
-5 1 8 ffffff
-4 1 8 ffffff
-3 1 8 ffffff
-2 1 8 ffffff
-1 1 8 ffffff
-13 2 8 ffffff
-12 2 8 ffffff
-11 2 8 ffffff
-10 2 8 ffffff
-9 2 8 ffffff
-8 2 8 ffffff
-7 2 8 ffffff
-6 2 8 ffffff
-5 2 8 ffffff
-4 2 8 ffffff
-3 2 8 ffffff
-2 2 8 ffffff
-1 2 8 ffffff
-13 3 8 ffffff
-12 3 8 ffffff
-11 3 8 ffffff
-10 3 8 ffffff
-9 3 8 ffffff
-8 3 8 ffffff
-7 3 8 ffffff
-6 3 8 ffffff
-5 3 8 ffffff
-4 3 8 ffffff
-3 3 8 ffffff
-2 3 8 ffffff
-1 3 8 ffffff
-12 4 8 ffffff
-11 4 8 ffffff
-10 4 8 ffffff
-9 4 8 ffffff
-8 4 8 ffffff
-7 4 8 ffffff
-6 4 8 ffffff
-5 4 8 ffffff
-4 4 8 ffffff
-3 4 8 ffffff
-2 4 8 ffffff
-1 4 8 ffffff
-12 5 8 ffffff
-11 5 8 ffffff
-10 5 8 ffffff
-9 5 8 ffffff
-8 5 8 ffffff
-7 5 8 ffffff
-6 5 8 ffffff
-5 5 8 ffffff
-4 5 8 ffffff
-3 5 8 ffffff
-2 5 8 ffffff
-1 5 8 ffffff
-11 6 8 ffffff
-10 6 8 ffffff
-9 6 8 ffffff
-8 6 8 ffffff
-7 6 8 ffffff
-6 6 8 ffffff
-5 6 8 ffffff
-4 6 8 ffffff
-3 6 8 ffffff
-2 6 8 ffffff
-1 6 8 ffffff
-11 7 8 ffffff
-10 7 8 ffffff
-9 7 8 ffffff
-8 7 8 ffffff
-7 7 8 ffffff
-6 7 8 ffffff
-5 7 8 ffffff
-4 7 8 ffffff
-3 7 8 ffffff
-2 7 8 ffffff
-1 7 8 ffffff
-10 8 8 ffffff
-9 8 8 ffffff
-8 8 8 ffffff
-7 8 8 ffffff
-6 8 8 ffffff
-5 8 8 ffffff
-4 8 8 ffffff
-3 8 8 ffffff
-2 8 8 ffffff
-1 8 8 ffffff
-9 9 8 ffffff
-8 9 8 ffffff
-7 9 8 ffffff
-6 9 8 ffffff
-5 9 8 ffffff
-4 9 8 ffffff
-3 9 8 ffffff
-2 9 8 ffffff
-1 9 8 ffffff
-8 10 8 ffffff
-7 10 8 ffffff
-6 10 8 ffffff
-5 10 8 ffffff
-4 10 8 ffffff
-3 10 8 ffffff
-2 10 8 ffffff
-1 10 8 ffffff
-6 11 8 ffffff
-5 11 8 ffffff
-4 11 8 ffffff
-3 11 8 ffffff
-2 11 8 ffffff
-1 11 8 ffffff
-4 12 8 ffffff
-3 12 8 ffffff
-2 12 8 ffffff
-1 12 8 ffffff
-14 0 9 ffffff
-13 0 9 ffffff
-12 0 9 ffffff
-11 0 9 ffffff
-10 0 9 ffffff
-9 0 9 ffffff
-8 0 9 ffffff
-7 0 9 ffffff
-6 0 9 ffffff
-5 0 9 ffffff
-4 0 9 ffffff
-3 0 9 ffffff
-2 0 9 ffffff
-1 0 9 ffffff
-14 1 9 ffffff
-13 1 9 ffffff
-12 1 9 ffffff
-11 1 9 ffffff
-10 1 9 ffffff
-9 1 9 ffffff
-8 1 9 ffffff
-7 1 9 ffffff
-6 1 9 ffffff
-5 1 9 ffffff
-4 1 9 ffffff
-3 1 9 ffffff
-2 1 9 ffffff
-1 1 9 ffffff
-13 2 9 ffffff
-12 2 9 ffffff
-11 2 9 ffffff
-10 2 9 ffffff
-9 2 9 ffffff
-8 2 9 ffffff
-7 2 9 ffffff
-6 2 9 ffffff
-5 2 9 ffffff
-4 2 9 ffffff
-3 2 9 ffffff
-2 2 9 ffffff
-1 2 9 ffffff
-13 3 9 ffffff
-12 3 9 ffffff
-11 3 9 ffffff
-10 3 9 ffffff
-9 3 9 ffffff
-8 3 9 ffffff
-7 3 9 ffffff
-6 3 9 ffffff
-5 3 9 ffffff
-4 3 9 ffffff
-3 3 9 ffffff
-2 3 9 ffffff
-1 3 9 ffffff
-13 4 9 ffffff
-12 4 9 ffffff
-11 4 9 ffffff
-10 4 9 ffffff
-9 4 9 ffffff
-8 4 9 ffffff
-7 4 9 ffffff
-6 4 9 ffffff
-5 4 9 ffffff
-4 4 9 ffffff
-3 4 9 ffffff
-2 4 9 ffffff
-1 4 9 ffffff
-12 5 9 ffffff
-11 5 9 ffffff
-10 5 9 ffffff
-9 5 9 ffffff
-8 5 9 ffffff
-7 5 9 ffffff
-6 5 9 ffffff
-5 5 9 ffffff
-4 5 9 ffffff
-3 5 9 ffffff
-2 5 9 ffffff
-1 5 9 ffffff
-12 6 9 ffffff
-11 6 9 ffffff
-10 6 9 ffffff
-9 6 9 ffffff
-8 6 9 ffffff
-7 6 9 ffffff
-6 6 9 ffffff
-5 6 9 ffffff
-4 6 9 ffffff
-3 6 9 ffffff
-2 6 9 ffffff
-1 6 9 ffffff
-11 7 9 ffffff
-10 7 9 ffffff
-9 7 9 ffffff
-8 7 9 ffffff
-7 7 9 ffffff
-6 7 9 ffffff
-5 7 9 ffffff
-4 7 9 ffffff
-3 7 9 ffffff
-2 7 9 ffffff
-1 7 9 ffffff
-10 8 9 ffffff
-9 8 9 ffffff
-8 8 9 ffffff
-7 8 9 ffffff
-6 8 9 ffffff
-5 8 9 ffffff
-4 8 9 ffffff
-3 8 9 ffffff
-2 8 9 ffffff
-1 8 9 ffffff
-10 9 9 ffffff
-9 9 9 ffffff
-8 9 9 ffffff
-7 9 9 ffffff
-6 9 9 ffffff
-5 9 9 ffffff
-4 9 9 ffffff
-3 9 9 ffffff
-2 9 9 ffffff
-1 9 9 ffffff
-8 10 9 ffffff
-7 10 9 ffffff
-6 10 9 ffffff
-5 10 9 ffffff
-4 10 9 ffffff
-3 10 9 ffffff
-2 10 9 ffffff
-1 10 9 ffffff
-7 11 9 ffffff
-6 11 9 ffffff
-5 11 9 ffffff
-4 11 9 ffffff
-3 11 9 ffffff
-2 11 9 ffffff
-1 11 9 ffffff
-5 12 9 ffffff
-4 12 9 ffffff
-3 12 9 ffffff
-2 12 9 ffffff
-1 12 9 ffffff
-2 13 9 ffffff
-1 13 9 ffffff
-14 0 10 ffffff
-13 0 10 ffffff
-12 0 10 ffffff
-11 0 10 ffffff
-10 0 10 ffffff
-9 0 10 ffffff
-8 0 10 ffffff
-7 0 10 ffffff
-6 0 10 ffffff
-5 0 10 ffffff
-4 0 10 ffffff
-3 0 10 ffffff
-2 0 10 ffffff
-1 0 10 ffffff
-14 1 10 ffffff
-13 1 10 ffffff
-12 1 10 ffffff
-11 1 10 ffffff
-10 1 10 ffffff
-9 1 10 ffffff
-8 1 10 ffffff
-7 1 10 ffffff
-6 1 10 ffffff
-5 1 10 ffffff
-4 1 10 ffffff
-3 1 10 ffffff
-2 1 10 ffffff
-1 1 10 ffffff
-14 2 10 ffffff
-13 2 10 ffffff
-12 2 10 ffffff
-11 2 10 ffffff
-10 2 10 ffffff
-9 2 10 ffffff
-8 2 10 ffffff
-7 2 10 ffffff
-6 2 10 ffffff
-5 2 10 ffffff
-4 2 10 ffffff
-3 2 10 ffffff
-2 2 10 ffffff
-1 2 10 ffffff
-13 3 10 ffffff
-12 3 10 ffffff
-11 3 10 ffffff
-10 3 10 ffffff
-9 3 10 ffffff
-8 3 10 ffffff
-7 3 10 ffffff
-6 3 10 ffffff
-5 3 10 ffffff
-4 3 10 ffffff
-3 3 10 ffffff
-2 3 10 ffffff
-1 3 10 ffffff
-13 4 10 ffffff
-12 4 10 ffffff
-11 4 10 ffffff
-10 4 10 ffffff
-9 4 10 ffffff
-8 4 10 ffffff
-7 4 10 ffffff
-6 4 10 ffffff
-5 4 10 ffffff
-4 4 10 ffffff
-3 4 10 ffffff
-2 4 10 ffffff
-1 4 10 ffffff
-13 5 10 ffffff
-12 5 10 ffffff
-11 5 10 ffffff
-10 5 10 ffffff
-9 5 10 ffffff
-8 5 10 ffffff
-7 5 10 ffffff
-6 5 10 ffffff
-5 5 10 ffffff
-4 5 10 ffffff
-3 5 10 ffffff
-2 5 10 ffffff
-1 5 10 ffffff
-12 6 10 ffffff
-11 6 10 ffffff
-10 6 10 ffffff
-9 6 10 ffffff
-8 6 10 ffffff
-7 6 10 ffffff
-6 6 10 ffffff
-5 6 10 ffffff
-4 6 10 ffffff
-3 6 10 ffffff
-2 6 10 ffffff
-1 6 10 ffffff
-12 7 10 ffffff
-11 7 10 ffffff
-10 7 10 ffffff
-9 7 10 ffffff
-8 7 10 ffffff
-7 7 10 ffffff
-6 7 10 ffffff
-5 7 10 ffffff
-4 7 10 ffffff
-3 7 10 ffffff
-2 7 10 ffffff
-1 7 10 ffffff
-11 8 10 ffffff
-10 8 10 ffffff
-9 8 10 ffffff
-8 8 10 ffffff
-7 8 10 ffffff
-6 8 10 ffffff
-5 8 10 ffffff
-4 8 10 ffffff
-3 8 10 ffffff
-2 8 10 ffffff
-1 8 10 ffffff
-10 9 10 ffffff
-9 9 10 ffffff
-8 9 10 ffffff
-7 9 10 ffffff
-6 9 10 ffffff
-5 9 10 ffffff
-4 9 10 ffffff
-3 9 10 ffffff
-2 9 10 ffffff
-1 9 10 ffffff
-9 10 10 ffffff
-8 10 10 ffffff
-7 10 10 ffffff
-6 10 10 ffffff
-5 10 10 ffffff
-4 10 10 ffffff
-3 10 10 ffffff
-2 10 10 ffffff
-1 10 10 ffffff
-8 11 10 ffffff
-7 11 10 ffffff
-6 11 10 ffffff
-5 11 10 ffffff
-4 11 10 ffffff
-3 11 10 ffffff
-2 11 10 ffffff
-1 11 10 ffffff
-6 12 10 ffffff
-5 12 10 ffffff
-4 12 10 ffffff
-3 12 10 ffffff
-2 12 10 ffffff
-1 12 10 ffffff
-3 13 10 ffffff
-2 13 10 ffffff
-1 13 10 ffffff
-14 0 11 ffffff
-13 0 11 ffffff
-12 0 11 ffffff
-11 0 11 ffffff
-10 0 11 ffffff
-9 0 11 ffffff
-8 0 11 ffffff
-7 0 11 ffffff
-6 0 11 ffffff
-5 0 11 ffffff
-4 0 11 ffffff
-3 0 11 ffffff
-2 0 11 ffffff
-1 0 11 ffffff
-14 1 11 ffffff
-13 1 11 ffffff
-12 1 11 ffffff
-11 1 11 ffffff
-10 1 11 ffffff
-9 1 11 ffffff
-8 1 11 ffffff
-7 1 11 ffffff
-6 1 11 ffffff
-5 1 11 ffffff
-4 1 11 ffffff
-3 1 11 ffffff
-2 1 11 ffffff
-1 1 11 ffffff
-14 2 11 ffffff
-13 2 11 ffffff
-12 2 11 ffffff
-11 2 11 ffffff
-10 2 11 ffffff
-9 2 11 ffffff
-8 2 11 ffffff
-7 2 11 ffffff
-6 2 11 ffffff
-5 2 11 ffffff
-4 2 11 ffffff
-3 2 11 ffffff
-2 2 11 ffffff
-1 2 11 ffffff
-14 3 11 ffffff
-13 3 11 ffffff
-12 3 11 ffffff
-11 3 11 ffffff
-10 3 11 ffffff
-9 3 11 ffffff
-8 3 11 ffffff
-7 3 11 ffffff
-6 3 11 ffffff
-5 3 11 ffffff
-4 3 11 ffffff
-3 3 11 ffffff
-2 3 11 ffffff
-1 3 11 ffffff
-14 4 11 ffffff
-13 4 11 ffffff
-12 4 11 ffffff
-11 4 11 ffffff
-10 4 11 ffffff
-9 4 11 ffffff
-8 4 11 ffffff
-7 4 11 ffffff
-6 4 11 ffffff
-5 4 11 ffffff
-4 4 11 ffffff
-3 4 11 ffffff
-2 4 11 ffffff
-1 4 11 ffffff
-13 5 11 ffffff
-12 5 11 ffffff
-11 5 11 ffffff
-10 5 11 ffffff
-9 5 11 ffffff
-8 5 11 ffffff
-7 5 11 ffffff
-6 5 11 ffffff
-5 5 11 ffffff
-4 5 11 ffffff
-3 5 11 ffffff
-2 5 11 ffffff
-1 5 11 ffffff
-13 6 11 ffffff
-12 6 11 ffffff
-11 6 11 ffffff
-10 6 11 ffffff
-9 6 11 ffffff
-8 6 11 ffffff
-7 6 11 ffffff
-6 6 11 ffffff
-5 6 11 ffffff
-4 6 11 ffffff
-3 6 11 ffffff
-2 6 11 ffffff
-1 6 11 ffffff
-12 7 11 ffffff
-11 7 11 ffffff
-10 7 11 ffffff
-9 7 11 ffffff
-8 7 11 ffffff
-7 7 11 ffffff
-6 7 11 ffffff
-5 7 11 ffffff
-4 7 11 ffffff
-3 7 11 ffffff
-2 7 11 ffffff
-1 7 11 ffffff
-11 8 11 ffffff
-10 8 11 ffffff
-9 8 11 ffffff
-8 8 11 ffffff
-7 8 11 ffffff
-6 8 11 ffffff
-5 8 11 ffffff
-4 8 11 ffffff
-3 8 11 ffffff
-2 8 11 ffffff
-1 8 11 ffffff
-11 9 11 ffffff
-10 9 11 ffffff
-9 9 11 ffffff
-8 9 11 ffffff
-7 9 11 ffffff
-6 9 11 ffffff
-5 9 11 ffffff
-4 9 11 ffffff
-3 9 11 ffffff
-2 9 11 ffffff
-1 9 11 ffffff
-10 10 11 ffffff
-9 10 11 ffffff
-8 10 11 ffffff
-7 10 11 ffffff
-6 10 11 ffffff
-5 10 11 ffffff
-4 10 11 ffffff
-3 10 11 ffffff
-2 10 11 ffffff
-1 10 11 ffffff
-8 11 11 ffffff
-7 11 11 ffffff
-6 11 11 ffffff
-5 11 11 ffffff
-4 11 11 ffffff
-3 11 11 ffffff
-2 11 11 ffffff
-1 11 11 ffffff
-7 12 11 ffffff
-6 12 11 ffffff
-5 12 11 ffffff
-4 12 11 ffffff
-3 12 11 ffffff
-2 12 11 ffffff
-1 12 11 ffffff
-5 13 11 ffffff
-4 13 11 ffffff
-3 13 11 ffffff
-2 13 11 ffffff
-1 13 11 ffffff
-15 0 12 ffffff
-14 0 12 ffffff
-13 0 12 ffffff
-12 0 12 ffffff
-11 0 12 ffffff
-10 0 12 ffffff
-9 0 12 ffffff
-8 0 12 ffffff
-7 0 12 ffffff
-6 0 12 ffffff
-5 0 12 ffffff
-4 0 12 ffffff
-3 0 12 ffffff
-2 0 12 ffffff
-1 0 12 ffffff
-14 1 12 ffffff
-13 1 12 ffffff
-12 1 12 ffffff
-11 1 12 ffffff
-10 1 12 ffffff
-9 1 12 ffffff
-8 1 12 ffffff
-7 1 12 ffffff
-6 1 12 ffffff
-5 1 12 ffffff
-4 1 12 ffffff
-3 1 12 ffffff
-2 1 12 ffffff
-1 1 12 ffffff
-14 2 12 ffffff
-13 2 12 ffffff
-12 2 12 ffffff
-11 2 12 ffffff
-10 2 12 ffffff
-9 2 12 ffffff
-8 2 12 ffffff
-7 2 12 ffffff
-6 2 12 ffffff
-5 2 12 ffffff
-4 2 12 ffffff
-3 2 12 ffffff
-2 2 12 ffffff
-1 2 12 ffffff
-14 3 12 ffffff
-13 3 12 ffffff
-12 3 12 ffffff
-11 3 12 ffffff
-10 3 12 ffffff
-9 3 12 ffffff
-8 3 12 ffffff
-7 3 12 ffffff
-6 3 12 ffffff
-5 3 12 ffffff
-4 3 12 ffffff
-3 3 12 ffffff
-2 3 12 ffffff
-1 3 12 ffffff
-14 4 12 ffffff
-13 4 12 ffffff
-12 4 12 ffffff
-11 4 12 ffffff
-10 4 12 ffffff
-9 4 12 ffffff
-8 4 12 ffffff
-7 4 12 ffffff
-6 4 12 ffffff
-5 4 12 ffffff
-4 4 12 ffffff
-3 4 12 ffffff
-2 4 12 ffffff
-1 4 12 ffffff
-13 5 12 ffffff
-12 5 12 ffffff
-11 5 12 ffffff
-10 5 12 ffffff
-9 5 12 ffffff
-8 5 12 ffffff
-7 5 12 ffffff
-6 5 12 ffffff
-5 5 12 ffffff
-4 5 12 ffffff
-3 5 12 ffffff
-2 5 12 ffffff
-1 5 12 ffffff
-13 6 12 ffffff
-12 6 12 ffffff
-11 6 12 ffffff
-10 6 12 ffffff
-9 6 12 ffffff
-8 6 12 ffffff
-7 6 12 ffffff
-6 6 12 ffffff
-5 6 12 ffffff
-4 6 12 ffffff
-3 6 12 ffffff
-2 6 12 ffffff
-1 6 12 ffffff
-12 7 12 ffffff
-11 7 12 ffffff
-10 7 12 ffffff
-9 7 12 ffffff
-8 7 12 ffffff
-7 7 12 ffffff
-6 7 12 ffffff
-5 7 12 ffffff
-4 7 12 ffffff
-3 7 12 ffffff
-2 7 12 ffffff
-1 7 12 ffffff
-12 8 12 ffffff
-11 8 12 ffffff
-10 8 12 ffffff
-9 8 12 ffffff
-8 8 12 ffffff
-7 8 12 ffffff
-6 8 12 ffffff
-5 8 12 ffffff
-4 8 12 ffffff
-3 8 12 ffffff
-2 8 12 ffffff
-1 8 12 ffffff
-11 9 12 ffffff
-10 9 12 ffffff
-9 9 12 ffffff
-8 9 12 ffffff
-7 9 12 ffffff
-6 9 12 ffffff
-5 9 12 ffffff
-4 9 12 ffffff
-3 9 12 ffffff
-2 9 12 ffffff
-1 9 12 ffffff
-10 10 12 ffffff
-9 10 12 ffffff
-8 10 12 ffffff
-7 10 12 ffffff
-6 10 12 ffffff
-5 10 12 ffffff
-4 10 12 ffffff
-3 10 12 ffffff
-2 10 12 ffffff
-1 10 12 ffffff
-9 11 12 ffffff
-8 11 12 ffffff
-7 11 12 ffffff
-6 11 12 ffffff
-5 11 12 ffffff
-4 11 12 ffffff
-3 11 12 ffffff
-2 11 12 ffffff
-1 11 12 ffffff
-7 12 12 ffffff
-6 12 12 ffffff
-5 12 12 ffffff
-4 12 12 ffffff
-3 12 12 ffffff
-2 12 12 ffffff
-1 12 12 ffffff
-5 13 12 ffffff
-4 13 12 ffffff
-3 13 12 ffffff
-2 13 12 ffffff
-1 13 12 ffffff
-1 14 12 ffffff
-15 0 13 ffffff
-14 0 13 ffffff
-13 0 13 ffffff
-12 0 13 ffffff
-11 0 13 ffffff
-10 0 13 ffffff
-9 0 13 ffffff
-8 0 13 ffffff
-7 0 13 ffffff
-6 0 13 ffffff
-5 0 13 ffffff
-4 0 13 ffffff
-3 0 13 ffffff
-2 0 13 ffffff
-1 0 13 ffffff
-15 1 13 ffffff
-14 1 13 ffffff
-13 1 13 ffffff
-12 1 13 ffffff
-11 1 13 ffffff
-10 1 13 ffffff
-9 1 13 ffffff
-8 1 13 ffffff
-7 1 13 ffffff
-6 1 13 ffffff
-5 1 13 ffffff
-4 1 13 ffffff
-3 1 13 ffffff
-2 1 13 ffffff
-1 1 13 ffffff
-15 2 13 ffffff
-14 2 13 ffffff
-13 2 13 ffffff
-12 2 13 ffffff
-11 2 13 ffffff
-10 2 13 ffffff
-9 2 13 ffffff
-8 2 13 ffffff
-7 2 13 ffffff
-6 2 13 ffffff
-5 2 13 ffffff
-4 2 13 ffffff
-3 2 13 ffffff
-2 2 13 ffffff
-1 2 13 ffffff
-14 3 13 ffffff
-13 3 13 ffffff
-12 3 13 ffffff
-11 3 13 ffffff
-10 3 13 ffffff
-9 3 13 ffffff
-8 3 13 ffffff
-7 3 13 ffffff
-6 3 13 ffffff
-5 3 13 ffffff
-4 3 13 ffffff
-3 3 13 ffffff
-2 3 13 ffffff
-1 3 13 ffffff
-14 4 13 ffffff
-13 4 13 ffffff
-12 4 13 ffffff
-11 4 13 ffffff
-10 4 13 ffffff
-9 4 13 ffffff
-8 4 13 ffffff
-7 4 13 ffffff
-6 4 13 ffffff
-5 4 13 ffffff
-4 4 13 ffffff
-3 4 13 ffffff
-2 4 13 ffffff
-1 4 13 ffffff
-14 5 13 ffffff
-13 5 13 ffffff
-12 5 13 ffffff
-11 5 13 ffffff
-10 5 13 ffffff
-9 5 13 ffffff
-8 5 13 ffffff
-7 5 13 ffffff
-6 5 13 ffffff
-5 5 13 ffffff
-4 5 13 ffffff
-3 5 13 ffffff
-2 5 13 ffffff
-1 5 13 ffffff
-13 6 13 ffffff
-12 6 13 ffffff
-11 6 13 ffffff
-10 6 13 ffffff
-9 6 13 ffffff
-8 6 13 ffffff
-7 6 13 ffffff
-6 6 13 ffffff
-5 6 13 ffffff
-4 6 13 ffffff
-3 6 13 ffffff
-2 6 13 ffffff
-1 6 13 ffffff
-13 7 13 ffffff
-12 7 13 ffffff
-11 7 13 ffffff
-10 7 13 ffffff
-9 7 13 ffffff
-8 7 13 ffffff
-7 7 13 ffffff
-6 7 13 ffffff
-5 7 13 ffffff
-4 7 13 ffffff
-3 7 13 ffffff
-2 7 13 ffffff
-1 7 13 ffffff
-12 8 13 ffffff
-11 8 13 ffffff
-10 8 13 ffffff
-9 8 13 ffffff
-8 8 13 ffffff
-7 8 13 ffffff
-6 8 13 ffffff
-5 8 13 ffffff
-4 8 13 ffffff
-3 8 13 ffffff
-2 8 13 ffffff
-1 8 13 ffffff
-11 9 13 ffffff
-10 9 13 ffffff
-9 9 13 ffffff
-8 9 13 ffffff
-7 9 13 ffffff
-6 9 13 ffffff
-5 9 13 ffffff
-4 9 13 ffffff
-3 9 13 ffffff
-2 9 13 ffffff
-1 9 13 ffffff
-10 10 13 ffffff
-9 10 13 ffffff
-8 10 13 ffffff
-7 10 13 ffffff
-6 10 13 ffffff
-5 10 13 ffffff
-4 10 13 ffffff
-3 10 13 ffffff
-2 10 13 ffffff
-1 10 13 ffffff
-9 11 13 ffffff
-8 11 13 ffffff
-7 11 13 ffffff
-6 11 13 ffffff
-5 11 13 ffffff
-4 11 13 ffffff
-3 11 13 ffffff
-2 11 13 ffffff
-1 11 13 ffffff
-8 12 13 ffffff
-7 12 13 ffffff
-6 12 13 ffffff
-5 12 13 ffffff
-4 12 13 ffffff
-3 12 13 ffffff
-2 12 13 ffffff
-1 12 13 ffffff
-6 13 13 ffffff
-5 13 13 ffffff
-4 13 13 ffffff
-3 13 13 ffffff
-2 13 13 ffffff
-1 13 13 ffffff
-3 14 13 ffffff
-2 14 13 ffffff
-1 14 13 ffffff
-15 0 14 ffffff
-14 0 14 ffffff
-13 0 14 ffffff
-12 0 14 ffffff
-11 0 14 ffffff
-10 0 14 ffffff
-9 0 14 ffffff
-8 0 14 ffffff
-7 0 14 ffffff
-6 0 14 ffffff
-5 0 14 ffffff
-4 0 14 ffffff
-3 0 14 ffffff
-2 0 14 ffffff
-1 0 14 ffffff
-15 1 14 ffffff
-14 1 14 ffffff
-13 1 14 ffffff
-12 1 14 ffffff
-11 1 14 ffffff
-10 1 14 ffffff
-9 1 14 ffffff
-8 1 14 ffffff
-7 1 14 ffffff
-6 1 14 ffffff
-5 1 14 ffffff
-4 1 14 ffffff
-3 1 14 ffffff
-2 1 14 ffffff
-1 1 14 ffffff
-15 2 14 ffffff
-14 2 14 ffffff
-13 2 14 ffffff
-12 2 14 ffffff
-11 2 14 ffffff
-10 2 14 ffffff
-9 2 14 ffffff
-8 2 14 ffffff
-7 2 14 ffffff
-6 2 14 ffffff
-5 2 14 ffffff
-4 2 14 ffffff
-3 2 14 ffffff
-2 2 14 ffffff
-1 2 14 ffffff
-14 3 14 ffffff
-13 3 14 ffffff
-12 3 14 ffffff
-11 3 14 ffffff
-10 3 14 ffffff
-9 3 14 ffffff
-8 3 14 ffffff
-7 3 14 ffffff
-6 3 14 ffffff
-5 3 14 ffffff
-4 3 14 ffffff
-3 3 14 ffffff
-2 3 14 ffffff
-1 3 14 ffffff
-14 4 14 ffffff
-13 4 14 ffffff
-12 4 14 ffffff
-11 4 14 ffffff
-10 4 14 ffffff
-9 4 14 ffffff
-8 4 14 ffffff
-7 4 14 ffffff
-6 4 14 ffffff
-5 4 14 ffffff
-4 4 14 ffffff
-3 4 14 ffffff
-2 4 14 ffffff
-1 4 14 ffffff
-14 5 14 ffffff
-13 5 14 ffffff
-12 5 14 ffffff
-11 5 14 ffffff
-10 5 14 ffffff
-9 5 14 ffffff
-8 5 14 ffffff
-7 5 14 ffffff
-6 5 14 ffffff
-5 5 14 ffffff
-4 5 14 ffffff
-3 5 14 ffffff
-2 5 14 ffffff
-1 5 14 ffffff
-13 6 14 ffffff
-12 6 14 ffffff
-11 6 14 ffffff
-10 6 14 ffffff
-9 6 14 ffffff
-8 6 14 ffffff
-7 6 14 ffffff
-6 6 14 ffffff
-5 6 14 ffffff
-4 6 14 ffffff
-3 6 14 ffffff
-2 6 14 ffffff
-1 6 14 ffffff
-13 7 14 ffffff
-12 7 14 ffffff
-11 7 14 ffffff
-10 7 14 ffffff
-9 7 14 ffffff
-8 7 14 ffffff
-7 7 14 ffffff
-6 7 14 ffffff
-5 7 14 ffffff
-4 7 14 ffffff
-3 7 14 ffffff
-2 7 14 ffffff
-1 7 14 ffffff
-12 8 14 ffffff
-11 8 14 ffffff
-10 8 14 ffffff
-9 8 14 ffffff
-8 8 14 ffffff
-7 8 14 ffffff
-6 8 14 ffffff
-5 8 14 ffffff
-4 8 14 ffffff
-3 8 14 ffffff
-2 8 14 ffffff
-1 8 14 ffffff
-11 9 14 ffffff
-10 9 14 ffffff
-9 9 14 ffffff
-8 9 14 ffffff
-7 9 14 ffffff
-6 9 14 ffffff
-5 9 14 ffffff
-4 9 14 ffffff
-3 9 14 ffffff
-2 9 14 ffffff
-1 9 14 ffffff
-10 10 14 ffffff
-9 10 14 ffffff
-8 10 14 ffffff
-7 10 14 ffffff
-6 10 14 ffffff
-5 10 14 ffffff
-4 10 14 ffffff
-3 10 14 ffffff
-2 10 14 ffffff
-1 10 14 ffffff
-9 11 14 ffffff
-8 11 14 ffffff
-7 11 14 ffffff
-6 11 14 ffffff
-5 11 14 ffffff
-4 11 14 ffffff
-3 11 14 ffffff
-2 11 14 ffffff
-1 11 14 ffffff
-8 12 14 ffffff
-7 12 14 ffffff
-6 12 14 ffffff
-5 12 14 ffffff
-4 12 14 ffffff
-3 12 14 ffffff
-2 12 14 ffffff
-1 12 14 ffffff
-6 13 14 ffffff
-5 13 14 ffffff
-4 13 14 ffffff
-3 13 14 ffffff
-2 13 14 ffffff
-1 13 14 ffffff
-3 14 14 ffffff
-2 14 14 ffffff
-1 14 14 ffffff
-15 0 15 ffffff
-14 0 15 ffffff
-13 0 15 ffffff
-12 0 15 ffffff
-11 0 15 ffffff
-10 0 15 ffffff
-9 0 15 ffffff
-8 0 15 ffffff
-7 0 15 ffffff
-6 0 15 ffffff
-5 0 15 ffffff
-4 0 15 ffffff
-3 0 15 ffffff
-2 0 15 ffffff
-1 0 15 ffffff
-15 1 15 ffffff
-14 1 15 ffffff
-13 1 15 ffffff
-12 1 15 ffffff
-11 1 15 ffffff
-10 1 15 ffffff
-9 1 15 ffffff
-8 1 15 ffffff
-7 1 15 ffffff
-6 1 15 ffffff
-5 1 15 ffffff
-4 1 15 ffffff
-3 1 15 ffffff
-2 1 15 ffffff
-1 1 15 ffffff
-15 2 15 ffffff
-14 2 15 ffffff
-13 2 15 ffffff
-12 2 15 ffffff
-11 2 15 ffffff
-10 2 15 ffffff
-9 2 15 ffffff
-8 2 15 ffffff
-7 2 15 ffffff
-6 2 15 ffffff
-5 2 15 ffffff
-4 2 15 ffffff
-3 2 15 ffffff
-2 2 15 ffffff
-1 2 15 ffffff
-14 3 15 ffffff
-13 3 15 ffffff
-12 3 15 ffffff
-11 3 15 ffffff
-10 3 15 ffffff
-9 3 15 ffffff
-8 3 15 ffffff
-7 3 15 ffffff
-6 3 15 ffffff
-5 3 15 ffffff
-4 3 15 ffffff
-3 3 15 ffffff
-2 3 15 ffffff
-1 3 15 ffffff
-14 4 15 ffffff
-13 4 15 ffffff
-12 4 15 ffffff
-11 4 15 ffffff
-10 4 15 ffffff
-9 4 15 ffffff
-8 4 15 ffffff
-7 4 15 ffffff
-6 4 15 ffffff
-5 4 15 ffffff
-4 4 15 ffffff
-3 4 15 ffffff
-2 4 15 ffffff
-1 4 15 ffffff
-14 5 15 ffffff
-13 5 15 ffffff
-12 5 15 ffffff
-11 5 15 ffffff
-10 5 15 ffffff
-9 5 15 ffffff
-8 5 15 ffffff
-7 5 15 ffffff
-6 5 15 ffffff
-5 5 15 ffffff
-4 5 15 ffffff
-3 5 15 ffffff
-2 5 15 ffffff
-1 5 15 ffffff
-13 6 15 ffffff
-12 6 15 ffffff
-11 6 15 ffffff
-10 6 15 ffffff
-9 6 15 ffffff
-8 6 15 ffffff
-7 6 15 ffffff
-6 6 15 ffffff
-5 6 15 ffffff
-4 6 15 ffffff
-3 6 15 ffffff
-2 6 15 ffffff
-1 6 15 ffffff
-13 7 15 ffffff
-12 7 15 ffffff
-11 7 15 ffffff
-10 7 15 ffffff
-9 7 15 ffffff
-8 7 15 ffffff
-7 7 15 ffffff
-6 7 15 ffffff
-5 7 15 ffffff
-4 7 15 ffffff
-3 7 15 ffffff
-2 7 15 ffffff
-1 7 15 ffffff
-12 8 15 ffffff
-11 8 15 ffffff
-10 8 15 ffffff
-9 8 15 ffffff
-8 8 15 ffffff
-7 8 15 ffffff
-6 8 15 ffffff
-5 8 15 ffffff
-4 8 15 ffffff
-3 8 15 ffffff
-2 8 15 ffffff
-1 8 15 ffffff
-11 9 15 ffffff
-10 9 15 ffffff
-9 9 15 ffffff
-8 9 15 ffffff
-7 9 15 ffffff
-6 9 15 ffffff
-5 9 15 ffffff
-4 9 15 ffffff
-3 9 15 ffffff
-2 9 15 ffffff
-1 9 15 ffffff
-10 10 15 ffffff
-9 10 15 ffffff
-8 10 15 ffffff
-7 10 15 ffffff
-6 10 15 ffffff
-5 10 15 ffffff
-4 10 15 ffffff
-3 10 15 ffffff
-2 10 15 ffffff
-1 10 15 ffffff
-9 11 15 ffffff
-8 11 15 ffffff
-7 11 15 ffffff
-6 11 15 ffffff
-5 11 15 ffffff
-4 11 15 ffffff
-3 11 15 ffffff
-2 11 15 ffffff
-1 11 15 ffffff
-8 12 15 ffffff
-7 12 15 ffffff
-6 12 15 ffffff
-5 12 15 ffffff
-4 12 15 ffffff
-3 12 15 ffffff
-2 12 15 ffffff
-1 12 15 ffffff
-6 13 15 ffffff
-5 13 15 ffffff
-4 13 15 ffffff
-3 13 15 ffffff
-2 13 15 ffffff
-1 13 15 ffffff
-3 14 15 ffffff
-2 14 15 ffffff
-1 14 15 ffffff
0 0 0 ffffff
1 0 0 ffffff
2 0 0 ffffff
3 0 0 ffffff
0 1 0 ffffff
1 1 0 ffffff
2 1 0 ffffff
3 1 0 ffffff
0 2 0 ffffff
1 2 0 ffffff
2 2 0 ffffff
0 0 1 ffffff
1 0 1 ffffff
2 0 1 ffffff
3 0 1 ffffff
4 0 1 ffffff
5 0 1 ffffff
6 0 1 ffffff
0 1 1 ffffff
1 1 1 ffffff
2 1 1 ffffff
3 1 1 ffffff
4 1 1 ffffff
5 1 1 ffffff
6 1 1 ffffff
0 2 1 ffffff
1 2 1 ffffff
2 2 1 ffffff
3 2 1 ffffff
4 2 1 ffffff
5 2 1 ffffff
0 3 1 ffffff
1 3 1 ffffff
2 3 1 ffffff
3 3 1 ffffff
4 3 1 ffffff
5 3 1 ffffff
0 4 1 ffffff
1 4 1 ffffff
2 4 1 ffffff
3 4 1 ffffff
4 4 1 ffffff
0 5 1 ffffff
1 5 1 ffffff
2 5 1 ffffff
0 0 2 ffffff
1 0 2 ffffff
2 0 2 ffffff
3 0 2 ffffff
4 0 2 ffffff
5 0 2 ffffff
6 0 2 ffffff
7 0 2 ffffff
8 0 2 ffffff
0 1 2 ffffff
1 1 2 ffffff
2 1 2 ffffff
3 1 2 ffffff
4 1 2 ffffff
5 1 2 ffffff
6 1 2 ffffff
7 1 2 ffffff
8 1 2 ffffff
0 2 2 ffffff
1 2 2 ffffff
2 2 2 ffffff
3 2 2 ffffff
4 2 2 ffffff
5 2 2 ffffff
6 2 2 ffffff
7 2 2 ffffff
0 3 2 ffffff
1 3 2 ffffff
2 3 2 ffffff
3 3 2 ffffff
4 3 2 ffffff
5 3 2 ffffff
6 3 2 ffffff
7 3 2 ffffff
0 4 2 ffffff
1 4 2 ffffff
2 4 2 ffffff
3 4 2 ffffff
4 4 2 ffffff
5 4 2 ffffff
6 4 2 ffffff
0 5 2 ffffff
1 5 2 ffffff
2 5 2 ffffff
3 5 2 ffffff
4 5 2 ffffff
5 5 2 ffffff
0 6 2 ffffff
1 6 2 ffffff
2 6 2 ffffff
3 6 2 ffffff
4 6 2 ffffff
0 7 2 ffffff
1 7 2 ffffff
2 7 2 ffffff
0 0 3 ffffff
1 0 3 ffffff
2 0 3 ffffff
3 0 3 ffffff
4 0 3 ffffff
5 0 3 ffffff
6 0 3 ffffff
7 0 3 ffffff
8 0 3 ffffff
9 0 3 ffffff
0 1 3 ffffff
1 1 3 ffffff
2 1 3 ffffff
3 1 3 ffffff
4 1 3 ffffff
5 1 3 ffffff
6 1 3 ffffff
7 1 3 ffffff
8 1 3 ffffff
9 1 3 ffffff
0 2 3 ffffff
1 2 3 ffffff
2 2 3 ffffff
3 2 3 ffffff
4 2 3 ffffff
5 2 3 ffffff
6 2 3 ffffff
7 2 3 ffffff
8 2 3 ffffff
9 2 3 ffffff
0 3 3 ffffff
1 3 3 ffffff
2 3 3 ffffff
3 3 3 ffffff
4 3 3 ffffff
5 3 3 ffffff
6 3 3 ffffff
7 3 3 ffffff
8 3 3 ffffff
0 4 3 ffffff
1 4 3 ffffff
2 4 3 ffffff
3 4 3 ffffff
4 4 3 ffffff
5 4 3 ffffff
6 4 3 ffffff
7 4 3 ffffff
8 4 3 ffffff
0 5 3 ffffff
1 5 3 ffffff
2 5 3 ffffff
3 5 3 ffffff
4 5 3 ffffff
5 5 3 ffffff
6 5 3 ffffff
7 5 3 ffffff
0 6 3 ffffff
1 6 3 ffffff
2 6 3 ffffff
3 6 3 ffffff
4 6 3 ffffff
5 6 3 ffffff
6 6 3 ffffff
0 7 3 ffffff
1 7 3 ffffff
2 7 3 ffffff
3 7 3 ffffff
4 7 3 ffffff
5 7 3 ffffff
0 8 3 ffffff
1 8 3 ffffff
2 8 3 ffffff
3 8 3 ffffff
0 0 4 ffffff
1 0 4 ffffff
2 0 4 ffffff
3 0 4 ffffff
4 0 4 ffffff
5 0 4 ffffff
6 0 4 ffffff
7 0 4 ffffff
8 0 4 ffffff
9 0 4 ffffff
10 0 4 ffffff
0 1 4 ffffff
1 1 4 ffffff
2 1 4 ffffff
3 1 4 ffffff
4 1 4 ffffff
5 1 4 ffffff
6 1 4 ffffff
7 1 4 ffffff
8 1 4 ffffff
9 1 4 ffffff
10 1 4 ffffff
0 2 4 ffffff
1 2 4 ffffff
2 2 4 ffffff
3 2 4 ffffff
4 2 4 ffffff
5 2 4 ffffff
6 2 4 ffffff
7 2 4 ffffff
8 2 4 ffffff
9 2 4 ffffff
10 2 4 ffffff
0 3 4 ffffff
1 3 4 ffffff
2 3 4 ffffff
3 3 4 ffffff
4 3 4 ffffff
5 3 4 ffffff
6 3 4 ffffff
7 3 4 ffffff
8 3 4 ffffff
9 3 4 ffffff
10 3 4 ffffff
0 4 4 ffffff
1 4 4 ffffff
2 4 4 ffffff
3 4 4 ffffff
4 4 4 ffffff
5 4 4 ffffff
6 4 4 ffffff
7 4 4 ffffff
8 4 4 ffffff
9 4 4 ffffff
0 5 4 ffffff
1 5 4 ffffff
2 5 4 ffffff
3 5 4 ffffff
4 5 4 ffffff
5 5 4 ffffff
6 5 4 ffffff
7 5 4 ffffff
8 5 4 ffffff
0 6 4 ffffff
1 6 4 ffffff
2 6 4 ffffff
3 6 4 ffffff
4 6 4 ffffff
5 6 4 ffffff
6 6 4 ffffff
7 6 4 ffffff
8 6 4 ffffff
0 7 4 ffffff
1 7 4 ffffff
2 7 4 ffffff
3 7 4 ffffff
4 7 4 ffffff
5 7 4 ffffff
6 7 4 ffffff
7 7 4 ffffff
0 8 4 ffffff
1 8 4 ffffff
2 8 4 ffffff
3 8 4 ffffff
4 8 4 ffffff
5 8 4 ffffff
0 9 4 ffffff
1 9 4 ffffff
2 9 4 ffffff
3 9 4 ffffff
4 9 4 ffffff
0 0 5 ffffff
1 0 5 ffffff
2 0 5 ffffff
3 0 5 ffffff
4 0 5 ffffff
5 0 5 ffffff
6 0 5 ffffff
7 0 5 ffffff
8 0 5 ffffff
9 0 5 ffffff
10 0 5 ffffff
11 0 5 ffffff
0 1 5 ffffff
1 1 5 ffffff
2 1 5 ffffff
3 1 5 ffffff
4 1 5 ffffff
5 1 5 ffffff
6 1 5 ffffff
7 1 5 ffffff
8 1 5 ffffff
9 1 5 ffffff
10 1 5 ffffff
11 1 5 ffffff
0 2 5 ffffff
1 2 5 ffffff
2 2 5 ffffff
3 2 5 ffffff
4 2 5 ffffff
5 2 5 ffffff
6 2 5 ffffff
7 2 5 ffffff
8 2 5 ffffff
9 2 5 ffffff
10 2 5 ffffff
11 2 5 ffffff
0 3 5 ffffff
1 3 5 ffffff
2 3 5 ffffff
3 3 5 ffffff
4 3 5 ffffff
5 3 5 ffffff
6 3 5 ffffff
7 3 5 ffffff
8 3 5 ffffff
9 3 5 ffffff
10 3 5 ffffff
0 4 5 ffffff
1 4 5 ffffff
2 4 5 ffffff
3 4 5 ffffff
4 4 5 ffffff
5 4 5 ffffff
6 4 5 ffffff
7 4 5 ffffff
8 4 5 ffffff
9 4 5 ffffff
10 4 5 ffffff
0 5 5 ffffff
1 5 5 ffffff
2 5 5 ffffff
3 5 5 ffffff
4 5 5 ffffff
5 5 5 ffffff
6 5 5 ffffff
7 5 5 ffffff
8 5 5 ffffff
9 5 5 ffffff
10 5 5 ffffff
0 6 5 ffffff
1 6 5 ffffff
2 6 5 ffffff
3 6 5 ffffff
4 6 5 ffffff
5 6 5 ffffff
6 6 5 ffffff
7 6 5 ffffff
8 6 5 ffffff
9 6 5 ffffff
0 7 5 ffffff
1 7 5 ffffff
2 7 5 ffffff
3 7 5 ffffff
4 7 5 ffffff
5 7 5 ffffff
6 7 5 ffffff
7 7 5 ffffff
8 7 5 ffffff
0 8 5 ffffff
1 8 5 ffffff
2 8 5 ffffff
3 8 5 ffffff
4 8 5 ffffff
5 8 5 ffffff
6 8 5 ffffff
7 8 5 ffffff
0 9 5 ffffff
1 9 5 ffffff
2 9 5 ffffff
3 9 5 ffffff
4 9 5 ffffff
5 9 5 ffffff
6 9 5 ffffff
0 10 5 ffffff
1 10 5 ffffff
2 10 5 ffffff
3 10 5 ffffff
0 0 6 ffffff
1 0 6 ffffff
2 0 6 ffffff
3 0 6 ffffff
4 0 6 ffffff
5 0 6 ffffff
6 0 6 ffffff
7 0 6 ffffff
8 0 6 ffffff
9 0 6 ffffff
10 0 6 ffffff
11 0 6 ffffff
12 0 6 ffffff
0 1 6 ffffff
1 1 6 ffffff
2 1 6 ffffff
3 1 6 ffffff
4 1 6 ffffff
5 1 6 ffffff
6 1 6 ffffff
7 1 6 ffffff
8 1 6 ffffff
9 1 6 ffffff
10 1 6 ffffff
11 1 6 ffffff
12 1 6 ffffff
0 2 6 ffffff
1 2 6 ffffff
2 2 6 ffffff
3 2 6 ffffff
4 2 6 ffffff
5 2 6 ffffff
6 2 6 ffffff
7 2 6 ffffff
8 2 6 ffffff
9 2 6 ffffff
10 2 6 ffffff
11 2 6 ffffff
12 2 6 ffffff
0 3 6 ffffff
1 3 6 ffffff
2 3 6 ffffff
3 3 6 ffffff
4 3 6 ffffff
5 3 6 ffffff
6 3 6 ffffff
7 3 6 ffffff
8 3 6 ffffff
9 3 6 ffffff
10 3 6 ffffff
11 3 6 ffffff
0 4 6 ffffff
1 4 6 ffffff
2 4 6 ffffff
3 4 6 ffffff
4 4 6 ffffff
5 4 6 ffffff
6 4 6 ffffff
7 4 6 ffffff
8 4 6 ffffff
9 4 6 ffffff
10 4 6 ffffff
11 4 6 ffffff
0 5 6 ffffff
1 5 6 ffffff
2 5 6 ffffff
3 5 6 ffffff
4 5 6 ffffff
5 5 6 ffffff
6 5 6 ffffff
7 5 6 ffffff
8 5 6 ffffff
9 5 6 ffffff
10 5 6 ffffff
0 6 6 ffffff
1 6 6 ffffff
2 6 6 ffffff
3 6 6 ffffff
4 6 6 ffffff
5 6 6 ffffff
6 6 6 ffffff
7 6 6 ffffff
8 6 6 ffffff
9 6 6 ffffff
10 6 6 ffffff
0 7 6 ffffff
1 7 6 ffffff
2 7 6 ffffff
3 7 6 ffffff
4 7 6 ffffff
5 7 6 ffffff
6 7 6 ffffff
7 7 6 ffffff
8 7 6 ffffff
9 7 6 ffffff
0 8 6 ffffff
1 8 6 ffffff
2 8 6 ffffff
3 8 6 ffffff
4 8 6 ffffff
5 8 6 ffffff
6 8 6 ffffff
7 8 6 ffffff
8 8 6 ffffff
0 9 6 ffffff
1 9 6 ffffff
2 9 6 ffffff
3 9 6 ffffff
4 9 6 ffffff
5 9 6 ffffff
6 9 6 ffffff
7 9 6 ffffff
0 10 6 ffffff
1 10 6 ffffff
2 10 6 ffffff
3 10 6 ffffff
4 10 6 ffffff
5 10 6 ffffff
0 11 6 ffffff
1 11 6 ffffff
2 11 6 ffffff
3 11 6 ffffff
0 0 7 ffffff
1 0 7 ffffff
2 0 7 ffffff
3 0 7 ffffff
4 0 7 ffffff
5 0 7 ffffff
6 0 7 ffffff
7 0 7 ffffff
8 0 7 ffffff
9 0 7 ffffff
10 0 7 ffffff
11 0 7 ffffff
12 0 7 ffffff
13 0 7 ffffff
0 1 7 ffffff
1 1 7 ffffff
2 1 7 ffffff
3 1 7 ffffff
4 1 7 ffffff
5 1 7 ffffff
6 1 7 ffffff
7 1 7 ffffff
8 1 7 ffffff
9 1 7 ffffff
10 1 7 ffffff
11 1 7 ffffff
12 1 7 ffffff
0 2 7 ffffff
1 2 7 ffffff
2 2 7 ffffff
3 2 7 ffffff
4 2 7 ffffff
5 2 7 ffffff
6 2 7 ffffff
7 2 7 ffffff
8 2 7 ffffff
9 2 7 ffffff
10 2 7 ffffff
11 2 7 ffffff
12 2 7 ffffff
0 3 7 ffffff
1 3 7 ffffff
2 3 7 ffffff
3 3 7 ffffff
4 3 7 ffffff
5 3 7 ffffff
6 3 7 ffffff
7 3 7 ffffff
8 3 7 ffffff
9 3 7 ffffff
10 3 7 ffffff
11 3 7 ffffff
12 3 7 ffffff
0 4 7 ffffff
1 4 7 ffffff
2 4 7 ffffff
3 4 7 ffffff
4 4 7 ffffff
5 4 7 ffffff
6 4 7 ffffff
7 4 7 ffffff
8 4 7 ffffff
9 4 7 ffffff
10 4 7 ffffff
11 4 7 ffffff
